<?xml version="1.0" encoding="utf-8"?>
<!-- This URDF was automatically created by SolidWorks to URDF Exporter! Originally created by Stephen Brawner (brawner@gmail.com) 
     Commit Version: 1.6.0-1-g15f4949  Build Version: 1.6.7594.29634
     For more information, please see http://wiki.ros.org/sw_urdf_exporter -->
<robot
  name="bioloidgp_social_robot">

  <link name="dummy">
  </link>

  <link
    name="base_link">
    <inertial>
      <origin
        xyz="-0.020929 0.0003067 -0.010821"
        rpy="0 0 0" />
      <mass
        value="0.38847" />
      <inertia
        ixx="0.00037179"
        ixy="-3.8113E-07"
        ixz="-5.6596E-06"
        iyy="0.00025726"
        iyz="-3.3879E-07"
        izz="0.00023648" />
    </inertial>
    <visual>
      <origin
        xyz="0 0 0"
        rpy="0 0 0" />
      <geometry>
        <mesh
          filename="package://bioloidgp_social_robot/meshes/base_link.STL" />
      </geometry>
      <material
        name="">
        <color
          rgba="0.75294 0.75294 0.75294 1" />
      </material>
    </visual>
    <collision>
      <origin
        xyz="0 0 0"
        rpy="0 0 0" />
      <geometry>
        <mesh
          filename="package://bioloidgp_social_robot/meshes/base_link.STL" />
      </geometry>
    </collision>
  </link>

  <joint name="dummy_joint" type="fixed">
     <parent link="dummy"/>
     <child link="base_link"/>
  </joint>

  <joint 
    name="imu_to_base_joint" 
    type="fixed">
    <origin 
      xyz="0.00824999999999999 0 -0.035"
      rpy="0 0 0" />
    <parent link="base_link"/>
    <child link="imu_link"/>
  </joint>

  <link 
    name="imu_link">
    <visual>
      <geometry>
        <box size="0.016 0.026 0.005"/>
      </geometry>
      <material name="green">
        <color rgba="0.0 1.0 0.0 1.0"/>
      </material>
    </visual>
  </link>

  <link
    name="right_arm_link_1">
    <inertial>
      <origin
        xyz="-6.0704E-08 -0.0092321 0.0051786"
        rpy="0 0 0" />
      <mass
        value="0.0040203" />
      <inertia
        ixx="8.5346E-07"
        ixy="1.7048E-12"
        ixz="-1.0516E-12"
        iyy="1.7713E-06"
        iyz="2.5119E-07"
        izz="1.691E-06" />
    </inertial>
    <visual>
      <origin
        xyz="0 0 0"
        rpy="0 0 0" />
      <geometry>
        <mesh
          filename="package://bioloidgp_social_robot/meshes/right_arm_link_1.STL" />
      </geometry>
      <material
        name="">
        <color
          rgba="0.79216 0.81961 0.93333 1" />
      </material>
    </visual>
    <collision>
      <origin
        xyz="0 0 0"
        rpy="0 0 0" />
      <geometry>
        <mesh
          filename="package://bioloidgp_social_robot/meshes/right_arm_link_1.STL" />
      </geometry>
    </collision>
  </link>
  <link
    name="right_arm_link_2">
    <inertial>
      <origin
        xyz="-0.00050189 -0.035219 0.0031256"
        rpy="0 0 0" />
      <mass
        value="0.088364" />
      <inertia
        ixx="2.19E-05"
        ixy="-8.8092E-09"
        ixz="-1.8948E-07"
        iyy="1.8529E-05"
        iyz="2.0129E-07"
        izz="1.67E-05" />
    </inertial>
    <visual>
      <origin
        xyz="0 0 0"
        rpy="0 0 0" />
      <geometry>
        <mesh
          filename="package://bioloidgp_social_robot/meshes/right_arm_link_2.STL" />
      </geometry>
      <material
        name="">
        <color
          rgba="0.79216 0.81961 0.93333 1" />
      </material>
    </visual>
    <collision>
      <origin
        xyz="0 0 0"
        rpy="0 0 0" />
      <geometry>
        <mesh
          filename="package://bioloidgp_social_robot/meshes/right_arm_link_2.STL" />
      </geometry>
    </collision>
  </link>
  <link
    name="right_arm_link_3">
    <inertial>
      <origin
        xyz="0.0062081 0.042396 -0.016804"
        rpy="0 0 0" />
      <mass
        value="0.053418" />
      <inertia
        ixx="1.0779E-05"
        ixy="2.3649E-08"
        ixz="1.9098E-07"
        iyy="1.4518E-05"
        iyz="2.4969E-07"
        izz="1.4395E-05" />
    </inertial>
    <visual>
      <origin
        xyz="0 0 0"
        rpy="0 3.1416 0" />
      <geometry>
        <mesh
          filename="package://bioloidgp_social_robot/meshes/right_arm_link_3.STL" />
      </geometry>
      <material
        name="">
        <color
          rgba="0.79216 0.81961 0.93333 1" />
      </material>
    </visual>
    <collision>
      <origin
        xyz="0 0 0"
        rpy="0 3.1416 0" />
      <geometry>
        <mesh
          filename="package://bioloidgp_social_robot/meshes/right_arm_link_3.STL" />
      </geometry>
    </collision>
  </link>
  <link
    name="right_gripper">
    <inertial>
      <origin
        xyz="0.018 -0.0062404 0.036135"
        rpy="0 0 0" />
      <mass
        value="0.0088243" />
      <inertia
        ixx="7.4613E-06"
        ixy="-2.1839E-11"
        ixz="-7.8633E-12"
        iyy="9.3608E-06"
        iyz="-1.8805E-06"
        izz="4.6829E-06" />
    </inertial>
    <visual>
      <origin
        xyz="0 0 0"
        rpy="3.1416 0 0" />
      <geometry>
        <mesh
          filename="package://bioloidgp_social_robot/meshes/right_gripper.STL" />
      </geometry>
      <material
        name="">
        <color
          rgba="0.79216 0.81961 0.93333 1" />
      </material>
    </visual>
    <collision>
      <origin
        xyz="0 0 0"
        rpy="3.1416 0 0" />
      <geometry>
        <mesh
          filename="package://bioloidgp_social_robot/meshes/right_gripper.STL" />
      </geometry>
    </collision>
  </link>



  <link
    name="left_arm_link_1">
    <inertial>
      <origin
        xyz="-6.0704E-08 -0.0092321 0.0051786"
        rpy="0 0 0" />
      <mass
        value="0.0040203" />
      <inertia
        ixx="8.5346E-07"
        ixy="1.7048E-12"
        ixz="-1.0516E-12"
        iyy="1.7713E-06"
        iyz="2.5119E-07"
        izz="1.691E-06" />
    </inertial>
    <visual>
      <origin
        xyz="0 0 0"
        rpy="0 0 0" />
      <geometry>
        <mesh
          filename="package://bioloidgp_social_robot/meshes/left_arm_link_1.STL" />
      </geometry>
      <material
        name="">
        <color
          rgba="0.79216 0.81961 0.93333 1" />
      </material>
    </visual>
    <collision>
      <origin
        xyz="0 0 0"
        rpy="0 0 0" />
      <geometry>
        <mesh
          filename="package://bioloidgp_social_robot/meshes/left_arm_link_1.STL" />
      </geometry>
    </collision>
  </link>
  <link
    name="left_arm_link_2">
    <inertial>
      <origin
        xyz="-0.035249 0.0031256 0.00047237"
        rpy="0 0 0" />
      <mass
        value="0.088364" />
      <inertia
        ixx="1.8529E-05"
        ixy="1.8067E-07"
        ixz="-8.8092E-09"
        iyy="1.67E-05"
        iyz="1.9248E-07"
        izz="2.19E-05" />
    </inertial>
    <visual>
      <origin
        xyz="0 0 0"
        rpy="0 0 0" />
      <geometry>
        <mesh
          filename="package://bioloidgp_social_robot/meshes/left_arm_link_2.STL" />
      </geometry>
      <material
        name="">
        <color
          rgba="0.79216 0.81961 0.93333 1" />
      </material>
    </visual>
    <collision>
      <origin
        xyz="0 0 0"
        rpy="0 0 0" />
      <geometry>
        <mesh
          filename="package://bioloidgp_social_robot/meshes/left_arm_link_2.STL" />
      </geometry>
    </collision>
  </link>
  <link
    name="left_arm_link_3">
    <inertial>
      <origin
        xyz="-0.0062081 0.042347 -0.016804"
        rpy="0 0 0" />
      <mass
        value="0.053418" />
      <inertia
        ixx="1.0779E-05"
        ixy="-3.02E-09"
        ixz="-1.9098E-07"
        iyy="1.4518E-05"
        iyz="2.527E-07"
        izz="1.4395E-05" />
    </inertial>
    <visual>
      <origin
        xyz="0 0 0"
        rpy="0 0 0" />
      <geometry>
        <mesh
          filename="package://bioloidgp_social_robot/meshes/left_arm_link_3.STL" />
      </geometry>
      <material
        name="">
        <color
          rgba="0.79216 0.81961 0.93333 1" />
      </material>
    </visual>
    <collision>
      <origin
        xyz="0 0 0"
        rpy="0 0 0" />
      <geometry>
        <mesh
          filename="package://bioloidgp_social_robot/meshes/left_arm_link_3.STL" />
      </geometry>
    </collision>
  </link>
  <link
    name="left_gripper">
    <inertial>
      <origin
        xyz="-0.018 -0.0062404 0.036135"
        rpy="0 0 0" />
      <mass
        value="0.0088243" />
      <inertia
        ixx="7.4613E-06"
        ixy="-2.1839E-11"
        ixz="-7.8633E-12"
        iyy="9.3608E-06"
        iyz="-1.8805E-06"
        izz="4.6829E-06" />
    </inertial>
    <visual>
      <origin
        xyz="0 0 0"
        rpy="3.1416 0 3.1416" />
      <geometry>
        <mesh
          filename="package://bioloidgp_social_robot/meshes/left_gripper.STL" />
      </geometry>
      <material
        name="">
        <color
          rgba="0.79216 0.81961 0.93333 1" />
      </material>
    </visual>
    <collision>
      <origin
        xyz="0 0 0"
        rpy="3.1416 0 3.1416" />
      <geometry>
        <mesh
          filename="package://bioloidgp_social_robot/meshes/left_gripper.STL" />
      </geometry>
    </collision>
  </link>


  <link
    name="torso_link">
    <inertial>
      <origin
        xyz="2.63162406857406E-08 -0.0210909555658785 -0.00131922984856178"
        rpy="0 0 0" />
      <mass
        value="0.0150306588580906" />
      <inertia
        ixx="1.22995746902599E-05"
        ixy="-5.36004118527771E-12"
        ixz="4.57561805749191E-15"
        iyy="1.26743899445149E-05"
        iyz="-4.84169136516332E-07"
        izz="1.42781332295549E-05" />
    </inertial>
    <visual>
      <origin
        xyz="0 0 0"
        rpy="0 0 0" />
      <geometry>
        <mesh
          filename="package://bioloidgp_social_robot/meshes/torso_link.STL" />
      </geometry>
      <material
        name="">
        <color
          rgba="0.792156862745098 0.819607843137255 0.933333333333333 1" />
      </material>
    </visual>
    <collision>
      <origin
        xyz="0 0 0"
        rpy="0 0 0" />
      <geometry>
        <mesh
          filename="package://bioloidgp_social_robot/meshes/torso_link.STL" />
      </geometry>
    </collision>
  </link>




  <link
    name="right_leg_link_1">
    <inertial>
      <origin
        xyz="-0.0129819085295125 -0.00228500435172165 0.000908026149630328"
        rpy="0 0 0" />
      <mass
        value="0.047405027669223" />
      <inertia
        ixx="7.27334637836052E-06"
        ixy="5.51374282894484E-08"
        ixz="1.90980207222024E-07"
        iyy="1.32375639686867E-05"
        iyz="-1.50339397226202E-09"
        izz="1.18495804679192E-05" />
    </inertial>
    <visual>
      <origin
        xyz="0 0 0"
        rpy="0 0 0" />
      <geometry>
        <mesh
          filename="package://bioloidgp_social_robot/meshes/right_leg_link_1.STL" />
      </geometry>
      <material
        name="">
        <color
          rgba="0.792156862745098 0.819607843137255 0.933333333333333 1" />
      </material>
    </visual>
    <collision>
      <origin
        xyz="0 0 0"
        rpy="0 0 0" />
      <geometry>
        <mesh
          filename="package://bioloidgp_social_robot/meshes/right_leg_link_1.STL" />
      </geometry>
    </collision>
  </link>

  <link
    name="right_leg_link_2">
    <inertial>
      <origin
        xyz="-0.0130339683821673 -0.0436380731762437 -0.000505151739103829"
        rpy="0 0 0" />
      <mass
        value="0.0891171757796176" />
      <inertia
        ixx="2.07420488419902E-05"
        ixy="1.89476813249674E-07"
        ixz="-1.92483601194151E-07"
        iyy="1.89661820142661E-05"
        iyz="-7.78205227092184E-08"
        izz="1.90005912983823E-05" />
    </inertial>
    <visual>
      <origin
        xyz="0 0 0"
        rpy="0 0 0" />
      <geometry>
        <mesh
          filename="package://bioloidgp_social_robot/meshes/right_leg_link_2.STL" />
      </geometry>
      <material
        name="">
        <color
          rgba="0.792156862745098 0.819607843137255 0.933333333333333 1" />
      </material>
    </visual>
    <collision>
      <origin
        xyz="0 0 0"
        rpy="0 0 0" />
      <geometry>
        <mesh
          filename="package://bioloidgp_social_robot/meshes/right_leg_link_2.STL" />
      </geometry>
    </collision>
  </link>

  <link
    name="right_leg_link_3">
    <inertial>
      <origin
        xyz="0.0139999999999994 0.0335563832066388 0.0151934897642466"
        rpy="0 0 0" />
      <mass
        value="0.00701486534628873" />
      <inertia
        ixx="5.15587753735929E-06"
        ixy="-9.64472061952054E-20"
        ixz="-3.356938423376E-20"
        iyy="3.83307916350284E-06"
        iyz="-4.23987865116651E-07"
        izz="7.34905050588704E-06" />
    </inertial>
    <visual>
      <origin
        xyz="0 0 0"
        rpy="0 0 0" />
      <geometry>
        <mesh
          filename="package://bioloidgp_social_robot/meshes/right_leg_link_3.STL" />
      </geometry>
      <material
        name="">
        <color
          rgba="0.792156862745098 0.819607843137255 0.933333333333333 1" />
      </material>
    </visual>
    <collision>
      <origin
        xyz="0 0 0"
        rpy="0 0 0" />
      <geometry>
        <mesh
          filename="package://bioloidgp_social_robot/meshes/right_leg_link_3.STL" />
      </geometry>
    </collision>
  </link>

  <link
    name="right_leg_link_4">
    <inertial>
      <origin
        xyz="-0.0133946384168482 0.0211528090768007 0.0129875072823342"
        rpy="0 0 0" />
      <mass
        value="0.0873984262026251" />
      <inertia
        ixx="2.17378173151335E-05"
        ixy="7.47586135809127E-20"
        ixz="-2.01292818032275E-07"
        iyy="2.20790808773904E-05"
        iyz="1.82242487051738E-07"
        izz="1.31204837284324E-05" />
    </inertial>
    <visual>
      <origin
        xyz="0 0 0"
        rpy="0 0 0" />
      <geometry>
        <mesh
          filename="package://bioloidgp_social_robot/meshes/right_leg_link_4.STL" />
      </geometry>
      <material
        name="">
        <color
          rgba="0.792156862745098 0.819607843137255 0.933333333333333 1" />
      </material>
    </visual>
    <collision>
      <origin
        xyz="0 0 0"
        rpy="0 0 0" />
      <geometry>
        <mesh
          filename="package://bioloidgp_social_robot/meshes/right_leg_link_4.STL" />
      </geometry>
    </collision>
  </link>

  <link
    name="right_leg_link_5">
    <inertial>
      <origin
        xyz="-0.00578156165290394 -0.0271016298640757 0.0001999999924545"
        rpy="0 0 0" />
      <mass
        value="0.0145032303847989" />
      <inertia
        ixx="9.53948774258595E-06"
        ixy="-6.23592491414207E-15"
        ixz="-6.34588901452735E-16"
        iyy="1.36797822725632E-05"
        iyz="6.68055590641044E-17"
        izz="5.46558889534128E-06" />
    </inertial>
    <visual>
      <origin
        xyz="0 0 0"
        rpy="0 3.1416 0" />
      <geometry>
        <mesh
          filename="package://bioloidgp_social_robot/meshes/right_leg_link_5.STL" />
      </geometry>
      <material
        name="">
        <color
          rgba="0.792156862745098 0.819607843137255 0.933333333333333 1" />
      </material>
    </visual>
    <collision>
      <origin
        xyz="0 0 0"
        rpy="0 3.1416 0" />
      <geometry>
        <mesh
          filename="package://bioloidgp_social_robot/meshes/right_leg_link_5.STL" />
      </geometry>
    </collision>
  </link>

  <link
    name="left_leg_link_1">
    <inertial>
      <origin
        xyz="-0.0129819085295124 -0.00234002672831647 -0.00090802614963037"
        rpy="0 0 0" />
      <mass
        value="0.0474050276692231" />
      <inertia
        ixx="7.27334637836053E-06"
        ixy="3.4512206668867E-08"
        ixz="-1.90980207222015E-07"
        iyy="1.32375639686867E-05"
        iyz="-1.50339397225981E-09"
        izz="1.18495804679193E-05" />
    </inertial>
    <visual>
      <origin
        xyz="0 0 0"
        rpy="0 3.1416 0" />
      <geometry>
        <mesh
          filename="package://bioloidgp_social_robot/meshes/left_leg_link_1.STL" />
      </geometry>
      <material
        name="">
        <color
          rgba="0.792156862745098 0.819607843137255 0.933333333333333 1" />
      </material>
    </visual>
    <collision>
      <origin
        xyz="0 0 0"
        rpy="0 3.1416 0" />
      <geometry>
        <mesh
          filename="package://bioloidgp_social_robot/meshes/left_leg_link_1.STL" />
      </geometry>
    </collision>
  </link>

  <link
    name="left_leg_link_2">
    <inertial>
      <origin
        xyz="0.0130339683821149 -0.043667341802208 -0.000534420365074506"
        rpy="0 0 0" />
      <mass
        value="0.0891171757796176" />
      <inertia
        ixx="2.07420488419902E-05"
        ixy="-1.92483601194349E-07"
        ixz="1.89476813249886E-07"
        iyy="1.89661820142661E-05"
        iyz="-7.78205227092225E-08"
        izz="1.90005912983823E-05" />
    </inertial>
    <visual>
      <origin
        xyz="0 0 0"
        rpy="0 3.1416 0" />
      <geometry>
        <mesh
          filename="package://bioloidgp_social_robot/meshes/left_leg_link_2.STL" />
      </geometry>
      <material
        name="">
        <color
          rgba="0.792156862745098 0.819607843137255 0.933333333333333 1" />
      </material>
    </visual>
    <collision>
      <origin
        xyz="0 0 0"
        rpy="0 3.1416 0" />
      <geometry>
        <mesh
          filename="package://bioloidgp_social_robot/meshes/left_leg_link_2.STL" />
      </geometry>
    </collision>
  </link>

  <link
    name="left_leg_link_3">
    <inertial>
      <origin
        xyz="-0.0140000000000141 0.033556383206642 0.0151934897642171"
        rpy="0 0 0" />
      <mass
        value="0.00701486534628874" />
      <inertia
        ixx="5.15587753735928E-06"
        ixy="3.10577851141471E-19"
        ixz="-2.10972444416208E-18"
        iyy="3.83307916350267E-06"
        iyz="-4.23987865115931E-07"
        izz="7.3490505058872E-06" />
    </inertial>
    <visual>
      <origin
        xyz="0 0 0"
        rpy="0 3.1416 0" />
      <geometry>
        <mesh
          filename="package://bioloidgp_social_robot/meshes/left_leg_link_3.STL" />
      </geometry>
      <material
        name="">
        <color
          rgba="0.792156862745098 0.819607843137255 0.933333333333333 1" />
      </material>
    </visual>
    <collision>
      <origin
        xyz="0 0 0"
        rpy="0 3.1416 0" />
      <geometry>
        <mesh
          filename="package://bioloidgp_social_robot/meshes/left_leg_link_3.STL" />
      </geometry>
    </collision>
  </link>


  <link
    name="left_leg_link_4">
    <inertial>
      <origin
        xyz="0.013424 0.021123 0.012988"
        rpy="0 0 0" />
      <mass
        value="0.087398" />
      <inertia
        ixx="2.1738E-05"
        ixy="-2.5019E-19"
        ixz="1.8067E-07"
        iyy="2.2079E-05"
        iyz="2.0287E-07"
        izz="1.312E-05" />
    </inertial>
    <visual>
      <origin
        xyz="0 0 0"
        rpy="0 0 3.1416" />
      <geometry>
        <mesh
          filename="package://bioloidgp_social_robot/meshes/left_leg_link_4.STL" />
      </geometry>
      <material
        name="">
        <color
          rgba="0.79216 0.81961 0.93333 1" />
      </material>
    </visual>
    <collision>
      <origin
        xyz="0 0 0"
        rpy="0 0 3.1416" />
      <geometry>
        <mesh
          filename="package://bioloidgp_social_robot/meshes/left_leg_link_4.STL" />
      </geometry>
    </collision>
  </link>


  <link
    name="left_leg_link_5">
    <inertial>
      <origin
        xyz="0.0095816 -0.027202 0.0002"
        rpy="0 0 0" />
      <mass
        value="0.014503" />
      <inertia
        ixx="9.5395E-06"
        ixy="-6.2359E-15"
        ixz="-6.3559E-16"
        iyy="1.368E-05"
        iyz="6.696E-17"
        izz="5.4656E-06" />
    </inertial>
    <visual>
      <origin
        xyz="0 0 0"
        rpy="0 3.1416 0" />
      <geometry>
        <mesh
          filename="package://bioloidgp_social_robot/meshes/left_leg_link_5.STL" />
      </geometry>
      <material
        name="">
        <color
          rgba="0.79216 0.81961 0.93333 1" />
      </material>
    </visual>
    <collision>
      <origin
        xyz="0 0 0"
        rpy="0 3.1416 0" />
      <geometry>
        <mesh
          filename="package://bioloidgp_social_robot/meshes/left_leg_link_5.STL" />
      </geometry>
    </collision>
  </link>

  <link
    name="head_link">
    <inertial>
      <origin
        xyz="0 0 0"
        rpy="0 0 0" />
      <mass
        value="0" />
      <inertia
        ixx="0"
        ixy="0"
        ixz="0"
        iyy="0"
        iyz="0"
        izz="0" />
    </inertial>
    <visual>
      <origin
        xyz="0 0 0"
        rpy="0 0 0" />
      <geometry>
        <mesh
          filename="package://bioloidgp_social_robot/meshes/head_link.STL" />
      </geometry>
      <material
        name="">
        <color
          rgba="1 1 1 1" />
      </material>
    </visual>
    <collision>
      <origin
        xyz="0 0 0"
        rpy="0 0 0" />
      <geometry>
        <mesh
          filename="package://bioloidgp_social_robot/meshes/head_link.STL" />
      </geometry>
    </collision>
  </link>

  <link
    name="camera">
    <inertial>
      <origin
        xyz="-0.00033356 0.0036577 0.036647"
        rpy="0 0 0" />
      <mass
        value="0.096022" />
      <inertia
        ixx="1.43E-05"
        ixy="-4.3064E-09"
        ixz="4.3532E-07"
        iyy="4.1194E-05"
        iyz="9.0106E-09"
        izz="3.6198E-05" />
    </inertial>
    <visual>
      <origin
        xyz="0 0 0"
        rpy="0 0 3.1416" />
      <geometry>
        <mesh
          filename="package://bioloidgp_social_robot/meshes/camera.STL" />
      </geometry>
      <material
        name="">
        <color
          rgba="0.79216 0.81961 0.93333 1" />
      </material>
    </visual>
    <collision>
      <origin
        xyz="0 0 0"
        rpy="0 0 3.1416" />
      <geometry>
        <mesh
          filename="package://bioloidgp_social_robot/meshes/camera.STL" />
      </geometry>
    </collision>
  </link>




  <joint
    name="joint_1"
    type="continuous">
    <origin
      xyz="0.00875 -0.05649 0.00275"
      rpy="3.1416 0 3.1416" />
    <parent
      link="base_link" />
    <child
      link="right_arm_link_1" />
    <axis
      xyz="0 1 0" />
  </joint>
  <joint
    name="joint_2"
    type="continuous">
    <origin
      xyz="0.00875 0.05649 0.00275"
      rpy="3.1416 0 0" />
    <parent
      link="base_link" />
    <child
      link="left_arm_link_1" />
    <axis
      xyz="0 1 0" />
  </joint>
  <joint
    name="joint_3"
    type="continuous">
    <origin
      xyz="0 -0.02301 0.018"
      rpy="-1.5708 0 1.5708" />
    <parent
      link="right_arm_link_1" />
    <child
      link="right_arm_link_2" />
    <axis
      xyz="0 0 1" />
  </joint>
  <joint
    name="joint_4"
    type="continuous">
    <origin
      xyz="0 -0.0230095805758357 0.0179999999999604"
      rpy="1.5707963267949 1.5707963267949 0" />
    <parent
      link="left_arm_link_1" />
    <child
      link="left_arm_link_2" />
    <axis
      xyz="0 1 0" />
  </joint>
  <joint
    name="joint_5"
    type="continuous">
    <origin
      xyz="0 -0.0574 0.0182"
      rpy="1.5708 0 0" />
    <parent
      link="right_arm_link_2" />
    <child
      link="right_arm_link_3" />
    <axis
      xyz="1 0 0" />
  </joint>
  <joint
    name="joint_6"
    type="continuous">
    <origin
      xyz="-0.0573999999999997 0.0182000000000009 0"
      rpy="0 1.5707963267949 0" />
    <parent
      link="left_arm_link_2" />
    <child
      link="left_arm_link_3" />
    <axis
      xyz="1 0 0" />
  </joint>
  <joint
    name="joint_7"
    type="continuous">
    <origin
      xyz="-0.0225 0.0425 0"
      rpy="1.5707963267949 -1.5707963267949 0" />
    <parent
      link="right_arm_link_3" />
    <child
      link="right_gripper" />
    <axis
      xyz="1 0 0" />
  </joint>
  <joint
    name="joint_8"
    type="continuous">
    <origin
      xyz="-0.0225000000000029 0.0424999999999997 0"
      rpy="1.5707963267949 1.5707963267949 0" />
    <parent
      link="left_arm_link_3" />
    <child
      link="left_gripper" />
    <axis
      xyz="1 0 0" />
  </joint>
  <joint
    name="joint_9"
    type="continuous">
    <origin
      xyz="-0.016 -0.0535000000000006 0"
      rpy="0 0 0" />
    <parent
      link="torso_link" />
    <child
      link="right_leg_link_1" />
    <axis
      xyz="0 0 1" />
  </joint>
  <joint
    name="joint_10"
    type="continuous">
    <origin
      xyz="0.016 -0.0535000000000006 0"
      rpy="0 0 0" />
    <parent
      link="torso_link" />
    <child
      link="left_leg_link_1" />
    <axis
      xyz="0 0 1" />
  </joint>
  <joint
    name="joint_11"
    type="continuous">
    <origin
      xyz="0 -0.0417999999999987 0"
      rpy="0 0 0" />
    <parent
      link="right_leg_link_1" />
    <child
      link="right_leg_link_2" />
    <axis
      xyz="1 0 0" />
  </joint>
  <joint
    name="joint_12"
    type="continuous">
    <origin
      xyz="0 -0.0418000000000007 0"
      rpy="3.14159265358979 0 -3.14159265358979" />
    <parent
      link="left_leg_link_1" />
    <child
      link="left_leg_link_2" />
    <axis
      xyz="1 0 0" />
  </joint>
  <joint
    name="joint_13"
    type="continuous">
    <origin
      xyz="0 -0.0744000000000003 -0.0144999999999987"
      rpy="0 0 3.14159265358979" />
    <parent
      link="right_leg_link_2" />
    <child
      link="right_leg_link_3" />
    <axis
      xyz="1 0 0" />
  </joint>
  <joint
    name="joint_14"
    type="continuous">
    <origin
      xyz="0 -0.0744 0.0145000000000106"
      rpy="0 0 -3.14159265358979" />
    <parent
      link="left_leg_link_2" />
    <child
      link="left_leg_link_3" />
    <axis
      xyz="1 0 0" />
  </joint>
  <joint
    name="joint_15"
    type="continuous">
    <origin
      xyz="0 0.0749999999999997 0.0145000000000012"
      rpy="-1.57079632679491 0 -3.14159265358979" />
    <parent
      link="right_leg_link_3" />
    <child
      link="right_leg_link_4" />
    <axis
      xyz="1 0 0" />
  </joint>
  <joint
    name="joint_16"
    type="continuous">
    <origin
      xyz="0 0.0750000000000028 -0.0144999999999764"
      rpy="-1.57079632679471 0 3.14159265358979" />
    <parent
      link="left_leg_link_3" />
    <child
      link="left_leg_link_4" />
    <axis
      xyz="1 0 0" />
  </joint>
  <joint
    name="joint_17"
    type="continuous">
    <origin
      xyz="-0.0138000000000002 0 -9.99999999997669E-05"
      rpy="1.57079632679491 0 3.1416" />
    <parent
      link="right_leg_link_4" />
    <child
      link="right_leg_link_5" />
    <axis
      xyz="0 0 1" />
  </joint>
  <joint
    name="joint_18"
    type="continuous">
    <origin
      xyz="-0.01 0 0"
      rpy="1.57079632679471 0 0" />
    <parent
      link="left_leg_link_4" />
    <child
      link="left_leg_link_5" />
    <axis
      xyz="0 0 1" />
  </joint>
  <joint
    name="joint_19"
    type="continuous">
    <origin
      xyz="0.00825 0 -0.05725"
      rpy="1.5708 0 1.5708" />
    <parent
      link="base_link" />
    <child
      link="torso_link" />
    <axis
      xyz="0 1 0" />
  </joint>
  <joint
    name="joint_20"
    type="continuous">
    <origin
      xyz="0.00825000000000002 0 0.0220498969223593"
      rpy="3.14159265358979 0 -1.60287187004926" />
    <parent
      link="base_link" />
    <child
      link="head_link" />
    <axis
      xyz="0 0 1" />
  </joint>
  <joint
    name="joint_21"
    type="continuous">
    <origin
      xyz="0 0 -0.05"
      rpy="-1.5707963267949 3.14159265358979 3.14159265358979" />
    <parent
      link="head_link" />
    <child
      link="camera" />
    <axis
      xyz="1 0 0" />
  </joint>
</robot>