<?xml version="1.0" encoding="utf-8"?>
<!-- This URDF was automatically created by SolidWorks to URDF Exporter! Originally created by Stephen Brawner (brawner@gmail.com) 
     Commit Version: 1.5.1-0-g916b5db  Build Version: 1.5.7152.31018
     For more information, please see http://wiki.ros.org/sw_urdf_exporter -->
<robot
  name="bioloidgp_social_robot">

  <link name="dummy">
  </link>

  <link
    name="base_link">
    <inertial>
      <origin
        xyz="-0.00011765 -8.1843E-08 -0.010051"
        rpy="0 0 0" />
      <mass
        value="0.23897" />
      <inertia ixx="1" ixy="0"  ixz="0"
               iyy="1" iyz="0"
               izz="1" />
    </inertial>
    <visual>
      <origin
        xyz="0 0 0"
        rpy="0 0 0" />
      <geometry>
        <mesh
          filename="package://bioloidgp_social_robot/meshes/base_link.STL" />
      </geometry>
      <material
        name="">
        <color
          rgba="0.79216 0.81961 0.93333 1" />
      </material>
    </visual>
    <collision>
      <origin
        xyz="0 0 0"
        rpy="0 0 0" />
      <geometry>
        <mesh
          filename="package://bioloidgp_social_robot/meshes/base_link.STL" />
      </geometry>
    </collision>
  </link>

  <joint name="dummy_joint" type="fixed">
     <parent link="dummy"/>
     <child link="base_link"/>
  </joint>

  <joint 
    name="imu_to_base_joint" 
    type="fixed">
    <origin 
      xyz="0.00824999999999999 0 -0.035"
      rpy="0 0 0" />
    <parent link="base_link"/>
    <child link="imu_link"/>
  </joint>

  <link 
    name="imu_link">
    <visual>
      <geometry>
        <box size="0.016 0.026 0.005"/>
      </geometry>
      <material name="green">
        <color rgba="0.0 1.0 0.0 1.0"/>
      </material>
    </visual>
  </link>

  <link
    name="right_arm_link_1">
    <inertial>
      <origin
        xyz="-6.07043906253324E-08 -0.0092320672392501 0.00517864249850521"
        rpy="0 0 0" />
      <mass
        value="0.00402029367652138" />
      <inertia
        ixx="1" ixy="0"  ixz="0"
               iyy="1" iyz="0"
               izz="1" />
    </inertial>
    <visual>
      <origin
        xyz="0 0 0"
        rpy="0 0 3.14159265358979" />
      <geometry>
        <mesh
          filename="package://bioloidgp_social_robot/meshes/right_arm_link_1.STL" />
      </geometry>
      <material
        name="">
        <color
          rgba="0.792156862745098 0.819607843137255 0.933333333333333 1" />
      </material>
    </visual>
    <collision>
      <origin
        xyz="0 0 0"
        rpy="0 0 3.14159265358979" />
      <geometry>
        <mesh
          filename="package://bioloidgp_social_robot/meshes/right_arm_link_1.STL" />
      </geometry>
    </collision>
  </link>
  <link
    name="right_arm_link_2">
    <inertial>
      <origin
        xyz="-0.000528170386428523 -0.0352518252774793 0.00311828556966412"
        rpy="0 0 0" />
      <mass
        value="0.0866430294972451" />
      <inertia
        ixx="1" ixy="0"  ixz="0"
               iyy="1" iyz="0"
               izz="1" />
    </inertial>
    <visual>
      <origin
        xyz="0 0 0"
        rpy="0 3.14159265358979 0" />
      <geometry>
        <mesh
          filename="package://bioloidgp_social_robot/meshes/right_arm_link_2.STL" />
      </geometry>
      <material
        name="">
        <color
          rgba="0.792156862745098 0.819607843137255 0.933333333333333 1" />
      </material>
    </visual>
    <collision>
      <origin
        xyz="0 0 0"
        rpy="0 3.14159265358979 0" />
      <geometry>
        <mesh
          filename="package://bioloidgp_social_robot/meshes/right_arm_link_2.STL" />
      </geometry>
    </collision>
  </link>
  <link
    name="right_arm_link_3">
    <inertial>
      <origin
        xyz="-0.00609948658909117 0.0423952309716983 0.0167593854637861"
        rpy="0 0 0" />
      <mass
        value="0.0525573198575286" />
      <inertia
        ixx="1" ixy="0"  ixz="0"
               iyy="1" iyz="0"
               izz="1" />
    </inertial>
    <visual>
      <origin
        xyz="0 0 0"
        rpy="0 0 3.14159265358979" />
      <geometry>
        <mesh
          filename="package://bioloidgp_social_robot/meshes/right_arm_link_3.STL" />
      </geometry>
      <material
        name="">
        <color
          rgba="0.792156862745098 0.819607843137255 0.933333333333333 1" />
      </material>
    </visual>
    <collision>
      <origin
        xyz="0 0 0"
        rpy="0 0 3.14159265358979" />
      <geometry>
        <mesh
          filename="package://bioloidgp_social_robot/meshes/right_arm_link_3.STL" />
      </geometry>
    </collision>
  </link>  
  <link
    name="right_gripper">
    <inertial>
      <origin
        xyz="0.0179998120299161 -0.00624035209800904 0.0361347174477126"
        rpy="3.14159265358979 0 0" />
      <mass
        value="0.00882433124339025" />
      <inertia
        ixx="1" ixy="0"  ixz="0"
               iyy="1" iyz="0"
               izz="1" />
    </inertial>
    <visual>
      <origin
        xyz="0 0 0"
        rpy="3.14159265358979 3.14159265358979 0" />
      <geometry>
        <mesh
          filename="package://bioloidgp_social_robot/meshes/right_gripper.STL" />
      </geometry>
      <material
        name="">
        <color
          rgba="0.792156862745098 0.819607843137255 0.933333333333333 1" />
      </material>
    </visual>
    <collision>
      <origin
        xyz="0 0 0"
        rpy="3.14159265358979 3.14159265358979 0" />
      <geometry>
        <mesh
          filename="package://bioloidgp_social_robot/meshes/right_gripper.STL" />
      </geometry>
    </collision>
  </link>



  <link
    name="left_arm_link_1">
    <inertial>
      <origin
        xyz="-6.07043893069426E-08 -0.00923206723925155 0.00517864249850553"
        rpy="0 0 0" />
      <mass
        value="0.00402029367652142" />
      <inertia
      ixx="1" ixy="0"  ixz="0"
               iyy="1" iyz="0"
               izz="1" />
    </inertial>
    <visual>
      <origin
        xyz="0 0 0"
        rpy="0 0 3.14159265358979" />
      <geometry>
        <mesh
          filename="package://bioloidgp_social_robot/meshes/left_arm_link_1.STL" />
      </geometry>
      <material
        name="">
        <color
          rgba="0.792156862745098 0.819607843137255 0.933333333333333 1" />
      </material>
    </visual>
    <collision>
      <origin
        xyz="0 0 0"
        rpy="0 0 3.14159265358979" />
      <geometry>
        <mesh
          filename="package://bioloidgp_social_robot/meshes/left_arm_link_1.STL" />
      </geometry>
    </collision>
  </link>
  <link
    name="left_arm_link_2">
    <inertial>
      <origin
        xyz="0.000496348530981336 -0.0352836471329275 0.00311828556966445"
        rpy="0 0 0" />
      <mass
        value="0.086643029497245" />
      <inertia
        ixx="1" ixy="0"  ixz="0"
               iyy="1" iyz="0"
               izz="1" />
    </inertial>
    <visual>
      <origin
        xyz="0 0 0"
        rpy="0 3.14159265358979 0" />
      <geometry>
        <mesh
          filename="package://bioloidgp_social_robot/meshes/left_arm_link_2.STL" />
      </geometry>
      <material
        name="">
        <color
          rgba="0.792156862745098 0.819607843137255 0.933333333333333 1" />
      </material>
    </visual>
    <collision>
      <origin
        xyz="0 0 0"
        rpy="0 3.14159265358979 0" />
      <geometry>
        <mesh
          filename="package://bioloidgp_social_robot/meshes/left_arm_link_2.STL" />
      </geometry>
    </collision>
  </link>
  <link
    name="left_arm_link_3">
    <inertial>
      <origin
        xyz="0.00609949587607726 0.0423427712578516 0.0167593854607105"
        rpy="0 0 0" />
      <mass
        value="0.0525573198575286" />
      <inertia
        ixx="1" ixy="0"  ixz="0"
               iyy="1" iyz="0"
               izz="1" />
    </inertial>
    <visual>
      <origin
        xyz="0 0 0"
        rpy="3.14159265358979 0 0" />
      <geometry>
        <mesh
          filename="package://bioloidgp_social_robot/meshes/left_arm_link_3.STL" />
      </geometry>
      <material
        name="">
        <color
          rgba="0.792156862745098 0.819607843137255 0.933333333333333 1" />
      </material>
    </visual>
    <collision>
      <origin
        xyz="0 0 0"
        rpy="3.14159265358979 0 0" />
      <geometry>
        <mesh
          filename="package://bioloidgp_social_robot/meshes/left_arm_link_3.STL" />
      </geometry>
    </collision>
  </link>
  <link
    name="left_gripper">
    <inertial>
      <origin
        xyz="-0.0180001879700939 -0.00624035209800401 0.0361347174477273"
        rpy="3.14159265358979 0 0" />
      <mass
        value="0.00882433124339499" />
      <inertia
        ixx="1" ixy="0"  ixz="0"
               iyy="1" iyz="0"
               izz="1" />
    </inertial>
    <visual>
      <origin
        xyz="0 0 0"
        rpy="3.14159265358979 0 0" />
      <geometry>
        <mesh
          filename="package://bioloidgp_social_robot/meshes/left_gripper.STL" />
      </geometry>
      <material
        name="">
        <color
          rgba="0.792156862745098 0.819607843137255 0.933333333333333 1" />
      </material>
    </visual>
    <collision>
      <origin
        xyz="0 0 0"
        rpy="3.14159265358979 0 0" />
      <geometry>
        <mesh
          filename="package://bioloidgp_social_robot/meshes/left_gripper.STL" />
      </geometry>
    </collision>
  </link>
  




  <link
    name="torso_Link">
    <inertial>
      <origin
        xyz="2.63162408644171E-08 -0.0210909555658786 -0.00131922984856178"
        rpy="0 0 0" />
      <mass
        value="0.0150306588580905" />
      <inertia
        ixx="1" ixy="0"  ixz="0"
               iyy="1" iyz="0"
               izz="1" />
    </inertial>
    <visual>
      <origin
        xyz="0 0 0"
        rpy="0 0 0" />
      <geometry>
        <mesh
          filename="package://bioloidgp_social_robot/meshes/torso_Link.STL" />
      </geometry>
      <material
        name="">
        <color
          rgba="0.792156862745098 0.819607843137255 0.933333333333333 1" />
      </material>
    </visual>
    <collision>
      <origin
        xyz="0 0 0"
        rpy="0 0 0" />
      <geometry>
        <mesh
          filename="package://bioloidgp_social_robot/meshes/torso_Link.STL" />
      </geometry>
    </collision>
  </link>




  <link
    name="right_leg_link_1">
    <inertial>
      <origin
        xyz="-0.0130433690693261 -0.002325655487879 0.000953577437985034"
        rpy="0 0 0" />
      <mass
        value="0.0465444227419532" />
      <inertia
        ixx="1" ixy="0"  ixz="0"
               iyy="1" iyz="0"
               izz="1" />
    </inertial>
    <visual>
      <origin
        xyz="0 0 0"
        rpy="0 3.14159265358979 0" />
      <geometry>
        <mesh
          filename="package://bioloidgp_social_robot/meshes/right_leg_link_1.STL" />
      </geometry>
      <material
        name="">
        <color
          rgba="0.792156862745098 0.819607843137255 0.933333333333333 1" />
      </material>
    </visual>
    <collision>
      <origin
        xyz="0 0 0"
        rpy="0 3.14159265358979 0" />
      <geometry>
        <mesh
          filename="package://bioloidgp_social_robot/meshes/right_leg_link_1.STL" />
      </geometry>
    </collision>
  </link>

  <link
    name="right_leg_link_2">
    <inertial>
      <origin
        xyz="-0.0129843075496472 -0.0436689123978272 -0.000466568121460592"
        rpy="0 0 0" />
      <mass
        value="0.0873959659250779" />
      <inertia
        ixx="1" ixy="0"  ixz="0"
               iyy="1" iyz="0"
               izz="1" />
    </inertial>
    <visual>
      <origin
        xyz="0 0 0"
        rpy="0 3.14159265358979 0" />
      <geometry>
        <mesh
          filename="package://bioloidgp_social_robot/meshes/right_leg_link_2.STL" />
      </geometry>
      <material
        name="">
        <color
          rgba="0.792156862745098 0.819607843137255 0.933333333333333 1" />
      </material>
    </visual>
    <collision>
      <origin
        xyz="0 0 0"
        rpy="0 3.14159265358979 0" />
      <geometry>
        <mesh
          filename="package://bioloidgp_social_robot/meshes/right_leg_link_2.STL" />
      </geometry>
    </collision>
  </link>

  <link
    name="right_leg_link_3">
    <inertial>
      <origin
        xyz="0.0139999999999992 0.033556383206639 0.015193489764246"
        rpy="0 0 0" />
      <mass
        value="0.00701486534628872" />
      <inertia
        ixx="1" ixy="0"  ixz="0"
               iyy="1" iyz="0"
               izz="1" />
    </inertial>
    <visual>
      <origin
        xyz="0 0 0"
        rpy="0 3.14159265358979 0" />
      <geometry>
        <mesh
          filename="package://bioloidgp_social_robot/meshes/right_leg_link_3.STL" />
      </geometry>
      <material
        name="">
        <color
          rgba="0.792156862745098 0.819607843137255 0.933333333333333 1" />
      </material>
    </visual>
    <collision>
      <origin
        xyz="0 0 0"
        rpy="0 3.14159265358979 0" />
      <geometry>
        <mesh
          filename="package://bioloidgp_social_robot/meshes/right_leg_link_3.STL" />
      </geometry>
    </collision>
  </link>

  <link
    name="right_leg_link_4">
    <inertial>
      <origin
        xyz="-0.013367992566117 0.0211280641759689 0.0130554015027962"
        rpy="0 0 0" />
      <mass
        value="0.0856772163480855" />
      <inertia
        ixx="1" ixy="0"  ixz="0"
               iyy="1" iyz="0"
               izz="1" />
    </inertial>
    <visual>
      <origin
        xyz="0 0 0"
        rpy="3.14159265358979 3.14159265358979 0" />
      <geometry>
        <mesh
          filename="package://bioloidgp_social_robot/meshes/right_leg_link_4.STL" />
      </geometry>
      <material
        name="">
        <color
          rgba="0.792156862745098 0.819607843137255 0.933333333333333 1" />
      </material>
    </visual>
    <collision>
      <origin
        xyz="0 0 0"
        rpy="3.14159265358979 3.14159265358979 0" />
      <geometry>
        <mesh
          filename="package://bioloidgp_social_robot/meshes/right_leg_link_4.STL" />
      </geometry>
    </collision>
  </link>

  <link
    name="right_leg_link_5">
    <inertial>
      <origin
        xyz="0.00019999999245765 -0.0271016298640742 0.00578156165290536"
        rpy="0 0 0" />
      <mass
        value="0.0145032303847989" />
      <inertia
        ixx="1" ixy="0"  ixz="0"
               iyy="1" iyz="0"
               izz="1" />
    </inertial>
    <visual>
      <origin
        xyz="0 0 0"
        rpy="0 0 0" />
      <geometry>
        <mesh
          filename="package://bioloidgp_social_robot/meshes/right_leg_link_5.STL" />
      </geometry>
      <material
        name="">
        <color
          rgba="0.792156862745098 0.819607843137255 0.933333333333333 1" />
      </material>
    </visual>
    <collision>
      <origin
        xyz="0 0 0"
        rpy="0 0 0" />
      <geometry>
        <mesh
          filename="package://bioloidgp_social_robot/meshes/right_leg_link_5.STL" />
      </geometry>
    </collision>
  </link>

  <link
    name="left_leg_link_1">
    <inertial>
      <origin
        xyz="-0.013043369069326 -0.00238489227282189 -0.000953577437985048"
        rpy="0 0 0" />
      <mass
        value="0.0465444227419532" />
      <inertia
        ixx="1" ixy="0"  ixz="0"
               iyy="1" iyz="0"
               izz="1" />
    </inertial>
    <visual>
      <origin
        xyz="0 0 0"
        rpy="0 0 0" />
      <geometry>
        <mesh
          filename="package://bioloidgp_social_robot/meshes/left_leg_link_1.STL" />
      </geometry>
      <material
        name="">
        <color
          rgba="0.792156862745098 0.819607843137255 0.933333333333333 1" />
      </material>
    </visual>
    <collision>
      <origin
        xyz="0 0 0"
        rpy="0 0 0" />
      <geometry>
        <mesh
          filename="package://bioloidgp_social_robot/meshes/left_leg_link_1.STL" />
      </geometry>
    </collision>
  </link>
  
  <link
    name="left_leg_link_2">
    <inertial>
      <origin
        xyz="0.0129843075495947 -0.0437004601006425 -0.000498115824281359"
        rpy="0 0 0" />
      <mass
        value="0.0873959659250778" />
      <inertia
        ixx="1" ixy="0"  ixz="0"
               iyy="1" iyz="0"
               izz="1" />
    </inertial>
    <visual>
      <origin
        xyz="0 0 0"
        rpy="0 0 0" />
      <geometry>
        <mesh
          filename="package://bioloidgp_social_robot/meshes/left_leg_link_2.STL" />
      </geometry>
      <material
        name="">
        <color
          rgba="0.792156862745098 0.819607843137255 0.933333333333333 1" />
      </material>
    </visual>
    <collision>
      <origin
        xyz="0 0 0"
        rpy="0 0 0" />
      <geometry>
        <mesh
          filename="package://bioloidgp_social_robot/meshes/left_leg_link_2.STL" />
      </geometry>
    </collision>
  </link>

  <link
    name="left_leg_link_3">
    <inertial>
      <origin
        xyz="-0.0140000000000142 0.033556383206639 0.0151934897642235"
        rpy="0 0 0" />
      <mass
        value="0.00701486534628872" />
      <inertia
        ixx="1" ixy="0"  ixz="0"
               iyy="1" iyz="0"
               izz="1" />
    </inertial>
    <visual>
      <origin
        xyz="0 0 0"
        rpy="0 0 0" />
      <geometry>
        <mesh
          filename="package://bioloidgp_social_robot/meshes/left_leg_link_3.STL" />
      </geometry>
      <material
        name="">
        <color
          rgba="0.792156862745098 0.819607843137255 0.933333333333333 1" />
      </material>
    </visual>
    <collision>
      <origin
        xyz="0 0 0"
        rpy="0 0 0" />
      <geometry>
        <mesh
          filename="package://bioloidgp_social_robot/meshes/left_leg_link_3.STL" />
      </geometry>
    </collision>
  </link>


  <link
    name="left_leg_link_4">
    <inertial>
      <origin
        xyz="0.0134001731396108 0.0210958836024548 0.0130554015027963"
        rpy="0 0 0" />
      <mass
        value="0.0856772163480854" />
      <inertia
        ixx="1" ixy="0"  ixz="0"
               iyy="1" iyz="0"
               izz="1" />
    </inertial>
    <visual>
      <origin
        xyz="0 0 0"
        rpy="0 0 0" />
      <geometry>
        <mesh
          filename="package://bioloidgp_social_robot/meshes/left_leg_link_4.STL" />
      </geometry>
      <material
        name="">
        <color
          rgba="0.792156862745098 0.819607843137255 0.933333333333333 1" />
      </material>
    </visual>
    <collision>
      <origin
        xyz="0 0 0"
        rpy="0 0 0" />
      <geometry>
        <mesh
          filename="package://bioloidgp_social_robot/meshes/left_leg_link_4.STL" />
      </geometry>
    </collision>
  </link>


  <link
    name="left_leg_link_5">
    <inertial>
      <origin
        xyz="-0.00019999999247397 0.0271016298640752 -0.00578156174805475"
        rpy="0 0 0" />
      <mass
        value="0.014503230384799" />
      <inertia
        ixx="1" ixy="0"  ixz="0"
               iyy="1" iyz="0"
               izz="1" />
    </inertial>
    <visual>
      <origin
        xyz="0 0 0"
        rpy="3.14159265358979 3.14159265358979 0" />
      <geometry>
        <mesh
          filename="package://bioloidgp_social_robot/meshes/left_leg_link_5.STL" />
      </geometry>
      <material
        name="">
        <color
          rgba="0.792156862745098 0.819607843137255 0.933333333333333 1" />
      </material>
    </visual>
    <collision>
      <origin
        xyz="0 0 0"
        rpy="3.14159265358979 3.14159265358979 0" />
      <geometry>
        <mesh
          filename="package://bioloidgp_social_robot/meshes/left_leg_link_5.STL" />
      </geometry>
    </collision>
  </link>

  <link
    name="head_link">
    <inertial>
      <origin
        xyz="1.92660815674303E-07 0.000589833196490114 -0.0219995934404275"
        rpy="0 0 0" />
      <mass
        value="0.0131552831434282" />
      <inertia
        ixx="1" ixy="0"  ixz="0"
               iyy="1" iyz="0"
               izz="1" />
    </inertial>
    <visual>
      <origin
        xyz="0 0 0"
        rpy="0 3.14159265358979 3.14159265358979" />
      <geometry>
        <mesh
          filename="package://bioloidgp_social_robot/meshes/head_link.STL" />
      </geometry>
      <material
        name="">
        <color
          rgba="0.792156862745098 0.819607843137255 0.933333333333333 1" />
      </material>
    </visual>
    <collision>
      <origin
        xyz="0 0 0"
        rpy="0 3.14159265358979 3.14159265358979" />
      <geometry>
        <mesh
          filename="package://bioloidgp_social_robot/meshes/head_link.STL" />
      </geometry>
    </collision>
  </link>

  <link
    name="camera">
    <inertial>
      <origin
        xyz="-4.35600903253008E-05 -0.0368907986255788 0.000350622600154388"
        rpy="0 0 0" />
      <mass
        value="0.0951615153632961" />
      <inertia
        ixx="1" ixy="0"  ixz="0"
               iyy="1" iyz="0"
               izz="1" />
    </inertial>
    <visual>
      <origin
        xyz="0 0 0"
        rpy="3.14159265358979 0 0" />
      <geometry>
        <mesh
          filename="package://bioloidgp_social_robot/meshes/camera.STL" />
      </geometry>
      <material
        name="">
        <color
          rgba="0.792156862745098 0.819607843137255 0.933333333333333 1" />
      </material>
    </visual>
    <collision>
      <origin
        xyz="0 0 0"
        rpy="3.14159265358979 0 0" />
      <geometry>
        <mesh
          filename="package://bioloidgp_social_robot/meshes/camera.STL" />
      </geometry>
    </collision>
  </link>




  <joint
    name="joint_1"
    type="continuous">
    <origin
      xyz="0.00874999999999919 -0.0564904194241639 0.00275000000000068"
      rpy="3.14159265358979 0 0" />
    <parent
      link="base_link" />
    <child
      link="right_arm_link_1" />
    <axis
      xyz="0 1 0" />
    <safety_controller
      k_velocity="0" />
  </joint>
  <joint
    name="joint_2"
    type="continuous">
    <origin
      xyz="0.00874999999999918 0.0564904194241643 0.00275"
      rpy="3.14159265358979 0 3.14159265358979" />
    <parent
      link="base_link" />
    <child
      link="left_arm_link_1" />
    <axis
      xyz="0 1 0" />
    <safety_controller
      k_velocity="0" />
  </joint>
  <joint
    name="joint_3"
    type="continuous">
    <origin
      xyz="0 0.0230095805758343 0.0179999999999891"
      rpy="-1.5707963267949 0 1.5707963267949" />
    <parent
      link="right_arm_link_1" />
    <child
      link="right_arm_link_2" />
    <axis
      xyz="0 0 1" />
    <safety_controller
      k_velocity="0" />
  </joint>
  <joint
    name="joint_4"
    type="continuous">
    <origin
      xyz="0 0.0230095805758357 0.0179999999999895"
      rpy="-1.5707963267949 0 -1.5707963267949" />
    <parent
      link="left_arm_link_1" />
    <child
      link="left_arm_link_2" />
    <axis
      xyz="0 0 1" />
    <safety_controller
      k_velocity="0" />
  </joint>
  <joint
    name="joint_5"
    type="continuous">
    <origin
      xyz="0 -0.0574 -0.0182000000000002"
      rpy="1.5707963267949 0 0" />
    <parent
      link="right_arm_link_2" />
    <child
      link="right_arm_link_3" />
    <axis
      xyz="1 0 0" />
    <safety_controller
      k_velocity="0" />
  </joint>
  <joint
    name="joint_6"
    type="continuous">
    <origin
      xyz="0 -0.0573999999999997 -0.0182000000000009"
      rpy="1.5707963267949 0 3.14159265358979" />
    <parent
      link="left_arm_link_2" />
    <child
      link="left_arm_link_3" />
    <axis
      xyz="1 0 0" />
    <safety_controller
      k_velocity="0" />
  </joint>
  <joint
    name="joint_7"
    type="continuous">
    <origin
      xyz="0.0224999999999999 -0.0425 0"
      rpy="1.5707963267949 1.5707963267949 0" />
    <parent
      link="right_arm_link_3" />
    <child
      link="right_gripper" />
    <axis
      xyz="1 0 0" />
    <safety_controller
      k_velocity="0" />
  </joint>
  <joint
    name="joint_8"
    type="continuous">
    <origin
      xyz="0.0225000000000024 -0.0424999999999999 0"
      rpy="-1.5707963267949 -1.5707963267949 0" />
    <parent
      link="left_arm_link_3" />
    <child
      link="left_gripper" />
    <axis
      xyz="1 0 0" />
    <safety_controller
      k_velocity="0" />
  </joint>
  <joint
    name="joint_9"
    type="continuous">
    <origin
      xyz="-0.016 -0.0535000000000009 0"
      rpy="-3.14159265358979 0 3.14159265358979" />
    <parent
      link="torso_Link" />
    <child
      link="right_leg_link_1" />
    <axis
      xyz="0 0 1" />
    <safety_controller
      k_velocity="0" />
  </joint>
  <joint
    name="joint_10"
    type="continuous">
    <origin
      xyz="0.016 -0.0535000000000007 0"
      rpy="3.14159265358979 0 3.14159265358979" />
    <parent
      link="torso_Link" />
    <child
      link="left_leg_link_1" />
    <axis
      xyz="0 0 1" />
    <safety_controller
      k_velocity="0" />
  </joint>
  <joint
    name="joint_11"
    type="continuous">
    <origin
      xyz="0 -0.0417999999999986 0"
      rpy="0 0 0" />
    <parent
      link="right_leg_link_1" />
    <child
      link="right_leg_link_2" />
    <axis
      xyz="1 0 0" />
    <safety_controller
      k_velocity="0" />
  </joint>
  <joint
    name="joint_12"
    type="continuous">
    <origin
      xyz="0 -0.0418000000000006 0"
      rpy="3.14159265358979 0 -3.14159265358979" />
    <parent
      link="left_leg_link_1" />
    <child
      link="left_leg_link_2" />
    <axis
      xyz="1 0 0" />
    <safety_controller
      k_velocity="0" />
  </joint>
  <joint
    name="joint_13"
    type="continuous">
    <origin
      xyz="0 -0.0744000000000003 0.0145000000000005"
      rpy="0 0 3.14159265358979" />
    <parent
      link="right_leg_link_2" />
    <child
      link="right_leg_link_3" />
    <axis
      xyz="1 0 0" />
    <safety_controller
      k_velocity="0" />
  </joint>
  <joint
    name="joint_14"
    type="continuous">
    <origin
      xyz="0 -0.0744 -0.0145000000000106"
      rpy="0 0 3.14159265358979" />
    <parent
      link="left_leg_link_2" />
    <child
      link="left_leg_link_3" />
    <axis
      xyz="1 0 0" />
    <safety_controller
      k_velocity="0" />
  </joint>
  <joint
    name="joint_15"
    type="continuous">
    <origin
      xyz="0 0.0750000000000001 -0.0145"
      rpy="-1.5707963267949 0 3.14159265358979" />
    <parent
      link="right_leg_link_3" />
    <child
      link="right_leg_link_4" />
    <axis
      xyz="1 0 0" />
    <safety_controller
      k_velocity="0" />
  </joint>
  <joint
    name="joint_16"
    type="continuous">
    <origin
      xyz="0 0.075 0.0144999999999907"
      rpy="-1.5707963267949 0 -3.14159265358979" />
    <parent
      link="left_leg_link_3" />
    <child
      link="left_leg_link_4" />
    <axis
      xyz="1 0 0" />
    <safety_controller
      k_velocity="0" />
  </joint>
  <joint
    name="joint_17"
    type="continuous">
    <origin
      xyz="0.0138000000000001 0 -9.99999999998225E-05"
      rpy="1.5707963267949 0 1.5707963267949" />
    <parent
      link="right_leg_link_4" />
    <child
      link="right_leg_link_5" />
    <axis
      xyz="1 0 0" />
    <safety_controller
      k_velocity="0" />
  </joint>
  <joint
    name="joint_18"
    type="continuous">
    <origin
      xyz="0.0137999999999867 0 -9.9999999999989E-05"
      rpy="1.5707963267949 0 -1.5707963267949" />
    <parent
      link="left_leg_link_4" />
    <child
      link="left_leg_link_5" />
    <axis
      xyz="1 0 0" />
    <safety_controller
      k_velocity="0" />
  </joint>
  <joint
    name="joint_19"
    type="continuous">
    <origin
      xyz="0.00824999999999999 0 -0.05725"
      rpy="1.5707963267949 0 1.5707963267949" />
    <parent
      link="base_link" />
    <child
      link="torso_Link" />
    <axis
      xyz="0 1 0" />
    <safety_controller
      k_velocity="0" />
  </joint>
  <joint
    name="joint_20"
    type="continuous">
    <origin
      xyz="0.00825000000000002 0 0.0220498969223593"
      rpy="3.14159265358979 3.14159265358979 1.5708" />
    <parent
      link="base_link" />
    <child
      link="head_link" />
    <axis
      xyz="0 0 1" />
    <safety_controller
      k_velocity="0" />
  </joint>
  <joint
    name="joint_21"
    type="continuous">
    <origin
      xyz="0 0 0.0537001030776406"
      rpy="0 -1.5707963267949 0" />
    <parent
      link="head_link" />
    <child
      link="camera" />
    <axis
      xyz="0 0 1" />
    <safety_controller
      k_velocity="0" />
  </joint>

  <!-- ///////////////////////////////////////////////////////////////////////////////////////////////////////////////////// -->
  <!-- Transmissions for ROS Control -->

  <transmission name="tran1">
    <type>transmission_interface/SimpleTransmission</type>
    <joint name="joint_1">
      <hardwareInterface>hardware_interface/PositionJointInterface</hardwareInterface>
    </joint>
    <actuator name="motor1">
      <hardwareInterface>hardware_interface/PositionJointInterface</hardwareInterface>
      <mechanicalReduction>1</mechanicalReduction>
    </actuator>
  </transmission>
  
  <transmission name="tran2">
    <type>transmission_interface/SimpleTransmission</type>
    <joint name="joint_2">
      <hardwareInterface>hardware_interface/PositionJointInterface</hardwareInterface>
    </joint>
    <actuator name="motor2">
      <hardwareInterface>hardware_interface/PositionJointInterface</hardwareInterface>
      <mechanicalReduction>1</mechanicalReduction>
    </actuator>
  </transmission>

  <transmission name="tran3">
    <type>transmission_interface/SimpleTransmission</type>
    <joint name="joint_3">
      <hardwareInterface>hardware_interface/PositionJointInterface</hardwareInterface>
    </joint>
    <actuator name="motor3">
      <hardwareInterface>hardware_interface/PositionJointInterface</hardwareInterface>
      <mechanicalReduction>1</mechanicalReduction>
    </actuator>
  </transmission>

  <transmission name="tran4">
    <type>transmission_interface/SimpleTransmission</type>
    <joint name="joint_4">
      <hardwareInterface>hardware_interface/PositionJointInterface</hardwareInterface>
    </joint>
    <actuator name="motor4">
      <hardwareInterface>hardware_interface/PositionJointInterface</hardwareInterface>
      <mechanicalReduction>1</mechanicalReduction>
    </actuator>
  </transmission>

  <transmission name="tran5">
    <type>transmission_interface/SimpleTransmission</type>
    <joint name="joint_5">
      <hardwareInterface>hardware_interface/PositionJointInterface</hardwareInterface>
    </joint>
    <actuator name="motor5">
      <hardwareInterface>hardware_interface/PositionJointInterface</hardwareInterface>
      <mechanicalReduction>1</mechanicalReduction>
    </actuator>
  </transmission>

  <transmission name="tran6">
    <type>transmission_interface/SimpleTransmission</type>
    <joint name="joint_6">
      <hardwareInterface>hardware_interface/PositionJointInterface</hardwareInterface>
    </joint>
    <actuator name="motor6">
      <hardwareInterface>hardware_interface/PositionJointInterface</hardwareInterface>
      <mechanicalReduction>1</mechanicalReduction>
    </actuator>
  </transmission>

  <transmission name="tran7">
    <type>transmission_interface/SimpleTransmission</type>
    <joint name="joint_7">
      <hardwareInterface>hardware_interface/PositionJointInterface</hardwareInterface>
    </joint>
    <actuator name="motor7">
      <hardwareInterface>hardware_interface/PositionJointInterface</hardwareInterface>
      <mechanicalReduction>1</mechanicalReduction>
    </actuator>
  </transmission>

  <transmission name="tran8">
    <type>transmission_interface/SimpleTransmission</type>
    <joint name="joint_8">
      <hardwareInterface>hardware_interface/PositionJointInterface</hardwareInterface>
    </joint>
    <actuator name="motor8">
      <hardwareInterface>hardware_interface/PositionJointInterface</hardwareInterface>
      <mechanicalReduction>1</mechanicalReduction>
    </actuator>
  </transmission>

  <transmission name="tran9">
    <type>transmission_interface/SimpleTransmission</type>
    <joint name="joint_9">
      <hardwareInterface>hardware_interface/PositionJointInterface</hardwareInterface>
    </joint>
    <actuator name="motor9">
      <hardwareInterface>hardware_interface/PositionJointInterface</hardwareInterface>
      <mechanicalReduction>1</mechanicalReduction>
    </actuator>
  </transmission>

  <transmission name="tran10">
    <type>transmission_interface/SimpleTransmission</type>
    <joint name="joint_10">
      <hardwareInterface>hardware_interface/PositionJointInterface</hardwareInterface>
    </joint>
    <actuator name="motor10">
      <hardwareInterface>hardware_interface/PositionJointInterface</hardwareInterface>
      <mechanicalReduction>1</mechanicalReduction>
    </actuator>
  </transmission>

  <transmission name="tran11">
    <type>transmission_interface/SimpleTransmission</type>
    <joint name="joint_11">
      <hardwareInterface>hardware_interface/PositionJointInterface</hardwareInterface>
    </joint>
    <actuator name="motor11">
      <hardwareInterface>hardware_interface/PositionJointInterface</hardwareInterface>
      <mechanicalReduction>1</mechanicalReduction>
    </actuator>
  </transmission>

  <transmission name="tran12">
    <type>transmission_interface/SimpleTransmission</type>
    <joint name="joint_12">
      <hardwareInterface>hardware_interface/PositionJointInterface</hardwareInterface>
    </joint>
    <actuator name="motor12">
      <hardwareInterface>hardware_interface/PositionJointInterface</hardwareInterface>
      <mechanicalReduction>1</mechanicalReduction>
    </actuator>
  </transmission>

  <transmission name="tran13">
    <type>transmission_interface/SimpleTransmission</type>
    <joint name="joint_13">
      <hardwareInterface>hardware_interface/PositionJointInterface</hardwareInterface>
    </joint>
    <actuator name="motor13">
      <hardwareInterface>hardware_interface/PositionJointInterface</hardwareInterface>
      <mechanicalReduction>1</mechanicalReduction>
    </actuator>
  </transmission>

  <transmission name="tran14">
    <type>transmission_interface/SimpleTransmission</type>
    <joint name="joint_14">
      <hardwareInterface>hardware_interface/PositionJointInterface</hardwareInterface>
    </joint>
    <actuator name="motor14">
      <hardwareInterface>hardware_interface/PositionJointInterface</hardwareInterface>
      <mechanicalReduction>1</mechanicalReduction>
    </actuator>
  </transmission>

  <transmission name="tran15">
    <type>transmission_interface/SimpleTransmission</type>
    <joint name="joint_15">
      <hardwareInterface>hardware_interface/PositionJointInterface</hardwareInterface>
    </joint>
    <actuator name="motor15">
      <hardwareInterface>hardware_interface/PositionJointInterface</hardwareInterface>
      <mechanicalReduction>1</mechanicalReduction>
    </actuator>
  </transmission>

  <transmission name="tran16">
    <type>transmission_interface/SimpleTransmission</type>
    <joint name="joint_16">
      <hardwareInterface>hardware_interface/PositionJointInterface</hardwareInterface>
    </joint>
    <actuator name="motor16">
      <hardwareInterface>hardware_interface/PositionJointInterface</hardwareInterface>
      <mechanicalReduction>1</mechanicalReduction>
    </actuator>
  </transmission>

  <transmission name="tran17">
    <type>transmission_interface/SimpleTransmission</type>
    <joint name="joint_17">
      <hardwareInterface>hardware_interface/PositionJointInterface</hardwareInterface>
    </joint>
    <actuator name="motor17">
      <hardwareInterface>hardware_interface/PositionJointInterface</hardwareInterface>
      <mechanicalReduction>1</mechanicalReduction>
    </actuator>
  </transmission>

  <transmission name="tran18">
    <type>transmission_interface/SimpleTransmission</type>
    <joint name="joint_18">
      <hardwareInterface>hardware_interface/PositionJointInterface</hardwareInterface>
    </joint>
    <actuator name="motor18">
      <hardwareInterface>hardware_interface/PositionJointInterface</hardwareInterface>
      <mechanicalReduction>1</mechanicalReduction>
    </actuator>
  </transmission>

  
  <transmission name="tran19">
    <type>transmission_interface/SimpleTransmission</type>
    <joint name="joint_19">
      <hardwareInterface>hardware_interface/PositionJointInterface</hardwareInterface>
    </joint>
    <actuator name="motor1">
      <hardwareInterface>hardware_interface/PositionJointInterface</hardwareInterface>
      <mechanicalReduction>1</mechanicalReduction>
    </actuator>
  </transmission>

  <transmission name="tran20">
    <type>transmission_interface/SimpleTransmission</type>
    <joint name="joint_20">
      <hardwareInterface>hardware_interface/PositionJointInterface</hardwareInterface>
    </joint>
    <actuator name="motor20">
      <hardwareInterface>hardware_interface/PositionJointInterface</hardwareInterface>
      <mechanicalReduction>1</mechanicalReduction>
    </actuator>
  </transmission>
  
  <transmission name="tran21">
    <type>transmission_interface/SimpleTransmission</type>
    <joint name="joint_21">
      <hardwareInterface>hardware_interface/PositionJointInterface</hardwareInterface>
    </joint>
    <actuator name="motor21">
      <hardwareInterface>hardware_interface/PositionJointInterface</hardwareInterface>
      <mechanicalReduction>1</mechanicalReduction>
    </actuator>
  </transmission>  

  <!-- ros_control plugin -->
<gazebo>
  <plugin name="gazebo_ros_control" filename="libgazebo_ros_control.so">
    <robotNamespace>/bioloidgp_social_robot</robotNamespace>
  </plugin>
</gazebo>

<gazebo reference="right_leg_link_5">
    <mu1>0.9</mu1>
    <mu2>0.9</mu2>
    <!-- <material>Gazebo/Black</material> -->
</gazebo>
<gazebo reference="left_leg_link_5">
    <mu1>0.9</mu1>
    <mu2>0.9</mu2>
    <!-- <material>Gazebo/Black</material> -->
</gazebo>

  <!-- <link


  <link
    name="torso_Link">
    <inertial>
      <origin
        xyz="2.63162406857406E-08 -0.0210909555658785 -0.00131922984856177"
        rpy="0 0 0" />
      <mass
        value="0.0150306588580906" />
      <inertia
        ixx="1" ixy="0"  ixz="0"
               iyy="1" iyz="0"
               izz="1" />
    </inertial>
    <visual>
      <origin
        xyz="0 0 0"
        rpy="0 0 0" />
      <geometry>
        <mesh
          filename="package://bioloidgp_social_robot/meshes/torso_Link.STL" />
      </geometry>
      <material
        name="">
        <color
          rgba="0.792156862745098 0.819607843137255 0.933333333333333 1" />
      </material>
    </visual>
    <collision>
      <origin
        xyz="0 0 0"
        rpy="0 0 0" />
      <geometry>
        <mesh
          filename="package://bioloidgp_social_robot/meshes/torso_Link.STL" />
      </geometry>
    </collision>
  </link>
  
  <link
    name="right_leg_link_1">
    <inertial>
      <origin
        xyz="-0.0130433690693261 -0.00232565548787902 0.000953577437985076"
        rpy="0 0 0" />
      <mass
        value="0.0465444227419532" />
      <inertia
        ixx="1" ixy="0"  ixz="0"
               iyy="1" iyz="0"
               izz="1" />
    </inertial>
    <visual>
      <origin
        xyz="0 0 0"
        rpy="0 0 0" />
      <geometry>
        <mesh
          filename="package://bioloidgp_social_robot/meshes/right_leg_link_1.STL" />
      </geometry>
      <material
        name="">
        <color
          rgba="0.792156862745098 0.819607843137255 0.933333333333333 1" />
      </material>
    </visual>
    <collision>
      <origin
        xyz="0 0 0"
        rpy="0 0 0" />
      <geometry>
        <mesh
          filename="package://bioloidgp_social_robot/meshes/right_leg_link_1.STL" />
      </geometry>
    </collision>
  </link>
  <joint
    name="joint_9"
    type="continuous">
    <origin
      xyz="-0.016 -0.0535000000000006 0"
      rpy="0 0 0" />
    <parent
      link="torso_Link" />
    <child
      link="right_leg_link_1" />
    <axis
      xyz="0 0 1" />
    <safety_controller
      k_velocity="0" />
  </joint>
  <link
    name="right_leg_link_2">
    <inertial>
      <origin
        xyz="-0.0129843075496472 -0.0436689123978274 -0.000466568121459968"
        rpy="0 0 0" />
      <mass
        value="0.087395965925078" />
      <inertia
        ixx="1" ixy="0"  ixz="0"
               iyy="1" iyz="0"
               izz="1" />
    </inertial>
    <visual>
      <origin
        xyz="0 0 0"
        rpy="0 0 0" />
      <geometry>
        <mesh
          filename="package://bioloidgp_social_robot/meshes/right_leg_link_2.STL" />
      </geometry>
      <material
        name="">
        <color
          rgba="0.792156862745098 0.819607843137255 0.933333333333333 1" />
      </material>
    </visual>
    <collision>
      <origin
        xyz="0 0 0"
        rpy="0 0 0" />
      <geometry>
        <mesh
          filename="package://bioloidgp_social_robot/meshes/right_leg_link_2.STL" />
      </geometry>
    </collision>
  </link>
  <joint
    name="joint_11"
    type="continuous">
    <origin
      xyz="0 -0.0417999999999987 0"
      rpy="0 0 0" />
    <parent
      link="right_leg_link_1" />
    <child
      link="right_leg_link_2" />
    <axis
      xyz="1 0 0" />
    <safety_controller
      k_velocity="0" />
  </joint>
  <link
    name="right_leg_link_3">
    <inertial>
      <origin
        xyz="0.0139999999999993 0.0335563832066387 0.0151934897642466"
        rpy="0 0 0" />
      <mass
        value="0.00701486534628872" />
      <inertia
        ixx="1" ixy="0"  ixz="0"
               iyy="1" iyz="0"
               izz="1" />
    </inertial>
    <visual>
      <origin
        xyz="0 0 0"
        rpy="0 0 0" />
      <geometry>
        <mesh
          filename="package://bioloidgp_social_robot/meshes/right_leg_link_3.STL" />
      </geometry>
      <material
        name="">
        <color
          rgba="0.792156862745098 0.819607843137255 0.933333333333333 1" />
      </material>
    </visual>
    <collision>
      <origin
        xyz="0 0 0"
        rpy="0 0 0" />
      <geometry>
        <mesh
          filename="package://bioloidgp_social_robot/meshes/right_leg_link_3.STL" />
      </geometry>
    </collision>
  </link>
  <joint
    name="joint_13"
    type="continuous">
    <origin
      xyz="0 -0.0744000000000003 -0.0144999999999987"
      rpy="0 0 3.14159265358979" />
    <parent
      link="right_leg_link_2" />
    <child
      link="right_leg_link_3" />
    <axis
      xyz="1 0 0" />
    <safety_controller
      k_velocity="0" />
  </joint>
  <link
    name="right_leg_link_4">
    <inertial>
      <origin
        xyz="-0.0133679925661171 0.0211280641759689 0.0130554015027964"
        rpy="0 0 0" />
      <mass
        value="0.0856772163480855" />
      <inertia
        ixx="1" ixy="0"  ixz="0"
               iyy="1" iyz="0"
               izz="1" />
    </inertial>
    <visual>
      <origin
        xyz="0 0 0"
        rpy="0 0 0" />
      <geometry>
        <mesh
          filename="package://bioloidgp_social_robot/meshes/right_leg_link_4.STL" />
      </geometry>
      <material
        name="">
        <color
          rgba="0.792156862745098 0.819607843137255 0.933333333333333 1" />
      </material>
    </visual>
    <collision>
      <origin
        xyz="0 0 0"
        rpy="0 0 0" />
      <geometry>
        <mesh
          filename="package://bioloidgp_social_robot/meshes/right_leg_link_4.STL" />
      </geometry>
    </collision>
  </link>
  <joint
    name="joint_15"
    type="continuous">
    <origin
      xyz="0 0.0749999999999997 0.0145000000000011"
      rpy="-1.57079632679491 0 -3.14159265358979" />
    <parent
      link="right_leg_link_3" />
    <child
      link="right_leg_link_4" />
    <axis
      xyz="1 0 0" />
    <safety_controller
      k_velocity="0" />
  </joint>
  <link
    name="right_leg_link_5">
    <inertial>
      <origin
        xyz="0.000199999992454472 -0.0271016298640756 0.00578156165290392"
        rpy="0 0 0" />
      <mass
        value="0.0145032303847989" />
      <inertia
        ixx="1" ixy="0"  ixz="0"
               iyy="1" iyz="0"
               izz="1" />
    </inertial>
    <visual>
      <origin
        xyz="0 0 0"
        rpy="0 0 0" />
      <geometry>
        <mesh
          filename="package://bioloidgp_social_robot/meshes/right_leg_link_5.STL" />
      </geometry>
      <material
        name="">
        <color
          rgba="0.792156862745098 0.819607843137255 0.933333333333333 1" />
      </material>
    </visual>
    <collision>
      <origin
        xyz="0 0 0"
        rpy="0 0 0" />
      <geometry>
        <mesh
          filename="package://bioloidgp_social_robot/meshes/right_leg_link_5.STL" />
      </geometry>
    </collision>
  </link>
  <joint
    name="joint_17"
    type="continuous">
    <origin
      xyz="-0.0138000000000002 0 -9.99999999997114E-05"
      rpy="1.5707963267949 0 -1.5707963267949" />
    <parent
      link="right_leg_link_4" />
    <child
      link="right_leg_link_5" />
    <axis
      xyz="1 0 0" />
    <safety_controller
      k_velocity="0" />
  </joint>
  <link
    name="left_leg_link_1">
    <inertial>
      <origin
        xyz="-0.013043369069326 -0.00238489227282188 -0.000953577437985104"
        rpy="0 0 0" />
      <mass
        value="0.0465444227419533" />
      <inertia
        ixx="1" ixy="0"  ixz="0"
               iyy="1" iyz="0"
               izz="1" />
    </inertial>
    <visual>
      <origin
        xyz="0 0 0"
        rpy="0 0 0" />
      <geometry>
        <mesh
          filename="package://bioloidgp_social_robot/meshes/left_leg_link_1.STL" />
      </geometry>
      <material
        name="">
        <color
          rgba="0.792156862745098 0.819607843137255 0.933333333333333 1" />
      </material>
    </visual>
    <collision>
      <origin
        xyz="0 0 0"
        rpy="0 0 0" />
      <geometry>
        <mesh
          filename="package://bioloidgp_social_robot/meshes/left_leg_link_1.STL" />
      </geometry>
    </collision>
  </link>
  <joint
    name="joint_10"
    type="continuous">
    <origin
      xyz="0.016 -0.0535000000000006 0"
      rpy="3.14159265358979 0 -3.14159265358979" />
    <parent
      link="torso_Link" />
    <child
      link="left_leg_link_1" />
    <axis
      xyz="0 0 1" />
    <safety_controller
      k_velocity="0" />
  </joint>
  <link
    name="left_leg_link_2">
    <inertial>
      <origin
        xyz="0.0129843075495947 -0.0437004601006425 -0.000498115824281373"
        rpy="0 0 0" />
      <mass
        value="0.087395965925078" />
      <inertia
        ixx="1" ixy="0"  ixz="0"
               iyy="1" iyz="0"
               izz="1" />
    </inertial>
    <visual>
      <origin
        xyz="0 0 0"
        rpy="0 0 0" />
      <geometry>
        <mesh
          filename="package://bioloidgp_social_robot/meshes/left_leg_link_2.STL" />
      </geometry>
      <material
        name="">
        <color
          rgba="0.792156862745098 0.819607843137255 0.933333333333333 1" />
      </material>
    </visual>
    <collision>
      <origin
        xyz="0 0 0"
        rpy="0 0 0" />
      <geometry>
        <mesh
          filename="package://bioloidgp_social_robot/meshes/left_leg_link_2.STL" />
      </geometry>
    </collision>
  </link>
  <joint
    name="joint_12"
    type="continuous">
    <origin
      xyz="0 -0.0418000000000007 0"
      rpy="3.14159265358979 0 -3.14159265358979" />
    <parent
      link="left_leg_link_1" />
    <child
      link="left_leg_link_2" />
    <axis
      xyz="1 0 0" />
    <safety_controller
      k_velocity="0" />
  </joint>
  <link
    name="left_leg_link_3">
    <inertial>
      <origin
        xyz="-0.0140000000000141 0.033556383206642 0.0151934897642171"
        rpy="0 0 0" />
      <mass
        value="0.00701486534628874" />
      <inertia
       ixx="1" ixy="0"  ixz="0"
               iyy="1" iyz="0"
               izz="1" />
    </inertial>
    <visual>
      <origin
        xyz="0 0 0"
        rpy="0 0 0" />
      <geometry>
        <mesh
          filename="package://bioloidgp_social_robot/meshes/left_leg_link_3.STL" />
      </geometry>
      <material
        name="">
        <color
          rgba="0.792156862745098 0.819607843137255 0.933333333333333 1" />
      </material>
    </visual>
    <collision>
      <origin
        xyz="0 0 0"
        rpy="0 0 0" />
      <geometry>
        <mesh
          filename="package://bioloidgp_social_robot/meshes/left_leg_link_3.STL" />
      </geometry>
    </collision>
  </link>
  <joint
    name="joint_14"
    type="continuous">
    <origin
      xyz="0 -0.0744 -0.0145000000000106"
      rpy="0 0 -3.14159265358979" />
    <parent
      link="left_leg_link_2" />
    <child
      link="left_leg_link_3" />
    <axis
      xyz="1 0 0" />
    <safety_controller
      k_velocity="0" />
  </joint>
  <link
    name="left_leg_link_4">
    <inertial>
      <origin
        xyz="0.0134001731396108 0.0210958836024549 0.0130554015027963"
        rpy="0 0 0" />
      <mass
        value="0.0856772163480855" />
      <inertia
        ixx="1" ixy="0"  ixz="0"
               iyy="1" iyz="0"
               izz="1" />
    </inertial>
    <visual>
      <origin
        xyz="0 0 0"
        rpy="0 0 0" />
      <geometry>
        <mesh
          filename="package://bioloidgp_social_robot/meshes/left_leg_link_4.STL" />
      </geometry>
      <material
        name="">
        <color
          rgba="0.792156862745098 0.819607843137255 0.933333333333333 1" />
      </material>
    </visual>
    <collision>
      <origin
        xyz="0 0 0"
        rpy="0 0 0" />
      <geometry>
        <mesh
          filename="package://bioloidgp_social_robot/meshes/left_leg_link_4.STL" />
      </geometry>
    </collision>
  </link>
  <joint
    name="joint_16"
    type="continuous">
    <origin
      xyz="0 0.0750000000000028 0.0144999999999764"
      rpy="-1.57079632679471 0 3.14159265358979" />
    <parent
      link="left_leg_link_3" />
    <child
      link="left_leg_link_4" />
    <axis
      xyz="1 0 0" />
    <safety_controller
      k_velocity="0" />
  </joint>
  <link
    name="left_leg_link_5">
    <inertial>
      <origin
        xyz="-0.000199999992515382 0.0271016298640602 -0.00578156174804375"
        rpy="0 0 0" />
      <mass
        value="0.0145032303847992" />
      <inertia
        ixx="1" ixy="0"  ixz="0"
               iyy="1" iyz="0"
               izz="1" />
    </inertial>
    <visual>
      <origin
        xyz="0 0 0"
        rpy="0 0 0" />
      <geometry>
        <mesh
          filename="package://bioloidgp_social_robot/meshes/left_leg_link_5.STL" />
      </geometry>
      <material
        name="">
        <color
          rgba="0.792156862745098 0.819607843137255 0.933333333333333 1" />
      </material>
    </visual>
    <collision>
      <origin
        xyz="0 0 0"
        rpy="0 0 0" />
      <geometry>
        <mesh
          filename="package://bioloidgp_social_robot/meshes/left_leg_link_5.STL" />
      </geometry>
    </collision>
  </link>
  <joint
    name="joint_18"
    type="continuous">
    <origin
      xyz="0.0137999999999866 0 -0.000100000000000044"
      rpy="-1.5707963267949 0 1.5707963267949" />
    <parent
      link="left_leg_link_4" />
    <child
      link="left_leg_link_5" />
    <axis
      xyz="1 0 0" />
    <safety_controller
      k_velocity="0" />
  </joint>
  <link
    name="head_link">
    <inertial>
      <origin
        xyz="1.91945763635022E-07 0.000589833409522802 -0.0219995925672971"
        rpy="0 0 0" />
      <mass
        value="0.0131552828145098" />
      <inertia
        ixx="1" ixy="0"  ixz="0"
               iyy="1" iyz="0"
               izz="1" />
    </inertial>
    <visual>
      <origin
        xyz="0 0 0"
        rpy="0 0 0" />
      <geometry>
        <mesh
          filename="package://bioloidgp_social_robot/meshes/head_link.STL" />
      </geometry>
      <material
        name="">
        <color
          rgba="0.792156862745098 0.819607843137255 0.933333333333333 1" />
      </material>
    </visual>
    <collision>
      <origin
        xyz="0 0 0"
        rpy="0 0 0" />
      <geometry>
        <mesh
          filename="package://bioloidgp_social_robot/meshes/head_link.STL" />
      </geometry>
    </collision>
  </link>
  <joint
    name="joint_20"
    type="continuous">
    <origin
      xyz="0.00825000000000002 0 0.0220498969223593"
      rpy="3.14159265358979 0 -1.60287187004926" />
    <parent
      link="base_link" />
    <child
      link="head_link" />
    <axis
      xyz="0 0 1" />
    <safety_controller
      k_velocity="0" />
  </joint>
  <link
    name="camera">
    <inertial>
      <origin
        xyz="-4.35545016548716E-05 -0.0368908103420887 0.000350647380343936"
        rpy="0 0 0" />
      <mass
        value="0.0951615958891303" />
      <inertia
        ixx="1" ixy="0"  ixz="0"
               iyy="1" iyz="0"
               izz="1" />
    </inertial>
    <visual>
      <origin
        xyz="0 0 0"
        rpy="0 0 0" />
      <geometry>
        <mesh
          filename="package://bioloidgp_social_robot/meshes/camera.STL" />
      </geometry>
      <material
        name="">
        <color
          rgba="0.792156862745098 0.819607843137255 0.933333333333333 1" />
      </material>
    </visual>
    <collision>
      <origin
        xyz="0 0 0"
        rpy="0 0 0" />
      <geometry>
        <mesh
          filename="package://bioloidgp_social_robot/meshes/camera.STL" />
      </geometry>
    </collision>
  </link>
  <joint
    name="joint_21"
    type="continuous">
    <origin
      xyz="0 0 -0.0537001030776406"
      rpy="0 1.5707963267949 0" />
    <parent
      link="head_link" />
    <child
      link="camera" />
    <axis
      xyz="0 0 1" />
    <safety_controller
      k_velocity="0" />
  </joint> -->
</robot>