<?xml version="1.0" encoding="utf-8"?>
<!-- This URDF was automatically created by SolidWorks to URDF Exporter! Originally created by Stephen Brawner (brawner@gmail.com) 
     Commit Version: 1.5.1-0-g916b5db  Build Version: 1.5.7152.31018
     For more information, please see http://wiki.ros.org/sw_urdf_exporter -->
<robot
  name="bioloid_gp1">
  <link
    name="base_link">
    <inertial>
      <origin
        xyz="-0.00355910116893569 -8.90355110819141E-10 0.00276509793203532"
        rpy="0 0 0" />
      <mass
        value="0.112944371237152" />
      <inertia
        ixx="5.09410057554706E-05"
        ixy="-2.31619284739531E-13"
        ixz="-2.01663682950217E-07"
        iyy="3.58755324524443E-05"
        iyz="2.93496587138638E-09"
        izz="6.19533298942277E-05" />
    </inertial>
    <visual>
      <origin
        xyz="0 0 0"
        rpy="0 0 0" />
      <geometry>
        <mesh
          filename="package://bioloid_gp1/meshes/base_link.STL" />
      </geometry>
      <material
        name="">
        <color
          rgba="0.792156862745098 0.819607843137255 0.933333333333333 1" />
      </material>
    </visual>
    <collision>
      <origin
        xyz="0 0 0"
        rpy="0 0 0" />
      <geometry>
        <mesh
          filename="package://bioloid_gp1/meshes/base_link.STL" />
      </geometry>
    </collision>
  </link>
  <link
    name="right_arm_link_1">
    <inertial>
      <origin
        xyz="-6.07043906253324E-08 -0.0092320672392501 0.00517864249850522"
        rpy="0 0 0" />
      <mass
        value="0.00402029367652139" />
      <inertia
        ixx="8.53462226825597E-07"
        ixy="1.70481192762851E-12"
        ixz="-1.05162131712832E-12"
        iyy="1.77130321667596E-06"
        iyz="2.51193243950453E-07"
        izz="1.69099459342747E-06" />
    </inertial>
    <visual>
      <origin
        xyz="0 0 0"
        rpy="0 0 0" />
      <geometry>
        <mesh
          filename="package://bioloid_gp1/meshes/right_arm_link_1.STL" />
      </geometry>
      <material
        name="">
        <color
          rgba="0.792156862745098 0.819607843137255 0.933333333333333 1" />
      </material>
    </visual>
    <collision>
      <origin
        xyz="0 0 0"
        rpy="0 0 0" />
      <geometry>
        <mesh
          filename="package://bioloid_gp1/meshes/right_arm_link_1.STL" />
      </geometry>
    </collision>
  </link>
  <joint
    name="joint_1"
    type="continuous">
    <origin
      xyz="0.00875 -0.05649 0.00275"
      rpy="3.1416 0 3.1416" />
    <parent
      link="base_link" />
    <child
      link="right_arm_link_1" />
    <axis
      xyz="0 1 0" />
    <safety_controller
      k_velocity="0" />
  </joint>
  <link
    name="right_arm_link_2">
    <inertial>
      <origin
        xyz="-0.000528170386428509 -0.0352518252774793 0.00311828556966412"
        rpy="0 0 0" />
      <mass
        value="0.0866430294972451" />
      <inertia
        ixx="2.18652500161555E-05"
        ixy="-8.94831167760344E-09"
        ixz="-1.89458955070907E-07"
        iyy="1.84666066901423E-05"
        iyz="2.01342587194598E-07"
        izz="1.66635512730656E-05" />
    </inertial>
    <visual>
      <origin
        xyz="0 0 0"
        rpy="0 0 0" />
      <geometry>
        <mesh
          filename="package://bioloid_gp1/meshes/right_arm_link_2.STL" />
      </geometry>
      <material
        name="">
        <color
          rgba="0.792156862745098 0.819607843137255 0.933333333333333 1" />
      </material>
    </visual>
    <collision>
      <origin
        xyz="0 0 0"
        rpy="0 0 0" />
      <geometry>
        <mesh
          filename="package://bioloid_gp1/meshes/right_arm_link_2.STL" />
      </geometry>
    </collision>
  </link>
  <joint
    name="joint_3"
    type="continuous">
    <origin
      xyz="0 -0.02301 0.018"
      rpy="-1.5708 0 1.5708" />
    <parent
      link="right_arm_link_1" />
    <child
      link="right_arm_link_2" />
    <axis
      xyz="0 0 1" />
    <safety_controller
      k_velocity="0" />
  </joint>
  <link
    name="right_arm_link_3">
    <inertial>
      <origin
        xyz="0.00415752095634414 0.0477168328995841 -0.01632646307713"
        rpy="0 0 0" />
      <mass
        value="0.0124405169193281" />
      <inertia
        ixx="1.01511820933173E-05"
        ixy="-7.57219531539473E-09"
        ixz="-1.05248182395921E-12"
        iyy="3.65282468945607E-06"
        iyz="2.51193224626463E-07"
        izz="9.92898397139804E-06" />
    </inertial>
    <visual>
      <origin
        xyz="0 0 0"
        rpy="0 0 0" />
      <geometry>
        <mesh
          filename="package://bioloid_gp1/meshes/right_arm_link_3.STL" />
      </geometry>
      <material
        name="">
        <color
          rgba="0.792156862745098 0.819607843137255 0.933333333333333 1" />
      </material>
    </visual>
    <collision>
      <origin
        xyz="0 0 0"
        rpy="0 0 0" />
      <geometry>
        <mesh
          filename="package://bioloid_gp1/meshes/right_arm_link_3.STL" />
      </geometry>
    </collision>
  </link>
  <joint
    name="joint_5"
    type="continuous">
    <origin
      xyz="0 -0.0574 0.0182"
      rpy="1.5708 0 3.1416" />
    <parent
      link="right_arm_link_2" />
    <child
      link="right_arm_link_3" />
    <axis
      xyz="1 0 0" />
    <safety_controller
      k_velocity="0" />
  </joint>
  <link
    name="left_arm_link_1">
    <inertial>
      <origin
        xyz="-6.07043890848979E-08 -0.00923206723925154 0.00517864249850555"
        rpy="0 0 0" />
      <mass
        value="0.00402029367652146" />
      <inertia
        ixx="8.53462226825606E-07"
        ixy="1.70481192659365E-12"
        ixz="-1.05162131482222E-12"
        iyy="1.77130321667598E-06"
        iyz="2.51193243950454E-07"
        izz="1.69099459342749E-06" />
    </inertial>
    <visual>
      <origin
        xyz="0 0 0"
        rpy="0 0 0" />
      <geometry>
        <mesh
          filename="package://bioloid_gp1/meshes/left_arm_link_1.STL" />
      </geometry>
      <material
        name="">
        <color
          rgba="0.792156862745098 0.819607843137255 0.933333333333333 1" />
      </material>
    </visual>
    <collision>
      <origin
        xyz="0 0 0"
        rpy="0 0 0" />
      <geometry>
        <mesh
          filename="package://bioloid_gp1/meshes/left_arm_link_1.STL" />
      </geometry>
    </collision>
  </link>
  <joint
    name="joint_2"
    type="continuous">
    <origin
      xyz="0.00875 0.05649 0.00275"
      rpy="3.1416 0 0" />
    <parent
      link="base_link" />
    <child
      link="left_arm_link_1" />
    <axis
      xyz="0 1 0" />
    <safety_controller
      k_velocity="0" />
  </joint>
  <link
    name="left_arm_link_2">
    <inertial>
      <origin
        xyz="0.000496348530981308 -0.0352836471329275 0.00311828556966444"
        rpy="0 0 0" />
      <mass
        value="0.0866430294972451" />
      <inertia
        ixx="2.18652500161555E-05"
        ixy="-8.94831167760773E-09"
        ixz="1.92394275517002E-07"
        iyy="1.84666066901423E-05"
        iyz="1.80510643393311E-07"
        izz="1.66635512730656E-05" />
    </inertial>
    <visual>
      <origin
        xyz="0 0 0"
        rpy="0 0 0" />
      <geometry>
        <mesh
          filename="package://bioloid_gp1/meshes/left_arm_link_2.STL" />
      </geometry>
      <material
        name="">
        <color
          rgba="0.792156862745098 0.819607843137255 0.933333333333333 1" />
      </material>
    </visual>
    <collision>
      <origin
        xyz="0 0 0"
        rpy="0 0 0" />
      <geometry>
        <mesh
          filename="package://bioloid_gp1/meshes/left_arm_link_2.STL" />
      </geometry>
    </collision>
  </link>
  <joint
    name="joint_4"
    type="continuous">
    <origin
      xyz="0 -0.0230095805758358 0.0179999999999895"
      rpy="-1.5707963267949 0 -1.5707963267949" />
    <parent
      link="left_arm_link_1" />
    <child
      link="left_arm_link_2" />
    <axis
      xyz="0 0 1" />
    <safety_controller
      k_velocity="0" />
  </joint>
  <link
    name="left_arm_link_3">
    <inertial>
      <origin
        xyz="-0.00415756019096616 0.0477168328995841 -0.0163264631919699"
        rpy="0 0 0" />
      <mass
        value="0.0124405169193281" />
      <inertia
        ixx="1.01511820933173E-05"
        ixy="7.57560493925653E-09"
        ixz="-1.05248182431746E-12"
        iyy="3.65282468945607E-06"
        iyz="2.51193263274454E-07"
        izz="9.92898397139806E-06" />
    </inertial>
    <visual>
      <origin
        xyz="0 0 0"
        rpy="0 0 0" />
      <geometry>
        <mesh
          filename="package://bioloid_gp1/meshes/left_arm_link_3.STL" />
      </geometry>
      <material
        name="">
        <color
          rgba="0.792156862745098 0.819607843137255 0.933333333333333 1" />
      </material>
    </visual>
    <collision>
      <origin
        xyz="0 0 0"
        rpy="0 0 0" />
      <geometry>
        <mesh
          filename="package://bioloid_gp1/meshes/left_arm_link_3.STL" />
      </geometry>
    </collision>
  </link>
  <joint
    name="joint_6"
    type="continuous">
    <origin
      xyz="0 -0.0573999999999997 0.0182000000000009"
      rpy="1.5707963267949 0 3.14159265358979" />
    <parent
      link="left_arm_link_2" />
    <child
      link="left_arm_link_3" />
    <axis
      xyz="1 0 0" />
    <safety_controller
      k_velocity="0" />
  </joint>
  <link
    name="torso_link">
    <inertial>
      <origin
        xyz="2.63162407828851E-08 0.032409044434122 -0.00131922984856171"
        rpy="0 0 0" />
      <mass
        value="0.0150306588580906" />
      <inertia
        ixx="1.22995746902599E-05"
        ixy="-5.36004120419293E-12"
        ixz="4.57561584526798E-15"
        iyy="1.26743899445148E-05"
        iyz="-4.84169136516327E-07"
        izz="1.42781332295549E-05" />
    </inertial>
    <visual>
      <origin
        xyz="0 0 0"
        rpy="0 0 0" />
      <geometry>
        <mesh
          filename="package://bioloid_gp1/meshes/torso_link.STL" />
      </geometry>
      <material
        name="">
        <color
          rgba="0.792156862745098 0.819607843137255 0.933333333333333 1" />
      </material>
    </visual>
    <collision>
      <origin
        xyz="0 0 0"
        rpy="0 0 0" />
      <geometry>
        <mesh
          filename="package://bioloid_gp1/meshes/torso_link.STL" />
      </geometry>
    </collision>
  </link>
  <joint
    name="joint_19"
    type="fixed">
    <origin
      xyz="0.00825000000000042 0 -0.0737500000000006"
      rpy="1.5707963267949 0 1.5707963267949" />
    <parent
      link="base_link" />
    <child
      link="torso_link" />
    <axis
      xyz="0 0 0" />
    <safety_controller
      k_velocity="0" />
  </joint>
  <link
    name="right_leg_link_1">
    <inertial>
      <origin
        xyz="-0.0130433690693261 -0.00232565548787897 0.000953577437985437"
        rpy="0 0 0" />
      <mass
        value="0.0465444227419532" />
      <inertia
        ixx="7.24109241174826E-06"
        ixy="5.52407893798063E-08"
        ixz="1.90926615293954E-07"
        iyy="1.32071311548595E-05"
        iyz="-1.46766022304875E-09"
        izz="1.18450916288587E-05" />
    </inertial>
    <visual>
      <origin
        xyz="0 0 0"
        rpy="0 0 0" />
      <geometry>
        <mesh
          filename="package://bioloid_gp1/meshes/right_leg_link_1.STL" />
      </geometry>
      <material
        name="">
        <color
          rgba="0.792156862745098 0.819607843137255 0.933333333333333 1" />
      </material>
    </visual>
    <collision>
      <origin
        xyz="0 0 0"
        rpy="0 0 0" />
      <geometry>
        <mesh
          filename="package://bioloid_gp1/meshes/right_leg_link_1.STL" />
      </geometry>
    </collision>
  </link>
  <joint
    name="joint_9"
    type="continuous">
    <origin
      xyz="-0.0160000000000004 0 0"
      rpy="0 0 0" />
    <parent
      link="torso_link" />
    <child
      link="right_leg_link_1" />
    <axis
      xyz="0 0 1" />
    <safety_controller
      k_velocity="0" />
  </joint>
  <link
    name="right_leg_link_2">
    <inertial>
      <origin
        xyz="-0.0129843075496472 -0.0436689123978273 -0.000466568121460509"
        rpy="0 0 0" />
      <mass
        value="0.087395965925078" />
      <inertia
        ixx="2.07330711638692E-05"
        ixy="1.89458955070831E-07"
        ixz="-1.92394275516865E-07"
        iyy="1.89034952338267E-05"
        iyz="-7.78205227092172E-08"
        izz="1.89379045179429E-05" />
    </inertial>
    <visual>
      <origin
        xyz="0 0 0"
        rpy="0 0 0" />
      <geometry>
        <mesh
          filename="package://bioloid_gp1/meshes/right_leg_link_2.STL" />
      </geometry>
      <material
        name="">
        <color
          rgba="0.792156862745098 0.819607843137255 0.933333333333333 1" />
      </material>
    </visual>
    <collision>
      <origin
        xyz="0 0 0"
        rpy="0 0 0" />
      <geometry>
        <mesh
          filename="package://bioloid_gp1/meshes/right_leg_link_2.STL" />
      </geometry>
    </collision>
  </link>
  <joint
    name="joint_11"
    type="continuous">
    <origin
      xyz="0 -0.0417999999999986 0"
      rpy="0 0 0" />
    <parent
      link="right_leg_link_1" />
    <child
      link="right_leg_link_2" />
    <axis
      xyz="1 0 0" />
    <safety_controller
      k_velocity="0" />
  </joint>
  <link
    name="right_leg_link_3">
    <inertial>
      <origin
        xyz="0.0139999999999992 0.033556383206639 0.0151934897642462"
        rpy="0 0 0" />
      <mass
        value="0.00701486534628872" />
      <inertia
        ixx="5.15587753735926E-06"
        ixy="-8.62765575531373E-20"
        ixz="-3.58175997697015E-20"
        iyy="3.83307916350282E-06"
        iyz="-4.23987865116599E-07"
        izz="7.34905050588702E-06" />
    </inertial>
    <visual>
      <origin
        xyz="0 0 0"
        rpy="0 0 0" />
      <geometry>
        <mesh
          filename="package://bioloid_gp1/meshes/right_leg_link_3.STL" />
      </geometry>
      <material
        name="">
        <color
          rgba="0.792156862745098 0.819607843137255 0.933333333333333 1" />
      </material>
    </visual>
    <collision>
      <origin
        xyz="0 0 0"
        rpy="0 0 0" />
      <geometry>
        <mesh
          filename="package://bioloid_gp1/meshes/right_leg_link_3.STL" />
      </geometry>
    </collision>
  </link>
  <joint
    name="joint_13"
    type="continuous">
    <origin
      xyz="0 -0.0744000000000003 -0.0145000000000005"
      rpy="0 0 3.14159265358979" />
    <parent
      link="right_leg_link_2" />
    <child
      link="right_leg_link_3" />
    <axis
      xyz="1 0 0" />
    <safety_controller
      k_velocity="0" />
  </joint>
  <link
    name="right_leg_link_4">
    <inertial>
      <origin
        xyz="-0.013367992566117 0.021128064175969 0.0130554015027963"
        rpy="0 0 0" />
      <mass
        value="0.0856772163480855" />
      <inertia
        ixx="2.17028956622458E-05"
        ixy="7.45122817651758E-20"
        ixz="-2.01342587194575E-07"
        iyy="2.20441592245027E-05"
        iyz="1.82085534033286E-07"
        izz="1.30559757952079E-05" />
    </inertial>
    <visual>
      <origin
        xyz="0 0 0"
        rpy="0 0 0" />
      <geometry>
        <mesh
          filename="package://bioloid_gp1/meshes/right_leg_link_4.STL" />
      </geometry>
      <material
        name="">
        <color
          rgba="0.792156862745098 0.819607843137255 0.933333333333333 1" />
      </material>
    </visual>
    <collision>
      <origin
        xyz="0 0 0"
        rpy="0 0 0" />
      <geometry>
        <mesh
          filename="package://bioloid_gp1/meshes/right_leg_link_4.STL" />
      </geometry>
    </collision>
  </link>
  <joint
    name="joint_15"
    type="continuous">
    <origin
      xyz="0 0.075 0.0145000000000002"
      rpy="-1.5707963267949 0 3.14159265358979" />
    <parent
      link="right_leg_link_3" />
    <child
      link="right_leg_link_4" />
    <axis
      xyz="1 0 0" />
    <safety_controller
      k_velocity="0" />
  </joint>
  <link
    name="right_leg_link_5">
    <inertial>
      <origin
        xyz="0.000199999992457914 -0.0271016298640743 0.00578156165290527"
        rpy="0 0 0" />
      <mass
        value="0.0145032303847988" />
      <inertia
        ixx="5.46558889534122E-06"
        ixy="6.68157958106957E-17"
        ixz="6.34590720150547E-16"
        iyy="1.36797822725631E-05"
        iyz="6.23591718166461E-15"
        izz="9.53948774258591E-06" />
    </inertial>
    <visual>
      <origin
        xyz="0 0 0"
        rpy="0 0 0" />
      <geometry>
        <mesh
          filename="package://bioloid_gp1/meshes/right_leg_link_5.STL" />
      </geometry>
      <material
        name="">
        <color
          rgba="0.792156862745098 0.819607843137255 0.933333333333333 1" />
      </material>
    </visual>
    <collision>
      <origin
        xyz="0 0 0"
        rpy="0 0 0" />
      <geometry>
        <mesh
          filename="package://bioloid_gp1/meshes/right_leg_link_5.STL" />
      </geometry>
    </collision>
  </link>
  <joint
    name="joint_17"
    type="continuous">
    <origin
      xyz="-0.0138 0 -9.99999999997669E-05"
      rpy="1.5707963267949 0 -1.5707963267949" />
    <parent
      link="right_leg_link_4" />
    <child
      link="right_leg_link_5" />
    <axis
      xyz="1 0 0" />
    <safety_controller
      k_velocity="0" />
  </joint>
  <link
    name="left_leg_link_1">
    <inertial>
      <origin
        xyz="-0.013043369069326 -0.00238489227282189 -0.00095357743798509"
        rpy="0 0 0" />
      <mass
        value="0.0465444227419532" />
      <inertia
        ixx="7.24109241174826E-06"
        ixy="3.44088455785087E-08"
        ixz="-1.90926615293941E-07"
        iyy="1.32071311548595E-05"
        iyz="-1.46766022304846E-09"
        izz="1.18450916288587E-05" />
    </inertial>
    <visual>
      <origin
        xyz="0 0 0"
        rpy="0 0 0" />
      <geometry>
        <mesh
          filename="package://bioloid_gp1/meshes/left_leg_link_1.STL" />
      </geometry>
      <material
        name="">
        <color
          rgba="0.792156862745098 0.819607843137255 0.933333333333333 1" />
      </material>
    </visual>
    <collision>
      <origin
        xyz="0 0 0"
        rpy="0 0 0" />
      <geometry>
        <mesh
          filename="package://bioloid_gp1/meshes/left_leg_link_1.STL" />
      </geometry>
    </collision>
  </link>
  <joint
    name="joint_10"
    type="continuous">
    <origin
      xyz="0.016 0 0"
      rpy="3.14159265358979 0 -3.14159265358979" />
    <parent
      link="torso_link" />
    <child
      link="left_leg_link_1" />
    <axis
      xyz="0 0 1" />
    <safety_controller
      k_velocity="0" />
  </joint>
  <link
    name="left_leg_link_2">
    <inertial>
      <origin
        xyz="0.0129843075496483 -0.0437004601006382 -0.000498115824349318"
        rpy="0 0 0" />
      <mass
        value="0.087395965925078" />
      <inertia
        ixx="2.07330711638695E-05"
        ixy="-1.92394275517343E-07"
        ixz="1.89458955067263E-07"
        iyy="1.89034952338267E-05"
        iyz="-7.78205227092368E-08"
        izz="1.89379045179425E-05" />
    </inertial>
    <visual>
      <origin
        xyz="0 0 0"
        rpy="0 0 0" />
      <geometry>
        <mesh
          filename="package://bioloid_gp1/meshes/left_leg_link_2.STL" />
      </geometry>
      <material
        name="">
        <color
          rgba="0.792156862745098 0.819607843137255 0.933333333333333 1" />
      </material>
    </visual>
    <collision>
      <origin
        xyz="0 0 0"
        rpy="0 0 0" />
      <geometry>
        <mesh
          filename="package://bioloid_gp1/meshes/left_leg_link_2.STL" />
      </geometry>
    </collision>
  </link>
  <joint
    name="joint_12"
    type="continuous">
    <origin
      xyz="0 -0.0418000000000007 0"
      rpy="3.14159265358979 0 -3.14159265358979" />
    <parent
      link="left_leg_link_1" />
    <child
      link="left_leg_link_2" />
    <axis
      xyz="1 0 0" />
    <safety_controller
      k_velocity="0" />
  </joint>
  <link
    name="left_leg_link_3">
    <inertial>
      <origin
        xyz="-0.0140000000000281 0.0335563832066419 0.0151934897642271"
        rpy="0 0 0" />
      <mass
        value="0.00701486534628872" />
      <inertia
        ixx="5.1558775373593E-06"
        ixy="3.03138649127152E-19"
        ixz="-2.1118104131574E-18"
        iyy="3.83307916350283E-06"
        iyz="-4.23987865116592E-07"
        izz="7.34905050588706E-06" />
    </inertial>
    <visual>
      <origin
        xyz="0 0 0"
        rpy="0 0 0" />
      <geometry>
        <mesh
          filename="package://bioloid_gp1/meshes/left_leg_link_3.STL" />
      </geometry>
      <material
        name="">
        <color
          rgba="0.792156862745098 0.819607843137255 0.933333333333333 1" />
      </material>
    </visual>
    <collision>
      <origin
        xyz="0 0 0"
        rpy="0 0 0" />
      <geometry>
        <mesh
          filename="package://bioloid_gp1/meshes/left_leg_link_3.STL" />
      </geometry>
    </collision>
  </link>
  <joint
    name="joint_14"
    type="continuous">
    <origin
      xyz="0 -0.0743999999999758 -0.0145000000001237"
      rpy="0 0 -3.14159265358979" />
    <parent
      link="left_leg_link_2" />
    <child
      link="left_leg_link_3" />
    <axis
      xyz="1 0 0" />
    <safety_controller
      k_velocity="0" />
  </joint>
  <link
    name="left_leg_link_4">
    <inertial>
      <origin
        xyz="0.0134001731396249 0.0210958836024549 0.0130554015027963"
        rpy="0 0 0" />
      <mass
        value="0.0856772163480854" />
      <inertia
        ixx="2.17028956622458E-05"
        ixy="-2.49349063667142E-19"
        ixz="1.80510643393132E-07"
        iyy="2.20441592245027E-05"
        iyz="2.02917477834786E-07"
        izz="1.30559757952079E-05" />
    </inertial>
    <visual>
      <origin
        xyz="0 0 0"
        rpy="0 0 0" />
      <geometry>
        <mesh
          filename="package://bioloid_gp1/meshes/left_leg_link_4.STL" />
      </geometry>
      <material
        name="">
        <color
          rgba="0.792156862745098 0.819607843137255 0.933333333333333 1" />
      </material>
    </visual>
    <collision>
      <origin
        xyz="0 0 0"
        rpy="0 0 0" />
      <geometry>
        <mesh
          filename="package://bioloid_gp1/meshes/left_leg_link_4.STL" />
      </geometry>
    </collision>
  </link>
  <joint
    name="joint_16"
    type="continuous">
    <origin
      xyz="0 0.0750000000000029 0.0144999999999943"
      rpy="-1.5707963267949 0 3.14159265358979" />
    <parent
      link="left_leg_link_3" />
    <child
      link="left_leg_link_4" />
    <axis
      xyz="1 0 0" />
    <safety_controller
      k_velocity="0" />
  </joint>
  <link
    name="left_leg_link_5">
    <inertial>
      <origin
        xyz="-0.00019999999247404 0.027101629864075 -0.00578156174805482"
        rpy="0 0 0" />
      <mass
        value="0.0145032303847987" />
      <inertia
        ixx="5.46558889534117E-06"
        ixy="6.6836357239274E-17"
        ixz="-6.3553817952006E-16"
        iyy="1.36797822725629E-05"
        iyz="-6.23589339895925E-15"
        izz="9.53948774258582E-06" />
    </inertial>
    <visual>
      <origin
        xyz="0 0 0"
        rpy="0 0 0" />
      <geometry>
        <mesh
          filename="package://bioloid_gp1/meshes/left_leg_link_5.STL" />
      </geometry>
      <material
        name="">
        <color
          rgba="0.792156862745098 0.819607843137255 0.933333333333333 1" />
      </material>
    </visual>
    <collision>
      <origin
        xyz="0 0 0"
        rpy="0 0 0" />
      <geometry>
        <mesh
          filename="package://bioloid_gp1/meshes/left_leg_link_5.STL" />
      </geometry>
    </collision>
  </link>
  <joint
    name="joint_18"
    type="continuous">
    <origin
      xyz="0.0138000000000007 0 -9.9999999999989E-05"
      rpy="-1.5707963267949 0 1.5707963267949" />
    <parent
      link="left_leg_link_4" />
    <child
      link="left_leg_link_5" />
    <axis
      xyz="1 0 0" />
    <safety_controller
      k_velocity="0" />
  </joint>
</robot>