<?xml version="1.0" encoding="utf-8"?>
<!-- This URDF was automatically created by SolidWorks to URDF Exporter! Originally created by Stephen Brawner (brawner@gmail.com) 
     Commit Version: 1.5.0-0-g9aa0fdb  Build Version: 1.5.7004.21443
     For more information, please see http://wiki.ros.org/sw_urdf_exporter -->
<robot
  name="BIOLOIDGPURDF">
  <link
    name="base_link">
    <inertial>
      <origin
        xyz="-0.00597111269746017 2.42873429701085E-13 0.00803112203996735"
        rpy="0 0 0" />
      <mass
        value="0.197310024404685" />
      <inertia
        ixx="0.000225464933012639"
        ixy="1.10285365860214E-08"
        ixz="8.85680062206937E-06"
        iyy="0.00011955864066369"
        iyz="4.41132329846465E-08"
        izz="0.0002073725918361" />
    </inertial>
    <visual>
      <origin
        xyz="0 0 0"
        rpy="0 0 0" />
      <geometry>
        <mesh
          filename="package://BIOLOIDGPURDF/meshes/base_link.STL" />
      </geometry>
      <material
        name="">
        <color
          rgba="0.792156862745098 0.819607843137255 0.933333333333333 1" />
      </material>
    </visual>
    <collision>
      <origin
        xyz="0 0 0"
        rpy="0 0 0" />
      <geometry>
        <mesh
          filename="package://BIOLOIDGPURDF/meshes/base_link.STL" />
      </geometry>
    </collision>
  </link>
  <link
    name="right_arm_link_1">
    <inertial>
      <origin
        xyz="-5.99523879707409E-08 -0.0092517241686121 0.00509147632820952"
        rpy="0 0 0" />
      <mass
        value="0.00431248529357434" />
      <inertia
        ixx="8.70633126050822E-07"
        ixy="1.77301380087765E-12"
        ixz="-1.00611738981066E-12"
        iyy="1.89328168631898E-06"
        iyz="2.56388149762672E-07"
        izz="1.81662338069163E-06" />
    </inertial>
    <visual>
      <origin
        xyz="0 0 0"
        rpy="0 0 0" />
      <geometry>
        <mesh
          filename="package://BIOLOIDGPURDF/meshes/right_arm_link_1.STL" />
      </geometry>
      <material
        name="">
        <color
          rgba="0.792156862745098 0.819607843137255 0.933333333333333 1" />
      </material>
    </visual>
    <collision>
      <origin
        xyz="0 0 0"
        rpy="0 0 0" />
      <geometry>
        <mesh
          filename="package://BIOLOIDGPURDF/meshes/right_arm_link_1.STL" />
      </geometry>
    </collision>
  </link>
  <joint
    name="joint_1"
    type="continuous">
    <origin
      xyz="0.00874999999999913 -0.0564909335310514 0.00275000000000069"
      rpy="3.14159265358979 0 3.14159265358979" />
    <parent
      link="base_link" />
    <child
      link="right_arm_link_1" />
    <axis
      xyz="0 1 0" />
    <safety_controller
      k_velocity="0" />
  </joint>
  <link
    name="right_arm_link_2">
    <inertial>
      <origin
        xyz="-0.000528170885429072 -0.035251825072309 0.00311828635700788"
        rpy="0 0 0" />
      <mass
        value="0.0866430354377455" />
      <inertia
        ixx="6.4761924185407E-05"
        ixy="-9.60813329605431E-07"
        ixz="1.88358990654775E-07"
        iyy="1.98963286836706E-05"
        iyz="3.91875640809218E-06"
        izz="5.89621039609704E-05" />
    </inertial>
    <visual>
      <origin
        xyz="0 0 0"
        rpy="0 0 0" />
      <geometry>
        <mesh
          filename="package://BIOLOIDGPURDF/meshes/right_arm_link_2.STL" />
      </geometry>
      <material
        name="">
        <color
          rgba="0.792156862745098 0.819607843137255 0.933333333333333 1" />
      </material>
    </visual>
    <collision>
      <origin
        xyz="0 0 0"
        rpy="0 0 0" />
      <geometry>
        <mesh
          filename="package://BIOLOIDGPURDF/meshes/right_arm_link_2.STL" />
      </geometry>
    </collision>
  </link>
  <joint
    name="joint_3"
    type="continuous">
    <origin
      xyz="0 -0.0230090664689468 0.0179999999999891"
      rpy="-1.5707963267949 0 1.5707963267949" />
    <parent
      link="right_arm_link_1" />
    <child
      link="right_arm_link_2" />
    <axis
      xyz="0 0 1" />
    <safety_controller
      k_velocity="0" />
  </joint>
  <link
    name="right_arm_link_3">
    <inertial>
      <origin
        xyz="-0.00606576438623159 0.0422353648311166 0.0167447249251931"
        rpy="0 0 0" />
      <mass
        value="0.0528495144448317" />
      <inertia
        ixx="1.88542572569392E-05"
        ixy="-2.20683878391148E-06"
        ixz="-1.172956194386E-07"
        iyy="1.87100847753974E-05"
        iyz="-8.67725862020746E-07"
        izz="2.5771340096243E-05" />
    </inertial>
    <visual>
      <origin
        xyz="0 0 0"
        rpy="0 0 0" />
      <geometry>
        <mesh
          filename="package://BIOLOIDGPURDF/meshes/right_arm_link_3.STL" />
      </geometry>
      <material
        name="">
        <color
          rgba="0.792156862745098 0.819607843137255 0.933333333333333 1" />
      </material>
    </visual>
    <collision>
      <origin
        xyz="0 0 0"
        rpy="0 0 0" />
      <geometry>
        <mesh
          filename="package://BIOLOIDGPURDF/meshes/right_arm_link_3.STL" />
      </geometry>
    </collision>
  </link>
  <joint
    name="joint_5"
    type="continuous">
    <origin
      xyz="0 -0.0574 0.0182000000000002"
      rpy="1.5707963267949 0 0" />
    <parent
      link="right_arm_link_2" />
    <child
      link="right_arm_link_3" />
    <axis
      xyz="1 0 0" />
    <safety_controller
      k_velocity="0" />
  </joint>
  <link
    name="right_gripper">
    <inertial>
      <origin
        xyz="0.0179998120299161 -0.00624035209800906 0.0361347174477126"
        rpy="0 0 0" />
      <mass
        value="0.00882433124339025" />
      <inertia
        ixx="7.46132223751768E-06"
        ixy="-2.18389626500294E-11"
        ixz="-7.86332274748643E-12"
        iyy="9.36079581691153E-06"
        iyz="-1.88054352881293E-06"
        izz="4.68291021353321E-06" />
    </inertial>
    <visual>
      <origin
        xyz="0 0 0"
        rpy="3.1416 0 0" />
      <geometry>
        <mesh
          filename="package://BIOLOIDGPURDF/meshes/right_gripper.STL" />
      </geometry>
      <material
        name="">
        <color
          rgba="0.792156862745098 0.819607843137255 0.933333333333333 1" />
      </material>
    </visual>
    <collision>
      <origin
        xyz="0 0 0"
        rpy="3.1416 0 0" />
      <geometry>
        <mesh
          filename="package://BIOLOIDGPURDF/meshes/right_gripper.STL" />
      </geometry>
    </collision>
  </link>
  <joint
    name="joint_7"
    type="continuous">
    <origin
      xyz="-0.0224999999999999 0.0425 0"
      rpy="1.5707963267949 -1.5707963267949 0" />
    <parent
      link="right_arm_link_3" />
    <child
      link="right_gripper" />
    <axis
      xyz="1 0 0" />
    <safety_controller
      k_velocity="0" />
  </joint>
  <link
    name="left_arm_link_1">
    <inertial>
      <origin
        xyz="-5.99523863470397E-08 -0.00925172416861354 0.00509147632820985"
        rpy="0 0 0" />
      <mass
        value="0.00431248529357434" />
      <inertia
        ixx="8.70633126050824E-07"
        ixy="1.77301379736504E-12"
        ixz="-1.00611738925695E-12"
        iyy="1.89328168631898E-06"
        iyz="2.56388149762673E-07"
        izz="1.81662338069164E-06" />
    </inertial>
    <visual>
      <origin
        xyz="0 0 0"
        rpy="0 0 0" />
      <geometry>
        <mesh
          filename="package://BIOLOIDGPURDF/meshes/left_arm_link_1.STL" />
      </geometry>
      <material
        name="">
        <color
          rgba="0.792156862745098 0.819607843137255 0.933333333333333 1" />
      </material>
    </visual>
    <collision>
      <origin
        xyz="0 0 0"
        rpy="0 0 0" />
      <geometry>
        <mesh
          filename="package://BIOLOIDGPURDF/meshes/left_arm_link_1.STL" />
      </geometry>
    </collision>
  </link>
  <joint
    name="joint_2"
    type="continuous">
    <origin
      xyz="0.00874999999999915 0.0564909335310519 0.00275"
      rpy="3.14159265358979 0 0" />
    <parent
      link="base_link" />
    <child
      link="left_arm_link_1" />
    <axis
      xyz="0 1 0" />
    <safety_controller
      k_velocity="0" />
  </joint>
  <link
    name="left_arm_link_2">
    <inertial>
      <origin
        xyz="0.000496349118212114 -0.0352836468395269 0.00311828635700813"
        rpy="0 0 0" />
      <mass
        value="0.0866430354377454" />
      <inertia
        ixx="6.48839674431359E-05"
        ixy="1.0038567960211E-06"
        ixz="-1.92543807437855E-07"
        iyy="1.98991534231237E-05"
        iyz="3.90314394747213E-06"
        izz="5.90869719581521E-05" />
    </inertial>
    <visual>
      <origin
        xyz="0 0 0"
        rpy="0 0 0" />
      <geometry>
        <mesh
          filename="package://BIOLOIDGPURDF/meshes/left_arm_link_2.STL" />
      </geometry>
      <material
        name="">
        <color
          rgba="0.792156862745098 0.819607843137255 0.933333333333333 1" />
      </material>
    </visual>
    <collision>
      <origin
        xyz="0 0 0"
        rpy="0 0 0" />
      <geometry>
        <mesh
          filename="package://BIOLOIDGPURDF/meshes/left_arm_link_2.STL" />
      </geometry>
    </collision>
  </link>
  <joint
    name="joint_4"
    type="continuous">
    <origin
      xyz="0 -0.0230090664689482 0.0179999999999895"
      rpy="-1.5707963267949 0 -1.5707963267949" />
    <parent
      link="left_arm_link_1" />
    <child
      link="left_arm_link_2" />
    <axis
      xyz="0 0 1" />
    <safety_controller
      k_velocity="0" />
  </joint>
  <link
    name="left_arm_link_3">
    <inertial>
      <origin
        xyz="0.00606577417038441 0.0421831952977966 0.0167447249221345"
        rpy="0 0 0" />
      <mass
        value="0.0528495144448317" />
      <inertia
        ixx="1.88526541486023E-05"
        ixy="2.19496656091265E-06"
        ixz="1.1729558692268E-07"
        iyy="1.87100785019237E-05"
        iyz="-8.68677608830887E-07"
        izz="2.5769730715244E-05" />
    </inertial>
    <visual>
      <origin
        xyz="0 0 0"
        rpy="0 0 0" />
      <geometry>
        <mesh
          filename="package://BIOLOIDGPURDF/meshes/left_arm_link_3.STL" />
      </geometry>
      <material
        name="">
        <color
          rgba="0.792156862745098 0.819607843137255 0.933333333333333 1" />
      </material>
    </visual>
    <collision>
      <origin
        xyz="0 0 0"
        rpy="0 0 0" />
      <geometry>
        <mesh
          filename="package://BIOLOIDGPURDF/meshes/left_arm_link_3.STL" />
      </geometry>
    </collision>
  </link>
  <joint
    name="joint_6"
    type="continuous">
    <origin
      xyz="0 -0.0573999999999997 0.018200000000001"
      rpy="1.5707963267949 0 0" />
    <parent
      link="left_arm_link_2" />
    <child
      link="left_arm_link_3" />
    <axis
      xyz="1 0 0" />
    <safety_controller
      k_velocity="0" />
  </joint>
  <link
    name="left_gripper">
    <inertial>
      <origin
        xyz="-0.0180001879700939 -0.00624035209800411 0.0361347174477271"
        rpy="0 0 0" />
      <mass
        value="0.00882433124339503" />
      <inertia
        ixx="7.46132223752179E-06"
        ixy="-2.1838961809922E-11"
        ixz="-7.86332015471738E-12"
        iyy="9.36079581691706E-06"
        iyz="-1.88054352881412E-06"
        izz="4.68291021353545E-06" />
    </inertial>
    <visual>
      <origin
        xyz="0 0 0"
        rpy="3.1416 0 0" />
      <geometry>
        <mesh
          filename="package://BIOLOIDGPURDF/meshes/left_gripper.STL" />
      </geometry>
      <material
        name="">
        <color
          rgba="0.792156862745098 0.819607843137255 0.933333333333333 1" />
      </material>
    </visual>
    <collision>
      <origin
        xyz="0 0 0"
        rpy="3.1416 0 0" />
      <geometry>
        <mesh
          filename="package://BIOLOIDGPURDF/meshes/left_gripper.STL" />
      </geometry>
    </collision>
  </link>
  <joint
    name="joint_8"
    type="continuous">
    <origin
      xyz="0.0225000000000024 0.0425 0"
      rpy="1.5707963267949 1.5707963267949 0" />
    <parent
      link="left_arm_link_3" />
    <child
      link="left_gripper" />
    <axis
      xyz="1 0 0" />
    <safety_controller
      k_velocity="0" />
  </joint>
  <link
    name="torso_Link">
    <inertial>
      <origin
        xyz="1.22991894446756E-15 -0.0218346005747998 -0.00143510443579974"
        rpy="0 0 0" />
      <mass
        value="0.0175904238224438" />
      <inertia
        ixx="1.39256548782639E-05"
        ixy="-7.47337320739357E-20"
        ixz="2.87959003007381E-19"
        iyy="1.43256116030718E-05"
        iyz="-5.19258251727891E-07"
        izz="1.52021771794982E-05" />
    </inertial>
    <visual>
      <origin
        xyz="0 0 0"
        rpy="0 0 0" />
      <geometry>
        <mesh
          filename="package://BIOLOIDGPURDF/meshes/torso_Link.STL" />
      </geometry>
      <material
        name="">
        <color
          rgba="0.792156862745098 0.819607843137255 0.933333333333333 1" />
      </material>
    </visual>
    <collision>
      <origin
        xyz="0 0 0"
        rpy="0 0 0" />
      <geometry>
        <mesh
          filename="package://BIOLOIDGPURDF/meshes/torso_Link.STL" />
      </geometry>
    </collision>
  </link>
  <joint
    name="joint_19"
    type="continuous">
    <origin
      xyz="0.00824999999999999 0 -0.02375"
      rpy="1.5707963267949 0 1.5707963267949" />
    <parent
      link="base_link" />
    <child
      link="torso_Link" />
    <axis
      xyz="0 1 0" />
    <safety_controller
      k_velocity="0" />
  </joint>
  <link
    name="right_leg_link_1">
    <inertial>
      <origin
        xyz="-0.0130433686111558 -0.00232565541955652 0.000953578453528892"
        rpy="0 0 0" />
      <mass
        value="0.0465444257122034" />
      <inertia
        ixx="9.99235737792942E-06"
        ixy="-1.71936981719273E-07"
        ixz="-9.99819793167413E-08"
        iyy="1.38273935535504E-05"
        iyz="-1.05427694515858E-07"
        izz="1.4421418206511E-05" />
    </inertial>
    <visual>
      <origin
        xyz="0 0 0"
        rpy="0 0 0" />
      <geometry>
        <mesh
          filename="package://BIOLOIDGPURDF/meshes/right_leg_link_1.STL" />
      </geometry>
      <material
        name="">
        <color
          rgba="0.792156862745098 0.819607843137255 0.933333333333333 1" />
      </material>
    </visual>
    <collision>
      <origin
        xyz="0 0 0"
        rpy="0 0 0" />
      <geometry>
        <mesh
          filename="package://BIOLOIDGPURDF/meshes/right_leg_link_1.STL" />
      </geometry>
    </collision>
  </link>
  <joint
    name="joint_9"
    type="continuous">
    <origin
      xyz="-0.016 -0.0535000000000007 0"
      rpy="0 0 0" />
    <parent
      link="torso_Link" />
    <child
      link="right_leg_link_1" />
    <axis
      xyz="0 0 1" />
    <safety_controller
      k_velocity="0" />
  </joint>
  <link
    name="right_leg_link_2">
    <inertial>
      <origin
        xyz="-0.0129933768641217 -0.0436970573415131 -0.000382655609194593"
        rpy="0 0 0" />
      <mass
        value="0.0881834718655757" />
      <inertia
        ixx="0.000101062824180916"
        ixy="-1.00002263782024E-07"
        ixz="1.2845900981245E-07"
        iyy="2.04796477612127E-05"
        iyz="-2.23397782275553E-06"
        izz="9.9543462536748E-05" />
    </inertial>
    <visual>
      <origin
        xyz="0 0 0"
        rpy="0 0 0" />
      <geometry>
        <mesh
          filename="package://BIOLOIDGPURDF/meshes/right_leg_link_2.STL" />
      </geometry>
      <material
        name="">
        <color
          rgba="0.792156862745098 0.819607843137255 0.933333333333333 1" />
      </material>
    </visual>
    <collision>
      <origin
        xyz="0 0 0"
        rpy="0 0 0" />
      <geometry>
        <mesh
          filename="package://BIOLOIDGPURDF/meshes/right_leg_link_2.STL" />
      </geometry>
    </collision>
  </link>
  <joint
    name="joint_11"
    type="continuous">
    <origin
      xyz="0 -0.0417999999999986 0"
      rpy="0 0 0" />
    <parent
      link="right_leg_link_1" />
    <child
      link="right_leg_link_2" />
    <axis
      xyz="1 0 0" />
    <safety_controller
      k_velocity="0" />
  </joint>
  <link
    name="right_leg_link_3">
    <inertial>
      <origin
        xyz="0.0139999999999993 0.0340551332977302 0.0155632377637608"
        rpy="0 0 0" />
      <mass
        value="0.0079072797227404" />
      <inertia
        ixx="5.32776553828385E-06"
        ixy="-9.24371218781444E-20"
        ixz="-3.3591791010832E-20"
        iyy="4.22027747361642E-06"
        iyz="-3.92003519035261E-07"
        izz="7.78909127423573E-06" />
    </inertial>
    <visual>
      <origin
        xyz="0 0 0"
        rpy="0 0 0" />
      <geometry>
        <mesh
          filename="package://BIOLOIDGPURDF/meshes/right_leg_link_3.STL" />
      </geometry>
      <material
        name="">
        <color
          rgba="0.792156862745098 0.819607843137255 0.933333333333333 1" />
      </material>
    </visual>
    <collision>
      <origin
        xyz="0 0 0"
        rpy="0 0 0" />
      <geometry>
        <mesh
          filename="package://BIOLOIDGPURDF/meshes/right_leg_link_3.STL" />
      </geometry>
    </collision>
  </link>
  <joint
    name="joint_13"
    type="continuous">
    <origin
      xyz="0 -0.0744000000000002 -0.0145000000000005"
      rpy="0 0 3.14159265358979" />
    <parent
      link="right_leg_link_2" />
    <child
      link="right_leg_link_3" />
    <axis
      xyz="1 0 0" />
    <safety_controller
      k_velocity="0" />
  </joint>
  <link
    name="right_leg_link_4">
    <inertial>
      <origin
        xyz="-0.0133698054325366 0.0211205241394332 0.0130895015607345"
        rpy="0 0 0" />
      <mass
        value="0.0859237565803214" />
      <inertia
        ixx="6.02259469198291E-05"
        ixy="7.29704181602787E-07"
        ixz="9.47537449993694E-08"
        iyy="2.32968656029174E-05"
        iyz="7.46386907678859E-09"
        izz="5.12809574431431E-05" />
    </inertial>
    <visual>
      <origin
        xyz="0 0 0"
        rpy="0 0 0" />
      <geometry>
        <mesh
          filename="package://BIOLOIDGPURDF/meshes/right_leg_link_4.STL" />
      </geometry>
      <material
        name="">
        <color
          rgba="0.792156862745098 0.819607843137255 0.933333333333333 1" />
      </material>
    </visual>
    <collision>
      <origin
        xyz="0 0 0"
        rpy="0 0 0" />
      <geometry>
        <mesh
          filename="package://BIOLOIDGPURDF/meshes/right_leg_link_4.STL" />
      </geometry>
    </collision>
  </link>
  <joint
    name="joint_15"
    type="continuous">
    <origin
      xyz="0 0.075 0.0145000000000001"
      rpy="-1.5707963267949 0 3.14159265358979" />
    <parent
      link="right_leg_link_3" />
    <child
      link="right_leg_link_4" />
    <axis
      xyz="1 0 0" />
    <safety_controller
      k_velocity="0" />
  </joint>
  <link
    name="right_leg_link_5">
    <inertial>
      <origin
        xyz="0.000199999993779801 -0.0275902112818819 0.00605058063621389"
        rpy="0 0 0" />
      <mass
        value="0.0175854270431212" />
      <inertia
        ixx="6.54643930160229E-06"
        ixy="-2.19848495655286E-16"
        ixz="8.47782118364479E-16"
        iyy="1.65177350592553E-05"
        iyz="2.96641934768506E-07"
        izz="1.21530015936674E-05" />
    </inertial>
    <visual>
      <origin
        xyz="0 0 0"
        rpy="0 0 0" />
      <geometry>
        <mesh
          filename="package://BIOLOIDGPURDF/meshes/right_leg_link_5.STL" />
      </geometry>
      <material
        name="">
        <color
          rgba="0.792156862745098 0.819607843137255 0.933333333333333 1" />
      </material>
    </visual>
    <collision>
      <origin
        xyz="0 0 0"
        rpy="0 0 0" />
      <geometry>
        <mesh
          filename="package://BIOLOIDGPURDF/meshes/right_leg_link_5.STL" />
      </geometry>
    </collision>
  </link>
  <joint
    name="joint_17"
    type="continuous">
    <origin
      xyz="-0.0138 0 -9.99999999997669E-05"
      rpy="1.5707963267949 0 -1.5707963267949" />
    <parent
      link="right_leg_link_4" />
    <child
      link="right_leg_link_5" />
    <axis
      xyz="1 0 0" />
    <safety_controller
      k_velocity="0" />
  </joint>
  <link
    name="left_leg_link_1">
    <inertial>
      <origin
        xyz="-0.0130433686111557 -0.00238489204053895 -0.000953578453528878"
        rpy="0 0 0" />
      <mass
        value="0.0465444257122034" />
      <inertia
        ixx="9.97936976499089E-06"
        ixy="-1.93169433759585E-07"
        ixz="9.9981979316743E-08"
        iyy="1.38273935535504E-05"
        iyz="1.03644120445212E-07"
        izz="1.44084305935725E-05" />
    </inertial>
    <visual>
      <origin
        xyz="0 0 0"
        rpy="0 0 0" />
      <geometry>
        <mesh
          filename="package://BIOLOIDGPURDF/meshes/left_leg_link_1.STL" />
      </geometry>
      <material
        name="">
        <color
          rgba="0.792156862745098 0.819607843137255 0.933333333333333 1" />
      </material>
    </visual>
    <collision>
      <origin
        xyz="0 0 0"
        rpy="0 0 0" />
      <geometry>
        <mesh
          filename="package://BIOLOIDGPURDF/meshes/left_leg_link_1.STL" />
      </geometry>
    </collision>
  </link>
  <joint
    name="joint_10"
    type="continuous">
    <origin
      xyz="0.016 -0.0535000000000007 0"
      rpy="3.14159265358979 0 -3.14159265358979" />
    <parent
      link="torso_Link" />
    <child
      link="left_leg_link_1" />
    <axis
      xyz="0 0 1" />
    <safety_controller
      k_velocity="0" />
  </joint>
  <link
    name="left_leg_link_2">
    <inertial>
      <origin
        xyz="0.0129933768640695 -0.0437283232289456 -0.00041392149663258"
        rpy="0 0 0" />
      <mass
        value="0.0881834718655757" />
      <inertia
        ixx="0.000101229845991638"
        ixy="9.83649408830372E-08"
        ixz="-1.30096332560613E-07"
        iyy="2.04774514909886E-05"
        iyz="-2.15233637129483E-06"
        izz="9.97126806176936E-05" />
    </inertial>
    <visual>
      <origin
        xyz="0 0 0"
        rpy="0 0 0" />
      <geometry>
        <mesh
          filename="package://BIOLOIDGPURDF/meshes/left_leg_link_2.STL" />
      </geometry>
      <material
        name="">
        <color
          rgba="0.792156862745098 0.819607843137255 0.933333333333333 1" />
      </material>
    </visual>
    <collision>
      <origin
        xyz="0 0 0"
        rpy="0 0 0" />
      <geometry>
        <mesh
          filename="package://BIOLOIDGPURDF/meshes/left_leg_link_2.STL" />
      </geometry>
    </collision>
  </link>
  <joint
    name="joint_12"
    type="continuous">
    <origin
      xyz="0 -0.0418000000000006 0"
      rpy="3.14159265358979 0 -3.14159265358979" />
    <parent
      link="left_leg_link_1" />
    <child
      link="left_leg_link_2" />
    <axis
      xyz="1 0 0" />
    <safety_controller
      k_velocity="0" />
  </joint>
  <link
    name="left_leg_link_3">
    <inertial>
      <origin
        xyz="-0.0140000000000145 0.0340551332977302 0.0155632377637383"
        rpy="0 0 0" />
      <mass
        value="0.00790727972274038" />
      <inertia
        ixx="5.32776553828383E-06"
        ixy="2.77979579926664E-19"
        ixz="-2.36740765015785E-18"
        iyy="4.22027747361641E-06"
        iyz="-3.92003519035259E-07"
        izz="7.78909127423571E-06" />
    </inertial>
    <visual>
      <origin
        xyz="0 0 0"
        rpy="0 0 0" />
      <geometry>
        <mesh
          filename="package://BIOLOIDGPURDF/meshes/left_leg_link_3.STL" />
      </geometry>
      <material
        name="">
        <color
          rgba="0.792156862745098 0.819607843137255 0.933333333333333 1" />
      </material>
    </visual>
    <collision>
      <origin
        xyz="0 0 0"
        rpy="0 0 0" />
      <geometry>
        <mesh
          filename="package://BIOLOIDGPURDF/meshes/left_leg_link_3.STL" />
      </geometry>
    </collision>
  </link>
  <joint
    name="joint_14"
    type="continuous">
    <origin
      xyz="0 -0.0744 -0.0145000000000106"
      rpy="0 0 3.14159265358979" />
    <parent
      link="left_leg_link_2" />
    <child
      link="left_leg_link_3" />
    <axis
      xyz="1 0 0" />
    <safety_controller
      k_velocity="0" />
  </joint>
  <link
    name="left_leg_link_4">
    <inertial>
      <origin
        xyz="0.0134018935838427 0.0210884359881069 0.0130895015607345"
        rpy="0 0 0" />
      <mass
        value="0.0859237565803214" />
      <inertia
        ixx="6.03423227002083E-05"
        ixy="-7.89206919925737E-07"
        ixz="-1.15583288842905E-07"
        iyy="2.32991493401383E-05"
        iyz="2.85691263699968E-08"
        izz="5.13996169607431E-05" />
    </inertial>
    <visual>
      <origin
        xyz="0 0 0"
        rpy="0 0 0" />
      <geometry>
        <mesh
          filename="package://BIOLOIDGPURDF/meshes/left_leg_link_4.STL" />
      </geometry>
      <material
        name="">
        <color
          rgba="0.792156862745098 0.819607843137255 0.933333333333333 1" />
      </material>
    </visual>
    <collision>
      <origin
        xyz="0 0 0"
        rpy="0 0 0" />
      <geometry>
        <mesh
          filename="package://BIOLOIDGPURDF/meshes/left_leg_link_4.STL" />
      </geometry>
    </collision>
  </link>
  <joint
    name="joint_16"
    type="continuous">
    <origin
      xyz="0 0.075 0.0144999999999907"
      rpy="-1.5707963267949 0 -3.14159265358979" />
    <parent
      link="left_leg_link_3" />
    <child
      link="left_leg_link_4" />
    <axis
      xyz="1 0 0" />
    <safety_controller
      k_velocity="0" />
  </joint>
  <link
    name="left_leg_link_5">
    <inertial>
      <origin
        xyz="-0.000199999993796648 0.0275902112818829 -0.0060505807146668"
        rpy="0 0 0" />
      <mass
        value="0.0175854270431213" />
      <inertia
        ixx="6.54643930698129E-06"
        ixy="-2.19009557593151E-16"
        ixz="-4.2299173137052E-16"
        iyy="1.65177350646342E-05"
        iyz="2.9664192591197E-07"
        izz="1.21530015936675E-05" />
    </inertial>
    <visual>
      <origin
        xyz="0 0 0"
        rpy="0 0 0" />
      <geometry>
        <mesh
          filename="package://BIOLOIDGPURDF/meshes/left_leg_link_5.STL" />
      </geometry>
      <material
        name="">
        <color
          rgba="0.792156862745098 0.819607843137255 0.933333333333333 1" />
      </material>
    </visual>
    <collision>
      <origin
        xyz="0 0 0"
        rpy="0 0 0" />
      <geometry>
        <mesh
          filename="package://BIOLOIDGPURDF/meshes/left_leg_link_5.STL" />
      </geometry>
    </collision>
  </link>
  <joint
    name="joint_18"
    type="continuous">
    <origin
      xyz="0.0137999999999867 0 -9.9999999999989E-05"
      rpy="-1.5707963267949 0 1.5707963267949" />
    <parent
      link="left_leg_link_4" />
    <child
      link="left_leg_link_5" />
    <axis
      xyz="1 0 0" />
    <safety_controller
      k_velocity="0" />
  </joint>
  <link
    name="head_link">
    <inertial>
      <origin
        xyz="1.92660815680375E-07 0.000589833196490114 -0.0219995934404275"
        rpy="0 0 0" />
      <mass
        value="0.0131552831434282" />
      <inertia
        ixx="5.23338949852371E-06"
        ixy="3.48156234986867E-12"
        ixz="6.72257113125423E-11"
        iyy="9.22115966799723E-06"
        iyz="-7.97728602162947E-08"
        izz="6.00760307627287E-06" />
    </inertial>
    <visual>
      <origin
        xyz="0 0 0"
        rpy="0 0 0" />
      <geometry>
        <mesh
          filename="package://BIOLOIDGPURDF/meshes/head_link.STL" />
      </geometry>
      <material
        name="">
        <color
          rgba="0.792156862745098 0.819607843137255 0.933333333333333 1" />
      </material>
    </visual>
    <collision>
      <origin
        xyz="0 0 0"
        rpy="0 0 0" />
      <geometry>
        <mesh
          filename="package://BIOLOIDGPURDF/meshes/head_link.STL" />
      </geometry>
    </collision>
  </link>
  <joint
    name="joint_20"
    type="continuous">
    <origin
      xyz="0.000250000000000014 0 0.0555498969223593"
      rpy="3.14159265358979 0 -1.5707963267949" />
    <parent
      link="base_link" />
    <child
      link="head_link" />
    <axis
      xyz="0 0 1" />
    <safety_controller
      k_velocity="0" />
  </joint>
  <link
    name="camera">
    <inertial>
      <origin
        xyz="-4.37141916987821E-05 -0.0368905949193783 0.000350614361722198"
        rpy="0 0 0" />
      <mass
        value="0.095160987633104" />
      <inertia
        ixx="8.89918647837385E-05"
        ixy="-3.52135014298042E-08"
        ixz="2.53853932051776E-10"
        iyy="3.82187121277295E-05"
        iyz="-1.49170179733209E-06"
        izz="6.00706363711014E-05" />
    </inertial>
    <visual>
      <origin
        xyz="0 0 0"
        rpy="0 0 0" />
      <geometry>
        <mesh
          filename="package://BIOLOIDGPURDF/meshes/camera.STL" />
      </geometry>
      <material
        name="">
        <color
          rgba="0.792156862745098 0.819607843137255 0.933333333333333 1" />
      </material>
    </visual>
    <collision>
      <origin
        xyz="0 0 0"
        rpy="0 0 0" />
      <geometry>
        <mesh
          filename="package://BIOLOIDGPURDF/meshes/camera.STL" />
      </geometry>
    </collision>
  </link>
  <joint
    name="joint_21"
    type="continuous">
    <origin
      xyz="0 0 -0.0537001030776406"
      rpy="0 1.5707963267949 0" />
    <parent
      link="head_link" />
    <child
      link="camera" />
    <axis
      xyz="0 0 1" />
    <safety_controller
      k_velocity="0" />
  </joint>
</robot>
