<sdf version='1.6'>
  <world name='default'>
    <light name='sun' type='directional'>
      <cast_shadows>1</cast_shadows>
      <pose frame=''>0 0 10 0 -0 0</pose>
      <diffuse>0.8 0.8 0.8 1</diffuse>
      <specular>0.2 0.2 0.2 1</specular>
      <attenuation>
        <range>1000</range>
        <constant>0.9</constant>
        <linear>0.01</linear>
        <quadratic>0.001</quadratic>
      </attenuation>
      <direction>-0.5 0.1 -0.9</direction>
    </light>
    <model name='ground_plane'>
      <static>1</static>
      <link name='link'>
        <collision name='collision'>
          <geometry>
            <plane>
              <normal>0 0 1</normal>
              <size>100 100</size>
            </plane>
          </geometry>
          <surface>
            <contact>
              <collide_bitmask>65535</collide_bitmask>
              <ode/>
            </contact>
            <friction>
              <ode>
                <mu>100</mu>
                <mu2>50</mu2>
              </ode>
              <torsional>
                <ode/>
              </torsional>
            </friction>
            <bounce/>
          </surface>
          <max_contacts>10</max_contacts>
        </collision>
        <visual name='visual'>
          <cast_shadows>0</cast_shadows>
          <geometry>
            <plane>
              <normal>0 0 1</normal>
              <size>100 100</size>
            </plane>
          </geometry>
          <material>
            <script>
              <uri>file://media/materials/scripts/gazebo.material</uri>
              <name>Gazebo/Grey</name>
            </script>
          </material>
        </visual>
        <self_collide>0</self_collide>
        <enable_wind>0</enable_wind>
        <kinematic>0</kinematic>
      </link>
    </model>
    <gravity>0 0 -9.8</gravity>
    <magnetic_field>6e-06 2.3e-05 -4.2e-05</magnetic_field>
    <atmosphere type='adiabatic'/>
    <physics name='default_physics' default='0' type='ode'>
      <max_step_size>0.001</max_step_size>
      <real_time_factor>1</real_time_factor>
      <real_time_update_rate>1000</real_time_update_rate>
    </physics>
    <scene>
      <ambient>0.4 0.4 0.4 1</ambient>
      <background>0.7 0.7 0.7 1</background>
      <shadows>1</shadows>
    </scene>
    <audio>
      <device>default</device>
    </audio>
    <wind/>
    <spherical_coordinates>
      <surface_model>EARTH_WGS84</surface_model>
      <latitude_deg>0</latitude_deg>
      <longitude_deg>0</longitude_deg>
      <elevation>0</elevation>
      <heading_deg>0</heading_deg>
    </spherical_coordinates>
    <model name='bioloidgp_social_robot'>
      <link name='dummy'>
        <pose frame=''>0 0 0 0 -0 0</pose>
        <inertial>
          <pose frame=''>-0.000118 -0 -0.010051 0 -0 0</pose>
          <mass>0.23897</mass>
          <inertia>
            <ixx>1</ixx>
            <ixy>0</ixy>
            <ixz>0</ixz>
            <iyy>1</iyy>
            <iyz>0</iyz>
            <izz>1</izz>
          </inertia>
        </inertial>
        <collision name='dummy_fixed_joint_lump__base_link_collision'>
          <pose frame=''>0 0 0 0 -0 0</pose>
          <geometry>
            <mesh>
              <scale>1 1 1</scale>
              <uri>/home/francisco/robotis_ws/src/ros-bioloid-gp/src/bioloid_gp_description/bioloidgp_social_robot/meshes/base_link.STL</uri>
            </mesh>
          </geometry>
          <max_contacts>10</max_contacts>
          <surface>
            <contact>
              <ode/>
            </contact>
            <bounce/>
            <friction>
              <torsional>
                <ode/>
              </torsional>
              <ode/>
            </friction>
          </surface>
        </collision>
        <visual name='dummy_fixed_joint_lump__base_link_visual'>
          <pose frame=''>0 0 0 0 -0 0</pose>
          <geometry>
            <mesh>
              <scale>1 1 1</scale>
              <uri>/home/francisco/robotis_ws/src/ros-bioloid-gp/src/bioloid_gp_description/bioloidgp_social_robot/meshes/base_link.STL</uri>
            </mesh>
          </geometry>
        </visual>
        <visual name='dummy_fixed_joint_lump__imu_link_visual_1'>
          <pose frame=''>0.00825 0 -0.035 0 -0 0</pose>
          <geometry>
            <box>
              <size>0.016 0.026 0.005</size>
            </box>
          </geometry>
        </visual>
        <self_collide>0</self_collide>
        <enable_wind>0</enable_wind>
        <kinematic>0</kinematic>
      </link>
      <link name='right_arm_link_1'>
        <pose frame=''>0.00875 -0.05649 0.00275 3.14159 -0 0</pose>
        <inertial>
          <pose frame=''>-0 -0.009232 0.005179 0 -0 0</pose>
          <mass>0.00402029</mass>
          <inertia>
            <ixx>1</ixx>
            <ixy>0</ixy>
            <ixz>0</ixz>
            <iyy>1</iyy>
            <iyz>0</iyz>
            <izz>1</izz>
          </inertia>
        </inertial>
        <collision name='right_arm_link_1_collision'>
          <pose frame=''>0 0 0 0 -0 3.14159</pose>
          <geometry>
            <mesh>
              <scale>1 1 1</scale>
              <uri>/home/francisco/robotis_ws/src/ros-bioloid-gp/src/bioloid_gp_description/bioloidgp_social_robot/meshes/right_arm_link_1.STL</uri>
            </mesh>
          </geometry>
          <max_contacts>10</max_contacts>
          <surface>
            <contact>
              <ode/>
            </contact>
            <bounce/>
            <friction>
              <torsional>
                <ode/>
              </torsional>
              <ode/>
            </friction>
          </surface>
        </collision>
        <visual name='right_arm_link_1_visual'>
          <pose frame=''>0 0 0 0 -0 3.14159</pose>
          <geometry>
            <mesh>
              <scale>1 1 1</scale>
              <uri>/home/francisco/robotis_ws/src/ros-bioloid-gp/src/bioloid_gp_description/bioloidgp_social_robot/meshes/right_arm_link_1.STL</uri>
            </mesh>
          </geometry>
        </visual>
        <self_collide>0</self_collide>
        <enable_wind>0</enable_wind>
        <kinematic>0</kinematic>
      </link>
      <joint name='joint_1' type='revolute'>
        <child>right_arm_link_1</child>
        <parent>dummy</parent>
        <axis>
          <xyz>0 -1 0</xyz>
          <limit>
            <lower>-1e+16</lower>
            <upper>1e+16</upper>
          </limit>
          <dynamics>
            <spring_reference>0</spring_reference>
            <spring_stiffness>0</spring_stiffness>
          </dynamics>
          <use_parent_model_frame>1</use_parent_model_frame>
        </axis>
      </joint>
      <link name='right_arm_link_2'>
        <pose frame=''>0.00875 -0.0795 -0.01525 1.5708 0 -1.5708</pose>
        <inertial>
          <pose frame=''>-0.000528 -0.035252 0.003118 0 -0 0</pose>
          <mass>0.086643</mass>
          <inertia>
            <ixx>1</ixx>
            <ixy>0</ixy>
            <ixz>0</ixz>
            <iyy>1</iyy>
            <iyz>0</iyz>
            <izz>1</izz>
          </inertia>
        </inertial>
        <collision name='right_arm_link_2_collision'>
          <pose frame=''>0 0 0 3.14159 -0 3.14159</pose>
          <geometry>
            <mesh>
              <scale>1 1 1</scale>
              <uri>/home/francisco/robotis_ws/src/ros-bioloid-gp/src/bioloid_gp_description/bioloidgp_social_robot/meshes/right_arm_link_2.STL</uri>
            </mesh>
          </geometry>
          <max_contacts>10</max_contacts>
          <surface>
            <contact>
              <ode/>
            </contact>
            <bounce/>
            <friction>
              <torsional>
                <ode/>
              </torsional>
              <ode/>
            </friction>
          </surface>
        </collision>
        <visual name='right_arm_link_2_visual'>
          <pose frame=''>0 0 0 3.14159 -0 3.14159</pose>
          <geometry>
            <mesh>
              <scale>1 1 1</scale>
              <uri>/home/francisco/robotis_ws/src/ros-bioloid-gp/src/bioloid_gp_description/bioloidgp_social_robot/meshes/right_arm_link_2.STL</uri>
            </mesh>
          </geometry>
        </visual>
        <self_collide>0</self_collide>
        <enable_wind>0</enable_wind>
        <kinematic>0</kinematic>
      </link>
      <joint name='joint_3' type='revolute'>
        <child>right_arm_link_2</child>
        <parent>right_arm_link_1</parent>
        <axis>
          <xyz>-1 0 0</xyz>
          <limit>
            <lower>-1e+16</lower>
            <upper>1e+16</upper>
          </limit>
          <dynamics>
            <spring_reference>0</spring_reference>
            <spring_stiffness>0</spring_stiffness>
          </dynamics>
          <use_parent_model_frame>1</use_parent_model_frame>
        </axis>
      </joint>
      <link name='right_arm_link_3'>
        <pose frame=''>0.02695 -0.0795 -0.07265 3.14159 -0 -1.5708</pose>
        <inertial>
          <pose frame=''>-0.006099 0.042395 0.016759 0 -0 0</pose>
          <mass>0.0525573</mass>
          <inertia>
            <ixx>1</ixx>
            <ixy>0</ixy>
            <ixz>0</ixz>
            <iyy>1</iyy>
            <iyz>0</iyz>
            <izz>1</izz>
          </inertia>
        </inertial>
        <collision name='right_arm_link_3_collision'>
          <pose frame=''>0 0 0 0 -0 3.14159</pose>
          <geometry>
            <mesh>
              <scale>1 1 1</scale>
              <uri>/home/francisco/robotis_ws/src/ros-bioloid-gp/src/bioloid_gp_description/bioloidgp_social_robot/meshes/right_arm_link_3.STL</uri>
            </mesh>
          </geometry>
          <max_contacts>10</max_contacts>
          <surface>
            <contact>
              <ode/>
            </contact>
            <bounce/>
            <friction>
              <torsional>
                <ode/>
              </torsional>
              <ode/>
            </friction>
          </surface>
        </collision>
        <visual name='right_arm_link_3_visual'>
          <pose frame=''>0 0 0 0 -0 3.14159</pose>
          <geometry>
            <mesh>
              <scale>1 1 1</scale>
              <uri>/home/francisco/robotis_ws/src/ros-bioloid-gp/src/bioloid_gp_description/bioloidgp_social_robot/meshes/right_arm_link_3.STL</uri>
            </mesh>
          </geometry>
        </visual>
        <self_collide>0</self_collide>
        <enable_wind>0</enable_wind>
        <kinematic>0</kinematic>
      </link>
      <joint name='joint_5' type='revolute'>
        <child>right_arm_link_3</child>
        <parent>right_arm_link_2</parent>
        <axis>
          <xyz>-0 -1 0</xyz>
          <limit>
            <lower>-1e+16</lower>
            <upper>1e+16</upper>
          </limit>
          <dynamics>
            <spring_reference>0</spring_reference>
            <spring_stiffness>0</spring_stiffness>
          </dynamics>
          <use_parent_model_frame>1</use_parent_model_frame>
        </axis>
      </joint>
      <link name='right_gripper'>
        <pose frame=''>0.06945 -0.102 -0.07265 -3e-06 -1.57079 3.14159</pose>
        <inertial>
          <pose frame=''>0.018 -0.00624 0.036135 3.14159 -0 0</pose>
          <mass>0.00882433</mass>
          <inertia>
            <ixx>1</ixx>
            <ixy>0</ixy>
            <ixz>0</ixz>
            <iyy>1</iyy>
            <iyz>0</iyz>
            <izz>1</izz>
          </inertia>
        </inertial>
        <collision name='right_gripper_collision'>
          <pose frame=''>0 0 0 0 -0 3.14159</pose>
          <geometry>
            <mesh>
              <scale>1 1 1</scale>
              <uri>/home/francisco/robotis_ws/src/ros-bioloid-gp/src/bioloid_gp_description/bioloidgp_social_robot/meshes/right_gripper.STL</uri>
            </mesh>
          </geometry>
          <max_contacts>10</max_contacts>
          <surface>
            <contact>
              <ode/>
            </contact>
            <bounce/>
            <friction>
              <torsional>
                <ode/>
              </torsional>
              <ode/>
            </friction>
          </surface>
        </collision>
        <visual name='right_gripper_visual'>
          <pose frame=''>0 0 0 0 -0 3.14159</pose>
          <geometry>
            <mesh>
              <scale>1 1 1</scale>
              <uri>/home/francisco/robotis_ws/src/ros-bioloid-gp/src/bioloid_gp_description/bioloidgp_social_robot/meshes/right_gripper.STL</uri>
            </mesh>
          </geometry>
        </visual>
        <self_collide>0</self_collide>
        <enable_wind>0</enable_wind>
        <kinematic>0</kinematic>
      </link>
      <joint name='joint_7' type='revolute'>
        <child>right_gripper</child>
        <parent>right_arm_link_3</parent>
        <axis>
          <xyz>0 0 1</xyz>
          <limit>
            <lower>-1e+16</lower>
            <upper>1e+16</upper>
          </limit>
          <dynamics>
            <spring_reference>0</spring_reference>
            <spring_stiffness>0</spring_stiffness>
          </dynamics>
          <use_parent_model_frame>1</use_parent_model_frame>
        </axis>
      </joint>
      <link name='torso_Link'>
        <pose frame=''>0.00825 0 -0.05725 1.5708 -0 1.5708</pose>
        <inertial>
          <pose frame=''>0 -0.021091 -0.001319 0 -0 0</pose>
          <mass>0.0150307</mass>
          <inertia>
            <ixx>1</ixx>
            <ixy>0</ixy>
            <ixz>0</ixz>
            <iyy>1</iyy>
            <iyz>0</iyz>
            <izz>1</izz>
          </inertia>
        </inertial>
        <collision name='torso_Link_collision'>
          <pose frame=''>0 0 0 0 -0 0</pose>
          <geometry>
            <mesh>
              <scale>1 1 1</scale>
              <uri>/home/francisco/robotis_ws/src/ros-bioloid-gp/src/bioloid_gp_description/bioloidgp_social_robot/meshes/torso_Link.STL</uri>
            </mesh>
          </geometry>
          <max_contacts>10</max_contacts>
          <surface>
            <contact>
              <ode/>
            </contact>
            <bounce/>
            <friction>
              <torsional>
                <ode/>
              </torsional>
              <ode/>
            </friction>
          </surface>
        </collision>
        <visual name='torso_Link_visual'>
          <pose frame=''>0 0 0 0 -0 0</pose>
          <geometry>
            <mesh>
              <scale>1 1 1</scale>
              <uri>/home/francisco/robotis_ws/src/ros-bioloid-gp/src/bioloid_gp_description/bioloidgp_social_robot/meshes/torso_Link.STL</uri>
            </mesh>
          </geometry>
        </visual>
        <self_collide>0</self_collide>
        <enable_wind>0</enable_wind>
        <kinematic>0</kinematic>
      </link>
      <joint name='joint_19' type='revolute'>
        <child>torso_Link</child>
        <parent>dummy</parent>
        <axis>
          <xyz>0 -0 1</xyz>
          <limit>
            <lower>-1e+16</lower>
            <upper>1e+16</upper>
          </limit>
          <dynamics>
            <spring_reference>0</spring_reference>
            <spring_stiffness>0</spring_stiffness>
          </dynamics>
          <use_parent_model_frame>1</use_parent_model_frame>
        </axis>
      </joint>
      <link name='left_leg_link_1'>
        <pose frame=''>0.00825 0.016 -0.11075 1.5708 0 -1.5708</pose>
        <inertial>
          <pose frame=''>-0.013043 -0.002385 -0.000954 0 -0 0</pose>
          <mass>0.0465444</mass>
          <inertia>
            <ixx>1</ixx>
            <ixy>0</ixy>
            <ixz>0</ixz>
            <iyy>1</iyy>
            <iyz>0</iyz>
            <izz>1</izz>
          </inertia>
        </inertial>
        <collision name='left_leg_link_1_collision'>
          <pose frame=''>0 0 0 0 -0 0</pose>
          <geometry>
            <mesh>
              <scale>1 1 1</scale>
              <uri>/home/francisco/robotis_ws/src/ros-bioloid-gp/src/bioloid_gp_description/bioloidgp_social_robot/meshes/left_leg_link_1.STL</uri>
            </mesh>
          </geometry>
          <max_contacts>10</max_contacts>
          <surface>
            <contact>
              <ode/>
            </contact>
            <bounce/>
            <friction>
              <torsional>
                <ode/>
              </torsional>
              <ode/>
            </friction>
          </surface>
        </collision>
        <visual name='left_leg_link_1_visual'>
          <pose frame=''>0 0 0 0 -0 0</pose>
          <geometry>
            <mesh>
              <scale>1 1 1</scale>
              <uri>/home/francisco/robotis_ws/src/ros-bioloid-gp/src/bioloid_gp_description/bioloidgp_social_robot/meshes/left_leg_link_1.STL</uri>
            </mesh>
          </geometry>
        </visual>
        <self_collide>0</self_collide>
        <enable_wind>0</enable_wind>
        <kinematic>0</kinematic>
      </link>
      <joint name='joint_10' type='revolute'>
        <child>left_leg_link_1</child>
        <parent>torso_Link</parent>
        <axis>
          <xyz>-1 -0 0</xyz>
          <limit>
            <lower>-1e+16</lower>
            <upper>1e+16</upper>
          </limit>
          <dynamics>
            <spring_reference>0</spring_reference>
            <spring_stiffness>0</spring_stiffness>
          </dynamics>
          <use_parent_model_frame>1</use_parent_model_frame>
        </axis>
      </joint>
      <link name='left_leg_link_2'>
        <pose frame=''>0.00825 0.016 -0.15255 1.5708 -0 1.5708</pose>
        <inertial>
          <pose frame=''>0.012984 -0.043701 -0.000498 0 -0 0</pose>
          <mass>0.087396</mass>
          <inertia>
            <ixx>1</ixx>
            <ixy>0</ixy>
            <ixz>0</ixz>
            <iyy>1</iyy>
            <iyz>0</iyz>
            <izz>1</izz>
          </inertia>
        </inertial>
        <collision name='left_leg_link_2_collision'>
          <pose frame=''>0 0 0 0 -0 0</pose>
          <geometry>
            <mesh>
              <scale>1 1 1</scale>
              <uri>/home/francisco/robotis_ws/src/ros-bioloid-gp/src/bioloid_gp_description/bioloidgp_social_robot/meshes/left_leg_link_2.STL</uri>
            </mesh>
          </geometry>
          <max_contacts>10</max_contacts>
          <surface>
            <contact>
              <ode/>
            </contact>
            <bounce/>
            <friction>
              <torsional>
                <ode/>
              </torsional>
              <ode/>
            </friction>
          </surface>
        </collision>
        <visual name='left_leg_link_2_visual'>
          <pose frame=''>0 0 0 0 -0 0</pose>
          <geometry>
            <mesh>
              <scale>1 1 1</scale>
              <uri>/home/francisco/robotis_ws/src/ros-bioloid-gp/src/bioloid_gp_description/bioloidgp_social_robot/meshes/left_leg_link_2.STL</uri>
            </mesh>
          </geometry>
        </visual>
        <self_collide>0</self_collide>
        <enable_wind>0</enable_wind>
        <kinematic>0</kinematic>
      </link>
      <joint name='joint_12' type='revolute'>
        <child>left_leg_link_2</child>
        <parent>left_leg_link_1</parent>
        <axis>
          <xyz>-0 1 -0</xyz>
          <limit>
            <lower>-1e+16</lower>
            <upper>1e+16</upper>
          </limit>
          <dynamics>
            <spring_reference>0</spring_reference>
            <spring_stiffness>0</spring_stiffness>
          </dynamics>
          <use_parent_model_frame>1</use_parent_model_frame>
        </axis>
      </joint>
      <link name='left_leg_link_3'>
        <pose frame=''>-0.00625 0.016 -0.22695 -1.5708 -0 -1.5708</pose>
        <inertial>
          <pose frame=''>-0.014 0.033556 0.015194 0 -0 0</pose>
          <mass>0.00701487</mass>
          <inertia>
            <ixx>1</ixx>
            <ixy>0</ixy>
            <ixz>0</ixz>
            <iyy>1</iyy>
            <iyz>0</iyz>
            <izz>1</izz>
          </inertia>
        </inertial>
        <collision name='left_leg_link_3_collision'>
          <pose frame=''>0 0 0 0 -0 0</pose>
          <geometry>
            <mesh>
              <scale>1 1 1</scale>
              <uri>/home/francisco/robotis_ws/src/ros-bioloid-gp/src/bioloid_gp_description/bioloidgp_social_robot/meshes/left_leg_link_3.STL</uri>
            </mesh>
          </geometry>
          <max_contacts>10</max_contacts>
          <surface>
            <contact>
              <ode/>
            </contact>
            <bounce/>
            <friction>
              <torsional>
                <ode/>
              </torsional>
              <ode/>
            </friction>
          </surface>
        </collision>
        <visual name='left_leg_link_3_visual'>
          <pose frame=''>0 0 0 0 -0 0</pose>
          <geometry>
            <mesh>
              <scale>1 1 1</scale>
              <uri>/home/francisco/robotis_ws/src/ros-bioloid-gp/src/bioloid_gp_description/bioloidgp_social_robot/meshes/left_leg_link_3.STL</uri>
            </mesh>
          </geometry>
        </visual>
        <self_collide>0</self_collide>
        <enable_wind>0</enable_wind>
        <kinematic>0</kinematic>
      </link>
      <joint name='joint_14' type='revolute'>
        <child>left_leg_link_3</child>
        <parent>left_leg_link_2</parent>
        <axis>
          <xyz>0 -1 0</xyz>
          <limit>
            <lower>-1e+16</lower>
            <upper>1e+16</upper>
          </limit>
          <dynamics>
            <spring_reference>0</spring_reference>
            <spring_stiffness>0</spring_stiffness>
          </dynamics>
          <use_parent_model_frame>1</use_parent_model_frame>
        </axis>
      </joint>
      <link name='left_leg_link_4'>
        <pose frame=''>0.00825 0.016 -0.30195 0 -0 1.5708</pose>
        <inertial>
          <pose frame=''>0.0134 0.021096 0.013055 0 -0 0</pose>
          <mass>0.0856772</mass>
          <inertia>
            <ixx>1</ixx>
            <ixy>0</ixy>
            <ixz>0</ixz>
            <iyy>1</iyy>
            <iyz>0</iyz>
            <izz>1</izz>
          </inertia>
        </inertial>
        <collision name='left_leg_link_4_collision'>
          <pose frame=''>0 0 0 0 -0 0</pose>
          <geometry>
            <mesh>
              <scale>1 1 1</scale>
              <uri>/home/francisco/robotis_ws/src/ros-bioloid-gp/src/bioloid_gp_description/bioloidgp_social_robot/meshes/left_leg_link_4.STL</uri>
            </mesh>
          </geometry>
          <max_contacts>10</max_contacts>
          <surface>
            <contact>
              <ode/>
            </contact>
            <bounce/>
            <friction>
              <torsional>
                <ode/>
              </torsional>
              <ode/>
            </friction>
          </surface>
        </collision>
        <visual name='left_leg_link_4_visual'>
          <pose frame=''>0 0 0 0 -0 0</pose>
          <geometry>
            <mesh>
              <scale>1 1 1</scale>
              <uri>/home/francisco/robotis_ws/src/ros-bioloid-gp/src/bioloid_gp_description/bioloidgp_social_robot/meshes/left_leg_link_4.STL</uri>
            </mesh>
          </geometry>
        </visual>
        <self_collide>0</self_collide>
        <enable_wind>0</enable_wind>
        <kinematic>0</kinematic>
      </link>
      <joint name='joint_16' type='revolute'>
        <child>left_leg_link_4</child>
        <parent>left_leg_link_3</parent>
        <axis>
          <xyz>-0 1 -0</xyz>
          <limit>
            <lower>-1e+16</lower>
            <upper>1e+16</upper>
          </limit>
          <dynamics>
            <spring_reference>0</spring_reference>
            <spring_stiffness>0</spring_stiffness>
          </dynamics>
          <use_parent_model_frame>1</use_parent_model_frame>
        </axis>
      </joint>
      <link name='left_leg_link_5'>
        <pose frame=''>0.00825 0.0298 -0.30205 1.5708 -0 0</pose>
        <inertial>
          <pose frame=''>-0.0002 0.027102 -0.005782 0 -0 0</pose>
          <mass>0.0145032</mass>
          <inertia>
            <ixx>1</ixx>
            <ixy>0</ixy>
            <ixz>0</ixz>
            <iyy>1</iyy>
            <iyz>0</iyz>
            <izz>1</izz>
          </inertia>
        </inertial>
        <collision name='left_leg_link_5_collision'>
          <pose frame=''>0 0 0 0 -0 3.14159</pose>
          <geometry>
            <mesh>
              <scale>1 1 1</scale>
              <uri>/home/francisco/robotis_ws/src/ros-bioloid-gp/src/bioloid_gp_description/bioloidgp_social_robot/meshes/left_leg_link_5.STL</uri>
            </mesh>
          </geometry>
          <surface>
            <contact>
              <ode/>
            </contact>
            <friction>
              <ode>
                <mu>0.9</mu>
                <mu2>0.9</mu2>
              </ode>
              <torsional>
                <ode/>
              </torsional>
            </friction>
            <bounce/>
          </surface>
          <max_contacts>10</max_contacts>
        </collision>
        <visual name='left_leg_link_5_visual'>
          <pose frame=''>0 0 0 0 -0 3.14159</pose>
          <geometry>
            <mesh>
              <scale>1 1 1</scale>
              <uri>/home/francisco/robotis_ws/src/ros-bioloid-gp/src/bioloid_gp_description/bioloidgp_social_robot/meshes/left_leg_link_5.STL</uri>
            </mesh>
          </geometry>
          <material>
            <script>
              <uri>__default__</uri>
              <name>__default__</name>
            </script>
          </material>
        </visual>
        <gravity>1</gravity>
        <velocity_decay/>
        <self_collide>0</self_collide>
        <enable_wind>0</enable_wind>
        <kinematic>0</kinematic>
      </link>
      <joint name='joint_18' type='revolute'>
        <child>left_leg_link_5</child>
        <parent>left_leg_link_4</parent>
        <axis>
          <xyz>1 0 0</xyz>
          <limit>
            <lower>-1e+16</lower>
            <upper>1e+16</upper>
          </limit>
          <dynamics>
            <spring_reference>0</spring_reference>
            <spring_stiffness>0</spring_stiffness>
          </dynamics>
          <use_parent_model_frame>1</use_parent_model_frame>
        </axis>
      </joint>
      <link name='right_leg_link_1'>
        <pose frame=''>0.00825 -0.016 -0.11075 1.5708 0 -1.5708</pose>
        <inertial>
          <pose frame=''>-0.013043 -0.002326 0.000954 0 -0 0</pose>
          <mass>0.0465444</mass>
          <inertia>
            <ixx>1</ixx>
            <ixy>0</ixy>
            <ixz>0</ixz>
            <iyy>1</iyy>
            <iyz>0</iyz>
            <izz>1</izz>
          </inertia>
        </inertial>
        <collision name='right_leg_link_1_collision'>
          <pose frame=''>0 0 0 3.14159 -0 3.14159</pose>
          <geometry>
            <mesh>
              <scale>1 1 1</scale>
              <uri>/home/francisco/robotis_ws/src/ros-bioloid-gp/src/bioloid_gp_description/bioloidgp_social_robot/meshes/right_leg_link_1.STL</uri>
            </mesh>
          </geometry>
          <max_contacts>10</max_contacts>
          <surface>
            <contact>
              <ode/>
            </contact>
            <bounce/>
            <friction>
              <torsional>
                <ode/>
              </torsional>
              <ode/>
            </friction>
          </surface>
        </collision>
        <visual name='right_leg_link_1_visual'>
          <pose frame=''>0 0 0 3.14159 -0 3.14159</pose>
          <geometry>
            <mesh>
              <scale>1 1 1</scale>
              <uri>/home/francisco/robotis_ws/src/ros-bioloid-gp/src/bioloid_gp_description/bioloidgp_social_robot/meshes/right_leg_link_1.STL</uri>
            </mesh>
          </geometry>
        </visual>
        <self_collide>0</self_collide>
        <enable_wind>0</enable_wind>
        <kinematic>0</kinematic>
      </link>
      <joint name='joint_9' type='revolute'>
        <child>right_leg_link_1</child>
        <parent>torso_Link</parent>
        <axis>
          <xyz>-1 -0 0</xyz>
          <limit>
            <lower>-1e+16</lower>
            <upper>1e+16</upper>
          </limit>
          <dynamics>
            <spring_reference>0</spring_reference>
            <spring_stiffness>0</spring_stiffness>
          </dynamics>
          <use_parent_model_frame>1</use_parent_model_frame>
        </axis>
      </joint>
      <link name='right_leg_link_2'>
        <pose frame=''>0.00825 -0.016 -0.15255 1.5708 0 -1.5708</pose>
        <inertial>
          <pose frame=''>-0.012984 -0.043669 -0.000467 0 -0 0</pose>
          <mass>0.087396</mass>
          <inertia>
            <ixx>1</ixx>
            <ixy>0</ixy>
            <ixz>0</ixz>
            <iyy>1</iyy>
            <iyz>0</iyz>
            <izz>1</izz>
          </inertia>
        </inertial>
        <collision name='right_leg_link_2_collision'>
          <pose frame=''>0 0 0 3.14159 -0 3.14159</pose>
          <geometry>
            <mesh>
              <scale>1 1 1</scale>
              <uri>/home/francisco/robotis_ws/src/ros-bioloid-gp/src/bioloid_gp_description/bioloidgp_social_robot/meshes/right_leg_link_2.STL</uri>
            </mesh>
          </geometry>
          <max_contacts>10</max_contacts>
          <surface>
            <contact>
              <ode/>
            </contact>
            <bounce/>
            <friction>
              <torsional>
                <ode/>
              </torsional>
              <ode/>
            </friction>
          </surface>
        </collision>
        <visual name='right_leg_link_2_visual'>
          <pose frame=''>0 0 0 3.14159 -0 3.14159</pose>
          <geometry>
            <mesh>
              <scale>1 1 1</scale>
              <uri>/home/francisco/robotis_ws/src/ros-bioloid-gp/src/bioloid_gp_description/bioloidgp_social_robot/meshes/right_leg_link_2.STL</uri>
            </mesh>
          </geometry>
        </visual>
        <self_collide>0</self_collide>
        <enable_wind>0</enable_wind>
        <kinematic>0</kinematic>
      </link>
      <joint name='joint_11' type='revolute'>
        <child>right_leg_link_2</child>
        <parent>right_leg_link_1</parent>
        <axis>
          <xyz>0 -1 0</xyz>
          <limit>
            <lower>-1e+16</lower>
            <upper>1e+16</upper>
          </limit>
          <dynamics>
            <spring_reference>0</spring_reference>
            <spring_stiffness>0</spring_stiffness>
          </dynamics>
          <use_parent_model_frame>1</use_parent_model_frame>
        </axis>
      </joint>
      <link name='right_leg_link_3'>
        <pose frame=''>-0.00625 -0.016 -0.22695 -1.5708 0 1.5708</pose>
        <inertial>
          <pose frame=''>0.014 0.033556 0.015194 0 -0 0</pose>
          <mass>0.00701487</mass>
          <inertia>
            <ixx>1</ixx>
            <ixy>0</ixy>
            <ixz>0</ixz>
            <iyy>1</iyy>
            <iyz>0</iyz>
            <izz>1</izz>
          </inertia>
        </inertial>
        <collision name='right_leg_link_3_collision'>
          <pose frame=''>0 0 0 3.14159 -0 3.14159</pose>
          <geometry>
            <mesh>
              <scale>1 1 1</scale>
              <uri>/home/francisco/robotis_ws/src/ros-bioloid-gp/src/bioloid_gp_description/bioloidgp_social_robot/meshes/right_leg_link_3.STL</uri>
            </mesh>
          </geometry>
          <max_contacts>10</max_contacts>
          <surface>
            <contact>
              <ode/>
            </contact>
            <bounce/>
            <friction>
              <torsional>
                <ode/>
              </torsional>
              <ode/>
            </friction>
          </surface>
        </collision>
        <visual name='right_leg_link_3_visual'>
          <pose frame=''>0 0 0 3.14159 -0 3.14159</pose>
          <geometry>
            <mesh>
              <scale>1 1 1</scale>
              <uri>/home/francisco/robotis_ws/src/ros-bioloid-gp/src/bioloid_gp_description/bioloidgp_social_robot/meshes/right_leg_link_3.STL</uri>
            </mesh>
          </geometry>
        </visual>
        <self_collide>0</self_collide>
        <enable_wind>0</enable_wind>
        <kinematic>0</kinematic>
      </link>
      <joint name='joint_13' type='revolute'>
        <child>right_leg_link_3</child>
        <parent>right_leg_link_2</parent>
        <axis>
          <xyz>-0 1 -0</xyz>
          <limit>
            <lower>-1e+16</lower>
            <upper>1e+16</upper>
          </limit>
          <dynamics>
            <spring_reference>0</spring_reference>
            <spring_stiffness>0</spring_stiffness>
          </dynamics>
          <use_parent_model_frame>1</use_parent_model_frame>
        </axis>
      </joint>
      <link name='right_leg_link_4'>
        <pose frame=''>0.00825 -0.016 -0.30195 0 0 -1.5708</pose>
        <inertial>
          <pose frame=''>-0.013368 0.021128 0.013055 0 -0 0</pose>
          <mass>0.0856772</mass>
          <inertia>
            <ixx>1</ixx>
            <ixy>0</ixy>
            <ixz>0</ixz>
            <iyy>1</iyy>
            <iyz>0</iyz>
            <izz>1</izz>
          </inertia>
        </inertial>
        <collision name='right_leg_link_4_collision'>
          <pose frame=''>0 0 0 0 -0 3.14159</pose>
          <geometry>
            <mesh>
              <scale>1 1 1</scale>
              <uri>/home/francisco/robotis_ws/src/ros-bioloid-gp/src/bioloid_gp_description/bioloidgp_social_robot/meshes/right_leg_link_4.STL</uri>
            </mesh>
          </geometry>
          <max_contacts>10</max_contacts>
          <surface>
            <contact>
              <ode/>
            </contact>
            <bounce/>
            <friction>
              <torsional>
                <ode/>
              </torsional>
              <ode/>
            </friction>
          </surface>
        </collision>
        <visual name='right_leg_link_4_visual'>
          <pose frame=''>0 0 0 0 -0 3.14159</pose>
          <geometry>
            <mesh>
              <scale>1 1 1</scale>
              <uri>/home/francisco/robotis_ws/src/ros-bioloid-gp/src/bioloid_gp_description/bioloidgp_social_robot/meshes/right_leg_link_4.STL</uri>
            </mesh>
          </geometry>
        </visual>
        <self_collide>0</self_collide>
        <enable_wind>0</enable_wind>
        <kinematic>0</kinematic>
      </link>
      <joint name='joint_15' type='revolute'>
        <child>right_leg_link_4</child>
        <parent>right_leg_link_3</parent>
        <axis>
          <xyz>0 -1 -0</xyz>
          <limit>
            <lower>-1e+16</lower>
            <upper>1e+16</upper>
          </limit>
          <dynamics>
            <spring_reference>0</spring_reference>
            <spring_stiffness>0</spring_stiffness>
          </dynamics>
          <use_parent_model_frame>1</use_parent_model_frame>
        </axis>
      </joint>
      <link name='right_leg_link_5'>
        <pose frame=''>0.00825 -0.0298 -0.30205 1.5708 -0 0</pose>
        <inertial>
          <pose frame=''>0.0002 -0.027102 0.005782 0 -0 0</pose>
          <mass>0.0145032</mass>
          <inertia>
            <ixx>1</ixx>
            <ixy>0</ixy>
            <ixz>0</ixz>
            <iyy>1</iyy>
            <iyz>0</iyz>
            <izz>1</izz>
          </inertia>
        </inertial>
        <collision name='right_leg_link_5_collision'>
          <pose frame=''>0 0 0 0 -0 0</pose>
          <geometry>
            <mesh>
              <scale>1 1 1</scale>
              <uri>/home/francisco/robotis_ws/src/ros-bioloid-gp/src/bioloid_gp_description/bioloidgp_social_robot/meshes/right_leg_link_5.STL</uri>
            </mesh>
          </geometry>
          <surface>
            <contact>
              <ode/>
            </contact>
            <friction>
              <ode>
                <mu>0.9</mu>
                <mu2>0.9</mu2>
              </ode>
              <torsional>
                <ode/>
              </torsional>
            </friction>
            <bounce/>
          </surface>
          <max_contacts>10</max_contacts>
        </collision>
        <visual name='right_leg_link_5_visual'>
          <pose frame=''>0 0 0 0 -0 0</pose>
          <geometry>
            <mesh>
              <scale>1 1 1</scale>
              <uri>/home/francisco/robotis_ws/src/ros-bioloid-gp/src/bioloid_gp_description/bioloidgp_social_robot/meshes/right_leg_link_5.STL</uri>
            </mesh>
          </geometry>
          <material>
            <script>
              <uri>__default__</uri>
              <name>__default__</name>
            </script>
          </material>
        </visual>
        <gravity>1</gravity>
        <velocity_decay/>
        <self_collide>0</self_collide>
        <enable_wind>0</enable_wind>
        <kinematic>0</kinematic>
      </link>
      <joint name='joint_17' type='revolute'>
        <child>right_leg_link_5</child>
        <parent>right_leg_link_4</parent>
        <axis>
          <xyz>1 0 -0</xyz>
          <limit>
            <lower>-1e+16</lower>
            <upper>1e+16</upper>
          </limit>
          <dynamics>
            <spring_reference>0</spring_reference>
            <spring_stiffness>0</spring_stiffness>
          </dynamics>
          <use_parent_model_frame>1</use_parent_model_frame>
        </axis>
      </joint>
      <link name='left_arm_link_1'>
        <pose frame=''>0.00875 0.05649 0.00275 3.14159 -0 3.14159</pose>
        <inertial>
          <pose frame=''>-0 -0.009232 0.005179 0 -0 0</pose>
          <mass>0.00402029</mass>
          <inertia>
            <ixx>1</ixx>
            <ixy>0</ixy>
            <ixz>0</ixz>
            <iyy>1</iyy>
            <iyz>0</iyz>
            <izz>1</izz>
          </inertia>
        </inertial>
        <collision name='left_arm_link_1_collision'>
          <pose frame=''>0 0 0 0 -0 3.14159</pose>
          <geometry>
            <mesh>
              <scale>1 1 1</scale>
              <uri>/home/francisco/robotis_ws/src/ros-bioloid-gp/src/bioloid_gp_description/bioloidgp_social_robot/meshes/left_arm_link_1.STL</uri>
            </mesh>
          </geometry>
          <max_contacts>10</max_contacts>
          <surface>
            <contact>
              <ode/>
            </contact>
            <bounce/>
            <friction>
              <torsional>
                <ode/>
              </torsional>
              <ode/>
            </friction>
          </surface>
        </collision>
        <visual name='left_arm_link_1_visual'>
          <pose frame=''>0 0 0 0 -0 3.14159</pose>
          <geometry>
            <mesh>
              <scale>1 1 1</scale>
              <uri>/home/francisco/robotis_ws/src/ros-bioloid-gp/src/bioloid_gp_description/bioloidgp_social_robot/meshes/left_arm_link_1.STL</uri>
            </mesh>
          </geometry>
        </visual>
        <self_collide>0</self_collide>
        <enable_wind>0</enable_wind>
        <kinematic>0</kinematic>
      </link>
      <joint name='joint_2' type='revolute'>
        <child>left_arm_link_1</child>
        <parent>dummy</parent>
        <axis>
          <xyz>0 1 0</xyz>
          <limit>
            <lower>-1e+16</lower>
            <upper>1e+16</upper>
          </limit>
          <dynamics>
            <spring_reference>0</spring_reference>
            <spring_stiffness>0</spring_stiffness>
          </dynamics>
          <use_parent_model_frame>1</use_parent_model_frame>
        </axis>
      </joint>
      <link name='left_arm_link_2'>
        <pose frame=''>0.00875 0.0795 -0.01525 1.5708 0 -1.5708</pose>
        <inertial>
          <pose frame=''>0.000496 -0.035284 0.003118 0 -0 0</pose>
          <mass>0.086643</mass>
          <inertia>
            <ixx>1</ixx>
            <ixy>0</ixy>
            <ixz>0</ixz>
            <iyy>1</iyy>
            <iyz>0</iyz>
            <izz>1</izz>
          </inertia>
        </inertial>
        <collision name='left_arm_link_2_collision'>
          <pose frame=''>0 0 0 3.14159 -0 3.14159</pose>
          <geometry>
            <mesh>
              <scale>1 1 1</scale>
              <uri>/home/francisco/robotis_ws/src/ros-bioloid-gp/src/bioloid_gp_description/bioloidgp_social_robot/meshes/left_arm_link_2.STL</uri>
            </mesh>
          </geometry>
          <max_contacts>10</max_contacts>
          <surface>
            <contact>
              <ode/>
            </contact>
            <bounce/>
            <friction>
              <torsional>
                <ode/>
              </torsional>
              <ode/>
            </friction>
          </surface>
        </collision>
        <visual name='left_arm_link_2_visual'>
          <pose frame=''>0 0 0 3.14159 -0 3.14159</pose>
          <geometry>
            <mesh>
              <scale>1 1 1</scale>
              <uri>/home/francisco/robotis_ws/src/ros-bioloid-gp/src/bioloid_gp_description/bioloidgp_social_robot/meshes/left_arm_link_2.STL</uri>
            </mesh>
          </geometry>
        </visual>
        <self_collide>0</self_collide>
        <enable_wind>0</enable_wind>
        <kinematic>0</kinematic>
      </link>
      <joint name='joint_4' type='revolute'>
        <child>left_arm_link_2</child>
        <parent>left_arm_link_1</parent>
        <axis>
          <xyz>-1 -0 0</xyz>
          <limit>
            <lower>-1e+16</lower>
            <upper>1e+16</upper>
          </limit>
          <dynamics>
            <spring_reference>0</spring_reference>
            <spring_stiffness>0</spring_stiffness>
          </dynamics>
          <use_parent_model_frame>1</use_parent_model_frame>
        </axis>
      </joint>
      <link name='left_arm_link_3'>
        <pose frame=''>0.02695 0.0795 -0.07265 0 -0 1.5708</pose>
        <inertial>
          <pose frame=''>0.0061 0.042343 0.016759 0 -0 0</pose>
          <mass>0.0525573</mass>
          <inertia>
            <ixx>1</ixx>
            <ixy>0</ixy>
            <ixz>0</ixz>
            <iyy>1</iyy>
            <iyz>0</iyz>
            <izz>1</izz>
          </inertia>
        </inertial>
        <collision name='left_arm_link_3_collision'>
          <pose frame=''>0 0 0 3.14159 -0 0</pose>
          <geometry>
            <mesh>
              <scale>1 1 1</scale>
              <uri>/home/francisco/robotis_ws/src/ros-bioloid-gp/src/bioloid_gp_description/bioloidgp_social_robot/meshes/left_arm_link_3.STL</uri>
            </mesh>
          </geometry>
          <max_contacts>10</max_contacts>
          <surface>
            <contact>
              <ode/>
            </contact>
            <bounce/>
            <friction>
              <torsional>
                <ode/>
              </torsional>
              <ode/>
            </friction>
          </surface>
        </collision>
        <visual name='left_arm_link_3_visual'>
          <pose frame=''>0 0 0 3.14159 -0 0</pose>
          <geometry>
            <mesh>
              <scale>1 1 1</scale>
              <uri>/home/francisco/robotis_ws/src/ros-bioloid-gp/src/bioloid_gp_description/bioloidgp_social_robot/meshes/left_arm_link_3.STL</uri>
            </mesh>
          </geometry>
        </visual>
        <self_collide>0</self_collide>
        <enable_wind>0</enable_wind>
        <kinematic>0</kinematic>
      </link>
      <joint name='joint_6' type='revolute'>
        <child>left_arm_link_3</child>
        <parent>left_arm_link_2</parent>
        <axis>
          <xyz>-0 1 0</xyz>
          <limit>
            <lower>-1e+16</lower>
            <upper>1e+16</upper>
          </limit>
          <dynamics>
            <spring_reference>0</spring_reference>
            <spring_stiffness>0</spring_stiffness>
          </dynamics>
          <use_parent_model_frame>1</use_parent_model_frame>
        </axis>
      </joint>
      <link name='left_gripper'>
        <pose frame=''>0.06945 0.102 -0.07265 3.14159 -1.57079 3.14159</pose>
        <inertial>
          <pose frame=''>-0.018 -0.00624 0.036135 3.14159 -0 0</pose>
          <mass>0.00882433</mass>
          <inertia>
            <ixx>1</ixx>
            <ixy>0</ixy>
            <ixz>0</ixz>
            <iyy>1</iyy>
            <iyz>0</iyz>
            <izz>1</izz>
          </inertia>
        </inertial>
        <collision name='left_gripper_collision'>
          <pose frame=''>0 0 0 3.14159 -0 0</pose>
          <geometry>
            <mesh>
              <scale>1 1 1</scale>
              <uri>/home/francisco/robotis_ws/src/ros-bioloid-gp/src/bioloid_gp_description/bioloidgp_social_robot/meshes/left_gripper.STL</uri>
            </mesh>
          </geometry>
          <max_contacts>10</max_contacts>
          <surface>
            <contact>
              <ode/>
            </contact>
            <bounce/>
            <friction>
              <torsional>
                <ode/>
              </torsional>
              <ode/>
            </friction>
          </surface>
        </collision>
        <visual name='left_gripper_visual'>
          <pose frame=''>0 0 0 3.14159 -0 0</pose>
          <geometry>
            <mesh>
              <scale>1 1 1</scale>
              <uri>/home/francisco/robotis_ws/src/ros-bioloid-gp/src/bioloid_gp_description/bioloidgp_social_robot/meshes/left_gripper.STL</uri>
            </mesh>
          </geometry>
        </visual>
        <self_collide>0</self_collide>
        <enable_wind>0</enable_wind>
        <kinematic>0</kinematic>
      </link>
      <joint name='joint_8' type='revolute'>
        <child>left_gripper</child>
        <parent>left_arm_link_3</parent>
        <axis>
          <xyz>0 -0 1</xyz>
          <limit>
            <lower>-1e+16</lower>
            <upper>1e+16</upper>
          </limit>
          <dynamics>
            <spring_reference>0</spring_reference>
            <spring_stiffness>0</spring_stiffness>
          </dynamics>
          <use_parent_model_frame>1</use_parent_model_frame>
        </axis>
      </joint>
      <link name='head_link'>
        <pose frame=''>0.00825 0 0.02205 0 0 -1.57079</pose>
        <inertial>
          <pose frame=''>0 0.00059 -0.022 0 -0 0</pose>
          <mass>0.0131553</mass>
          <inertia>
            <ixx>1</ixx>
            <ixy>0</ixy>
            <ixz>0</ixz>
            <iyy>1</iyy>
            <iyz>0</iyz>
            <izz>1</izz>
          </inertia>
        </inertial>
        <collision name='head_link_collision'>
          <pose frame=''>0 0 0 3.14159 -0 0</pose>
          <geometry>
            <mesh>
              <scale>1 1 1</scale>
              <uri>/home/francisco/robotis_ws/src/ros-bioloid-gp/src/bioloid_gp_description/bioloidgp_social_robot/meshes/head_link.STL</uri>
            </mesh>
          </geometry>
          <max_contacts>10</max_contacts>
          <surface>
            <contact>
              <ode/>
            </contact>
            <bounce/>
            <friction>
              <torsional>
                <ode/>
              </torsional>
              <ode/>
            </friction>
          </surface>
        </collision>
        <visual name='head_link_visual'>
          <pose frame=''>0 0 0 3.14159 -0 0</pose>
          <geometry>
            <mesh>
              <scale>1 1 1</scale>
              <uri>/home/francisco/robotis_ws/src/ros-bioloid-gp/src/bioloid_gp_description/bioloidgp_social_robot/meshes/head_link.STL</uri>
            </mesh>
          </geometry>
        </visual>
        <self_collide>0</self_collide>
        <enable_wind>0</enable_wind>
        <kinematic>0</kinematic>
      </link>
      <joint name='joint_20' type='revolute'>
        <child>head_link</child>
        <parent>dummy</parent>
        <axis>
          <xyz>0 -0 1</xyz>
          <limit>
            <lower>-1e+16</lower>
            <upper>1e+16</upper>
          </limit>
          <dynamics>
            <spring_reference>0</spring_reference>
            <spring_stiffness>0</spring_stiffness>
          </dynamics>
          <use_parent_model_frame>1</use_parent_model_frame>
        </axis>
      </joint>
      <link name='camera'>
        <pose frame=''>0.00825 -0 0.07575 1.5708 -1.57079 3.14159</pose>
        <inertial>
          <pose frame=''>-4.4e-05 -0.036891 0.000351 0 -0 0</pose>
          <mass>0.0951615</mass>
          <inertia>
            <ixx>1</ixx>
            <ixy>0</ixy>
            <ixz>0</ixz>
            <iyy>1</iyy>
            <iyz>0</iyz>
            <izz>1</izz>
          </inertia>
        </inertial>
        <collision name='camera_collision'>
          <pose frame=''>0 0 0 3.14159 -0 0</pose>
          <geometry>
            <mesh>
              <scale>1 1 1</scale>
              <uri>/home/francisco/robotis_ws/src/ros-bioloid-gp/src/bioloid_gp_description/bioloidgp_social_robot/meshes/camera.STL</uri>
            </mesh>
          </geometry>
          <max_contacts>10</max_contacts>
          <surface>
            <contact>
              <ode/>
            </contact>
            <bounce/>
            <friction>
              <torsional>
                <ode/>
              </torsional>
              <ode/>
            </friction>
          </surface>
        </collision>
        <visual name='camera_visual'>
          <pose frame=''>0 0 0 3.14159 -0 0</pose>
          <geometry>
            <mesh>
              <scale>1 1 1</scale>
              <uri>/home/francisco/robotis_ws/src/ros-bioloid-gp/src/bioloid_gp_description/bioloidgp_social_robot/meshes/camera.STL</uri>
            </mesh>
          </geometry>
        </visual>
        <self_collide>0</self_collide>
        <enable_wind>0</enable_wind>
        <kinematic>0</kinematic>
      </link>
      <joint name='joint_21' type='revolute'>
        <child>camera</child>
        <parent>head_link</parent>
        <axis>
          <xyz>-4e-06 1 -0</xyz>
          <limit>
            <lower>-1e+16</lower>
            <upper>1e+16</upper>
          </limit>
          <dynamics>
            <spring_reference>0</spring_reference>
            <spring_stiffness>0</spring_stiffness>
          </dynamics>
          <use_parent_model_frame>1</use_parent_model_frame>
        </axis>
      </joint>
      <static>0</static>
      <plugin name='gazebo_ros_control' filename='libgazebo_ros_control.so'>
        <robotNamespace>/bioloidgp_social_robot</robotNamespace>
      </plugin>
      <pose frame=''>0 0 0.33 0 -0 0</pose>
    </model>
    <model name='wood_cube_10cm'>
      <link name='link'>
        <pose frame=''>0 0 0.05 0 -0 0</pose>
        <inertial>
          <mass>0.5167</mass>
          <inertia>
            <ixx>0.000861167</ixx>
            <ixy>0</ixy>
            <ixz>0</ixz>
            <iyy>0.000861167</iyy>
            <iyz>0</iyz>
            <izz>0.000861167</izz>
          </inertia>
        </inertial>
        <collision name='collision'>
          <geometry>
            <box>
              <size>0.1 0.1 0.1</size>
            </box>
          </geometry>
          <surface>
            <contact>
              <poissons_ratio>0.347</poissons_ratio>
              <elastic_modulus>8.8e+09</elastic_modulus>
              <ode>
                <kp>100000</kp>
                <kd>100</kd>
                <max_vel>100</max_vel>
                <min_depth>0.001</min_depth>
              </ode>
            </contact>
            <friction>
              <torsional>
                <coefficient>1</coefficient>
                <use_patch_radius>0</use_patch_radius>
                <surface_radius>0.01</surface_radius>
                <ode/>
              </torsional>
              <ode/>
            </friction>
            <bounce/>
          </surface>
          <max_contacts>10</max_contacts>
        </collision>
        <visual name='visual'>
          <geometry>
            <box>
              <size>0.1 0.1 0.1</size>
            </box>
          </geometry>
          <material>
            <script>
              <uri>file://media/materials/scripts/gazebo.material</uri>
              <name>Gazebo/Wood</name>
            </script>
          </material>
        </visual>
        <self_collide>0</self_collide>
        <enable_wind>0</enable_wind>
        <kinematic>0</kinematic>
      </link>
      <pose frame=''>0.007745 0.463064 0 0 -0 0</pose>
    </model>
    <model name='frc2016_ramparts'>
      <static>1</static>
      <link name='link'>
        <visual name='platform'>
          <pose frame=''>0 0 0.06967 0 -0 0</pose>
          <geometry>
            <box>
              <size>1.27 0.5969 0.003175</size>
            </box>
          </geometry>
        </visual>
        <collision name='platform'>
          <pose frame=''>0 0 0.06967 0 -0 0</pose>
          <geometry>
            <box>
              <size>1.27 0.5969 0.003175</size>
            </box>
          </geometry>
          <max_contacts>10</max_contacts>
          <surface>
            <contact>
              <ode/>
            </contact>
            <bounce/>
            <friction>
              <torsional>
                <ode/>
              </torsional>
              <ode/>
            </friction>
          </surface>
        </collision>
        <visual name='ramp1'>
          <pose frame=''>0.30472 0.00588 0.1109 -0.13 0 0</pose>
          <geometry>
            <box>
              <size>0.60957 0.588891 0.00462</size>
            </box>
          </geometry>
          <material>
            <ambient>0.2 0.2 0.2 1</ambient>
            <diffuse>0.2 0.2 0.2 1</diffuse>
          </material>
        </visual>
        <collision name='ramp1'>
          <pose frame=''>0.30472 0.00588 0.1109 -0.13 0 0</pose>
          <geometry>
            <box>
              <size>0.60957 0.588891 0.00462</size>
            </box>
          </geometry>
          <max_contacts>10</max_contacts>
          <surface>
            <contact>
              <ode/>
            </contact>
            <bounce/>
            <friction>
              <torsional>
                <ode/>
              </torsional>
              <ode/>
            </friction>
          </surface>
        </collision>
        <visual name='up1'>
          <pose frame=''>0.30472 -0.28806 0.11072 0 -0 0</pose>
          <geometry>
            <box>
              <size>0.60957 0.00462 0.07872</size>
            </box>
          </geometry>
          <material>
            <ambient>0.2 0.2 0.2 1</ambient>
            <diffuse>0.2 0.2 0.2 1</diffuse>
          </material>
        </visual>
        <collision name='up1'>
          <pose frame=''>0.30472 -0.28806 0.11072 0 -0 0</pose>
          <geometry>
            <box>
              <size>0.60957 0.00462 0.07872</size>
            </box>
          </geometry>
          <max_contacts>10</max_contacts>
          <surface>
            <contact>
              <ode/>
            </contact>
            <bounce/>
            <friction>
              <torsional>
                <ode/>
              </torsional>
              <ode/>
            </friction>
          </surface>
        </collision>
        <visual name='ramp2'>
          <pose frame=''>-0.30472 -0.00619 0.1109 0.13 -0 0</pose>
          <geometry>
            <box>
              <size>0.60957 0.588891 0.00462</size>
            </box>
          </geometry>
          <material>
            <ambient>0.2 0.2 0.2 1</ambient>
            <diffuse>0.2 0.2 0.2 1</diffuse>
          </material>
        </visual>
        <collision name='ramp2'>
          <pose frame=''>-0.30472 -0.00619 0.1109 0.13 -0 0</pose>
          <geometry>
            <box>
              <size>0.60957 0.588891 0.00462</size>
            </box>
          </geometry>
          <max_contacts>10</max_contacts>
          <surface>
            <contact>
              <ode/>
            </contact>
            <bounce/>
            <friction>
              <torsional>
                <ode/>
              </torsional>
              <ode/>
            </friction>
          </surface>
        </collision>
        <visual name='up2'>
          <pose frame=''>-0.30472 0.28806 0.11072 0 -0 0</pose>
          <geometry>
            <box>
              <size>0.60957 0.00462 0.07872</size>
            </box>
          </geometry>
          <material>
            <ambient>0.2 0.2 0.2 1</ambient>
            <diffuse>0.2 0.2 0.2 1</diffuse>
          </material>
        </visual>
        <collision name='up2'>
          <pose frame=''>-0.30472 0.28806 0.11072 0 -0 0</pose>
          <geometry>
            <box>
              <size>0.60957 0.00462 0.07872</size>
            </box>
          </geometry>
          <max_contacts>10</max_contacts>
          <surface>
            <contact>
              <ode/>
            </contact>
            <bounce/>
            <friction>
              <torsional>
                <ode/>
              </torsional>
              <ode/>
            </friction>
          </surface>
        </collision>
        <self_collide>0</self_collide>
        <enable_wind>0</enable_wind>
        <kinematic>0</kinematic>
      </link>
      <pose frame=''>-0.089837 1.15791 0 0 -0 0</pose>
    </model>
    <model name='frc2016_rockwall'>
      <static>1</static>
      <link name='link'>
        <inertial>
          <mass>10</mass>
          <pose frame=''>0 0 0.08974 0 -0 0</pose>
          <inertia>
            <ixx>0.327091</ixx>
            <ixy>0</ixy>
            <ixz>0</ixz>
            <iyy>1.37417</iyy>
            <iyz>0</iyz>
            <izz>1.64109</izz>
          </inertia>
        </inertial>
        <visual name='platform'>
          <pose frame=''>0 0 0.06432 0 -0 0</pose>
          <geometry>
            <box>
              <size>1.27 0.5969 0.003175</size>
            </box>
          </geometry>
        </visual>
        <collision name='platform'>
          <pose frame=''>0 0 0.06432 0 -0 0</pose>
          <geometry>
            <box>
              <size>1.27 0.5969 0.003175</size>
            </box>
          </geometry>
          <max_contacts>10</max_contacts>
          <surface>
            <contact>
              <ode/>
            </contact>
            <bounce/>
            <friction>
              <torsional>
                <ode/>
              </torsional>
              <ode/>
            </friction>
          </surface>
        </collision>
        <visual name='up1'>
          <pose frame=''>0 0.05166 0.12537 0 -0 0</pose>
          <geometry>
            <box>
              <size>1.27 0.00462 0.11892</size>
            </box>
          </geometry>
          <material>
            <ambient>0.46 0.46 0.46 1</ambient>
            <diffuse>0.46 0.46 0.46 1</diffuse>
          </material>
        </visual>
        <collision name='up1'>
          <pose frame=''>0 0.05166 0.12537 0 -0 0</pose>
          <geometry>
            <box>
              <size>1.27 0.00462 0.11892</size>
            </box>
          </geometry>
          <max_contacts>10</max_contacts>
          <surface>
            <contact>
              <ode/>
            </contact>
            <bounce/>
            <friction>
              <torsional>
                <ode/>
              </torsional>
              <ode/>
            </friction>
          </surface>
        </collision>
        <visual name='up2'>
          <pose frame=''>0 -0.05801 0.12537 0 -0 0</pose>
          <geometry>
            <box>
              <size>1.27 0.00462 0.11892</size>
            </box>
          </geometry>
          <material>
            <ambient>0.46 0.46 0.46 1</ambient>
            <diffuse>0.46 0.46 0.46 1</diffuse>
          </material>
        </visual>
        <collision name='up2'>
          <pose frame=''>0 -0.05801 0.12537 0 -0 0</pose>
          <geometry>
            <box>
              <size>1.27 0.00462 0.11892</size>
            </box>
          </geometry>
          <max_contacts>10</max_contacts>
          <surface>
            <contact>
              <ode/>
            </contact>
            <bounce/>
            <friction>
              <torsional>
                <ode/>
              </torsional>
              <ode/>
            </friction>
          </surface>
        </collision>
        <visual name='top'>
          <pose frame=''>0 -0.00249 0.18252 0 -0 0</pose>
          <geometry>
            <box>
              <size>1.27 0.1143 0.00462</size>
            </box>
          </geometry>
          <material>
            <ambient>0.46 0.46 0.46 1</ambient>
            <diffuse>0.46 0.46 0.46 1</diffuse>
          </material>
        </visual>
        <collision name='top'>
          <pose frame=''>0 -0.00249 0.18252 0 -0 0</pose>
          <geometry>
            <box>
              <size>1.27 0.1143 0.00462</size>
            </box>
          </geometry>
          <max_contacts>10</max_contacts>
          <surface>
            <contact>
              <ode/>
            </contact>
            <bounce/>
            <friction>
              <torsional>
                <ode/>
              </torsional>
              <ode/>
            </friction>
          </surface>
        </collision>
        <self_collide>0</self_collide>
        <enable_wind>0</enable_wind>
        <kinematic>0</kinematic>
      </link>
      <pose frame=''>-1.5516 0.545406 0 0 -0 0</pose>
    </model>
    <state world_name='default'>
      <sim_time>687 366000000</sim_time>
      <real_time>692 365081270</real_time>
      <wall_time>1585139437 578265410</wall_time>
      <iterations>687366</iterations>
      <model name='bioloidgp_social_robot'>
        <pose frame=''>0.00089 0.000583 0.334013 0.000413 0.000833 -0.008754</pose>
        <scale>1 1 1</scale>
        <link name='camera'>
          <pose frame=''>0.009203 0.000479 0.40975 -1.10707 -1.56987 -0.47248</pose>
          <velocity>0.002352 0.001299 -0.002307 -0.00318 0.005717 -1.4e-05</velocity>
          <acceleration>-0.005803 0.004936 -2.52167 -0.019284 -0.011128 3e-06</acceleration>
          <wrench>-0.000552 0.00047 -0.239966 0 -0 0</wrench>
        </link>
        <link name='dummy'>
          <pose frame=''>0.00089 0.000583 0.334013 0.000413 0.000833 -0.008754</pose>
          <velocity>0.001919 0.001058 -0.002356 -0.003181 0.005717 -1.4e-05</velocity>
          <acceleration>-0.005052 0.003885 -2.26823 -0.020783 -0.011181 2e-06</acceleration>
          <wrench>-0.001207 0.000928 -0.542038 0 -0 0</wrench>
        </link>
        <link name='head_link'>
          <pose frame=''>0.009158 0.000502 0.356056 -0.000833 0.000413 -1.57954</pose>
          <velocity>0.002045 0.001128 -0.002411 -0.003181 0.005717 -1.4e-05</velocity>
          <acceleration>-0.005188 0.004223 -2.24381 -0.019925 -0.011094 2e-06</acceleration>
          <wrench>-6.8e-05 5.6e-05 -0.029518 0 -0 0</wrench>
        </link>
        <link name='left_arm_link_1'>
          <pose frame=''>0.010137 0.056993 0.336755 3.14112 0.499167 3.13261</pose>
          <velocity>0.001935 0.001067 -0.00144 -0.003179 0.00572 -1.4e-05</velocity>
          <acceleration>-0.005282 0.003119 -1.46978 -0.015972 -0.011448 4e-06</acceleration>
          <wrench>-2.1e-05 1.3e-05 -0.005909 0 -0 0</wrench>
        </link>
        <link name='left_arm_link_2'>
          <pose frame=''>0.018954 0.079933 0.320967 2.12683 0.434869 -1.32372</pose>
          <velocity>0.001845 0.001016 -0.001886 -0.003179 0.00572 -1.4e-05</velocity>
          <acceleration>-0.004773 0.002718 -1.71975 -0.01568 -0.011399 -1.9e-05</acceleration>
          <wrench>-0.000414 0.000235 -0.149004 0 -0 0</wrench>
        </link>
        <link name='left_arm_link_3'>
          <pose frame=''>0.059287 0.107115 0.285464 -1.05603 -0.434864 1.81788</pose>
          <velocity>0.001643 0.000903 -0.002214 -0.003179 0.00572 -1.4e-05</velocity>
          <acceleration>-0.004428 0.002257 -1.7282 -0.015646 -0.011444 -2.2e-05</acceleration>
          <wrench>-0.000233 0.000119 -0.09083 0 -0 0</wrench>
        </link>
        <link name='left_gripper'>
          <pose frame=''>0.078396 0.116907 0.328493 -3.13183 -0.462851 -2.66058</pose>
          <velocity>0.001889 0.001039 -0.002365 -0.003179 0.00572 -1.4e-05</velocity>
          <acceleration>-0.00473 0.002723 -1.73524 -0.015875 -0.011444 -3.9e-05</acceleration>
          <wrench>-4.2e-05 2.4e-05 -0.015312 0 -0 0</wrench>
        </link>
        <link name='left_leg_link_1'>
          <pose frame=''>0.009188 0.016557 0.223293 1.56997 0.000413 -1.57956</pose>
          <velocity>0.001287 0.000706 -0.003466 -0.003181 0.005721 -1.4e-05</velocity>
          <acceleration>-0.004061 0.00399 -1.99066 -0.022691 -0.007384 1e-06</acceleration>
          <wrench>-0.000189 0.000186 -0.092654 0 -0 0</wrench>
        </link>
        <link name='left_leg_link_2'>
          <pose frame=''>0.009153 0.016574 0.181495 1.57163 -0.000413 1.56204</pose>
          <velocity>0.001048 0.000573 -0.003802 -0.00318 0.005721 -1.4e-05</velocity>
          <acceleration>-0.002984 0.001969 -2.63652 -0.020122 -0.003602 1e-06</acceleration>
          <wrench>-0.000261 0.000172 -0.230421 0 -0 0</wrench>
        </link>
        <link name='left_leg_link_3'>
          <pose frame=''>-0.005408 0.016733 0.107131 -1.57163 0.000413 -1.57956</pose>
          <velocity>0.000627 0.000334 -0.013027 -0.003178 0.005721 -1.4e-05</velocity>
          <acceleration>0.006898 -0.002989 -22.1372 -0.017686 -0.001165 1e-06</acceleration>
          <wrench>4.8e-05 -2.1e-05 -0.155289 0 -0 0</wrench>
        </link>
        <link name='left_leg_link_4'>
          <pose frame=''>0.00903 0.016637 0.032115 0.000833 -0.000413 1.56204</pose>
          <velocity>0.000197 9.6e-05 -0.01096 -0.003177 0.005721 -1.4e-05</velocity>
          <acceleration>0.005166 -0.002825 -17.5369 -0.015599 0.00584 0</acceleration>
          <wrench>0.000443 -0.000242 -1.50251 0 -0 0</wrench>
        </link>
        <link name='left_leg_link_5'>
          <pose frame=''>0.00915 0.030437 0.032037 1.57121 0.000833 -0.008754</pose>
          <velocity>0.000205 9.2e-05 -0.015023 -0.003178 0.005723 -1.4e-05</velocity>
          <acceleration>0.021487 -0.009362 -25.4936 -0.01412 0.00992 -0</acceleration>
          <wrench>0.000312 -0.000136 -0.369738 0 -0 0</wrench>
        </link>
        <link name='right_arm_link_1'>
          <pose frame=''>0.009148 -0.055983 0.33671 -3.14112 -0.499167 -0.00898</pose>
          <velocity>0.001933 0.001066 -0.001182 -0.003181 0.005718 -1.4e-05</velocity>
          <acceleration>-0.005271 0.003156 -1.62047 -0.020447 -0.011232 2e-06</acceleration>
          <wrench>-2.1e-05 1.3e-05 -0.006515 0 -0 0</wrench>
        </link>
        <link name='right_arm_link_2'>
          <pose frame=''>0.017562 -0.079061 0.320903 2.1266 -0.434065 -1.83529</pose>
          <velocity>0.001843 0.001016 -0.001462 -0.003181 0.005717 -1.4e-05</velocity>
          <acceleration>-0.004784 0.002616 -1.81097 -0.020221 -0.011197 -1.3e-05</acceleration>
          <wrench>-0.000415 0.000227 -0.156907 0 -0 0</wrench>
        </link>
        <link name='right_arm_link_3'>
          <pose frame=''>0.057413 -0.106915 0.285377 -2.08579 -0.434064 -1.83529</pose>
          <velocity>0.001639 0.000902 -0.001611 -0.003181 0.005718 -1.4e-05</velocity>
          <acceleration>-0.004222 0.001615 -1.81646 -0.020185 -0.011207 -1.1e-05</acceleration>
          <wrench>-0.000222 8.5e-05 -0.095468 0 -0 0</wrench>
        </link>
        <link name='right_gripper'>
          <pose frame=''>0.076347 -0.117076 0.328398 -0.01059 -0.463239 2.64344</pose>
          <velocity>0.001885 0.001039 -0.001697 -0.003181 0.005718 -1.4e-05</velocity>
          <acceleration>-0.00565 0.004221 -1.82216 -0.020357 -0.011238 -1.7e-05</acceleration>
          <wrench>-5e-05 3.7e-05 -0.016079 0 -0 0</wrench>
        </link>
        <link name='right_leg_link_1'>
          <pose frame=''>0.008908 -0.015442 0.223274 1.56997 0.000413 -1.57956</pose>
          <velocity>0.001282 0.000708 0.002607 -0.003184 0.005716 -1.4e-05</velocity>
          <acceleration>-0.010664 0.006627 11.4804 -0.026297 -0.024535 2e-06</acceleration>
          <wrench>-0.000496 0.000308 0.534349 0 -0 0</wrench>
        </link>
        <link name='right_leg_link_2'>
          <pose frame=''>0.008873 -0.015424 0.181477 1.56997 0.000413 -1.57956</pose>
          <velocity>0.001042 0.000575 0.002799 -0.003184 0.005713 -1.4e-05</velocity>
          <acceleration>-0.009175 0.004719 12.2054 -0.029961 -0.028114 2e-06</acceleration>
          <wrench>-0.000802 0.000412 1.0667 0 -0 0</wrench>
        </link>
        <link name='right_leg_link_3'>
          <pose frame=''>-0.005688 -0.015266 0.107154 -1.56997 -0.000413 1.56204</pose>
          <velocity>0.000609 0.000344 0.009331 -0.003184 0.005706 -1.4e-05</velocity>
          <acceleration>-0.017997 0.010942 33.2682 -0.034099 -0.035663 4e-06</acceleration>
          <wrench>-0.000126 7.7e-05 0.233372 0 -0 0</wrench>
        </link>
        <link name='right_leg_link_4'>
          <pose frame=''>0.008749 -0.015362 0.032128 -0.000833 0.000413 -1.57956</pose>
          <velocity>0.000184 0.000103 0.00769 -0.003183 0.005705 -1.4e-05</velocity>
          <acceleration>-0.015376 0.008454 28.4177 -0.038286 -0.035728 1e-06</acceleration>
          <wrench>-0.001317 0.000724 2.43474 0 -0 0</wrench>
        </link>
        <link name='right_leg_link_5'>
          <pose frame=''>0.008628 -0.029161 0.032056 1.57121 0.000833 -0.008754</pose>
          <velocity>0.000183 0.000102 0.010185 -0.003182 0.005705 -1.4e-05</velocity>
          <acceleration>-0.02362 0.013909 37.5851 -0.037392 -0.039973 5e-06</acceleration>
          <wrench>-0.000343 0.000202 0.545104 0 -0 0</wrench>
        </link>
        <link name='torso_Link'>
          <pose frame=''>0.009092 0.000535 0.276786 1.57163 -0.000413 1.56204</pose>
          <velocity>0.001592 0.000876 -0.00331 -0.003181 0.005719 -1.4e-05</velocity>
          <acceleration>-0.004792 0.004803 -1.85076 -0.025209 -0.011433 0</acceleration>
          <wrench>-7.2e-05 7.2e-05 -0.027818 0 -0 0</wrench>
        </link>
      </model>
      <model name='frc2016_ramparts'>
        <pose frame=''>-0.089837 1.15791 0 0 -0 0</pose>
        <scale>1 1 1</scale>
        <link name='link'>
          <pose frame=''>-0.089837 1.15791 0 0 -0 0</pose>
          <velocity>0 0 0 0 -0 0</velocity>
          <acceleration>0 0 0 0 -0 0</acceleration>
          <wrench>0 0 0 0 -0 0</wrench>
        </link>
      </model>
      <model name='frc2016_rockwall'>
        <pose frame=''>-1.5516 0.545406 0 0 -0 0</pose>
        <scale>1 1 1</scale>
        <link name='link'>
          <pose frame=''>-1.5516 0.545406 0 0 -0 0</pose>
          <velocity>0 0 0 0 -0 0</velocity>
          <acceleration>0 0 0 0 -0 0</acceleration>
          <wrench>0 0 0 0 -0 0</wrench>
        </link>
      </model>
      <model name='ground_plane'>
        <pose frame=''>0 0 0 0 -0 0</pose>
        <scale>1 1 1</scale>
        <link name='link'>
          <pose frame=''>0 0 0 0 -0 0</pose>
          <velocity>0 0 0 0 -0 0</velocity>
          <acceleration>0 0 0 0 -0 0</acceleration>
          <wrench>0 0 0 0 -0 0</wrench>
        </link>
      </model>
      <model name='wood_cube_10cm'>
        <pose frame=''>0.007745 0.463064 -0.001013 0 -0 0</pose>
        <scale>1 1 1</scale>
        <link name='link'>
          <pose frame=''>0.007745 0.463064 0.048987 0 -0 0</pose>
          <velocity>0 0 0 0 -0 0</velocity>
          <acceleration>-0 -0 0 0 -0 0</acceleration>
          <wrench>-0 -0 0 0 -0 0</wrench>
        </link>
      </model>
      <light name='sun'>
        <pose frame=''>0 0 10 0 -0 0</pose>
      </light>
    </state>
    <gui fullscreen='0'>
      <camera name='user_camera'>
        <pose frame=''>3.40034 -0.207124 2.23528 0 0.415643 2.81216</pose>
        <view_controller>orbit</view_controller>
        <projection_type>perspective</projection_type>
      </camera>
    </gui>
  </world>
</sdf>
