<sdf version='1.6'>
  <world name='default'>
    <light name='sun' type='directional'>
      <cast_shadows>1</cast_shadows>
      <pose frame=''>0 0 10 0 -0 0</pose>
      <diffuse>0.8 0.8 0.8 1</diffuse>
      <specular>0.2 0.2 0.2 1</specular>
      <attenuation>
        <range>1000</range>
        <constant>0.9</constant>
        <linear>0.01</linear>
        <quadratic>0.001</quadratic>
      </attenuation>
      <direction>-0.5 0.1 -0.9</direction>
    </light>
    <model name='ground_plane'>
      <static>1</static>
      <link name='link'>
        <collision name='collision'>
          <geometry>
            <plane>
              <normal>0 0 1</normal>
              <size>100 100</size>
            </plane>
          </geometry>
          <surface>
            <contact>
              <collide_bitmask>65535</collide_bitmask>
              <ode/>
            </contact>
            <friction>
              <ode>
                <mu>100</mu>
                <mu2>50</mu2>
              </ode>
              <torsional>
                <ode/>
              </torsional>
            </friction>
            <bounce/>
          </surface>
          <max_contacts>10</max_contacts>
        </collision>
        <visual name='visual'>
          <cast_shadows>0</cast_shadows>
          <geometry>
            <plane>
              <normal>0 0 1</normal>
              <size>100 100</size>
            </plane>
          </geometry>
          <material>
            <script>
              <uri>file://media/materials/scripts/gazebo.material</uri>
              <name>Gazebo/Grey</name>
            </script>
          </material>
        </visual>
        <self_collide>0</self_collide>
        <enable_wind>0</enable_wind>
        <kinematic>0</kinematic>
      </link>
    </model>
    <gravity>0 0 -9.8</gravity>
    <magnetic_field>6e-06 2.3e-05 -4.2e-05</magnetic_field>
    <atmosphere type='adiabatic'/>
    <physics name='default_physics' default='0' type='ode'>
      <max_step_size>0.001</max_step_size>
      <real_time_factor>1</real_time_factor>
      <real_time_update_rate>1000</real_time_update_rate>
    </physics>
    <scene>
      <ambient>0.4 0.4 0.4 1</ambient>
      <background>0.7 0.7 0.7 1</background>
      <shadows>1</shadows>
    </scene>
    <audio>
      <device>default</device>
    </audio>
    <wind/>
    <spherical_coordinates>
      <surface_model>EARTH_WGS84</surface_model>
      <latitude_deg>0</latitude_deg>
      <longitude_deg>0</longitude_deg>
      <elevation>0</elevation>
      <heading_deg>0</heading_deg>
    </spherical_coordinates>
    <model name='bioloidgp_social_robot'>
      <link name='dummy'>
        <pose frame=''>0 0 0 0 -0 0</pose>
        <inertial>
          <pose frame=''>-0.000118 -0 -0.010051 0 -0 0</pose>
          <mass>0.23897</mass>
          <inertia>
            <ixx>0.00013318</ixx>
            <ixy>1.3505e-10</ixy>
            <ixz>-6.4063e-06</ixz>
            <iyy>0.00010393</iyy>
            <iyz>-2.1172e-10</iyz>
            <izz>0.00013952</izz>
          </inertia>
        </inertial>
        <collision name='dummy_fixed_joint_lump__base_link_collision'>
          <pose frame=''>0 0 0 0 -0 0</pose>
          <geometry>
            <mesh>
              <scale>1 1 1</scale>
              <uri>/home/francisco/robotis_ws/src/ros-bioloid-gp/bioloid_gp_description/bioloidgp_social_robot/meshes/base_link.STL</uri>
            </mesh>
          </geometry>
          <max_contacts>10</max_contacts>
          <surface>
            <contact>
              <ode/>
            </contact>
            <bounce/>
            <friction>
              <torsional>
                <ode/>
              </torsional>
              <ode/>
            </friction>
          </surface>
        </collision>
        <visual name='dummy_fixed_joint_lump__base_link_visual'>
          <pose frame=''>0 0 0 0 -0 0</pose>
          <geometry>
            <mesh>
              <scale>1 1 1</scale>
              <uri>/home/francisco/robotis_ws/src/ros-bioloid-gp/bioloid_gp_description/bioloidgp_social_robot/meshes/base_link.STL</uri>
            </mesh>
          </geometry>
        </visual>
        <visual name='dummy_fixed_joint_lump__imu_link_visual_1'>
          <pose frame=''>0.00825 0 -0.035 0 -0 0</pose>
          <geometry>
            <box>
              <size>0.016 0.026 0.005</size>
            </box>
          </geometry>
        </visual>
        <self_collide>0</self_collide>
        <enable_wind>0</enable_wind>
        <kinematic>0</kinematic>
      </link>
      <link name='right_arm_link_1'>
        <pose frame=''>0.00875 -0.05649 0.00275 3.14159 -0 0</pose>
        <inertial>
          <pose frame=''>-0 -0.009232 0.005179 0 -0 0</pose>
          <mass>0.00402029</mass>
          <inertia>
            <ixx>8.53462e-07</ixx>
            <ixy>1.70481e-12</ixy>
            <ixz>-1.05162e-12</ixz>
            <iyy>1.7713e-06</iyy>
            <iyz>2.51193e-07</iyz>
            <izz>1.69099e-06</izz>
          </inertia>
        </inertial>
        <collision name='right_arm_link_1_collision'>
          <pose frame=''>0 0 0 0 -0 3.14159</pose>
          <geometry>
            <mesh>
              <scale>1 1 1</scale>
              <uri>/home/francisco/robotis_ws/src/ros-bioloid-gp/bioloid_gp_description/bioloidgp_social_robot/meshes/right_arm_link_1.STL</uri>
            </mesh>
          </geometry>
          <max_contacts>10</max_contacts>
          <surface>
            <contact>
              <ode/>
            </contact>
            <bounce/>
            <friction>
              <torsional>
                <ode/>
              </torsional>
              <ode/>
            </friction>
          </surface>
        </collision>
        <visual name='right_arm_link_1_visual'>
          <pose frame=''>0 0 0 0 -0 3.14159</pose>
          <geometry>
            <mesh>
              <scale>1 1 1</scale>
              <uri>/home/francisco/robotis_ws/src/ros-bioloid-gp/bioloid_gp_description/bioloidgp_social_robot/meshes/right_arm_link_1.STL</uri>
            </mesh>
          </geometry>
        </visual>
        <self_collide>0</self_collide>
        <enable_wind>0</enable_wind>
        <kinematic>0</kinematic>
      </link>
      <joint name='joint_1' type='revolute'>
        <child>right_arm_link_1</child>
        <parent>dummy</parent>
        <axis>
          <xyz>0 -1 0</xyz>
          <limit>
            <lower>-1e+16</lower>
            <upper>1e+16</upper>
          </limit>
          <dynamics>
            <spring_reference>0</spring_reference>
            <spring_stiffness>0</spring_stiffness>
          </dynamics>
          <use_parent_model_frame>1</use_parent_model_frame>
        </axis>
      </joint>
      <link name='right_arm_link_2'>
        <pose frame=''>0.00875 -0.0795 -0.01525 1.5708 0 -1.5708</pose>
        <inertial>
          <pose frame=''>-0.000528 -0.035252 0.003118 0 -0 0</pose>
          <mass>0.086643</mass>
          <inertia>
            <ixx>2.18653e-05</ixx>
            <ixy>-8.94831e-09</ixy>
            <ixz>-1.89459e-07</ixz>
            <iyy>1.84666e-05</iyy>
            <iyz>2.01343e-07</iyz>
            <izz>1.66636e-05</izz>
          </inertia>
        </inertial>
        <collision name='right_arm_link_2_collision'>
          <pose frame=''>0 0 0 3.14159 -0 3.14159</pose>
          <geometry>
            <mesh>
              <scale>1 1 1</scale>
              <uri>/home/francisco/robotis_ws/src/ros-bioloid-gp/bioloid_gp_description/bioloidgp_social_robot/meshes/right_arm_link_2.STL</uri>
            </mesh>
          </geometry>
          <max_contacts>10</max_contacts>
          <surface>
            <contact>
              <ode/>
            </contact>
            <bounce/>
            <friction>
              <torsional>
                <ode/>
              </torsional>
              <ode/>
            </friction>
          </surface>
        </collision>
        <visual name='right_arm_link_2_visual'>
          <pose frame=''>0 0 0 3.14159 -0 3.14159</pose>
          <geometry>
            <mesh>
              <scale>1 1 1</scale>
              <uri>/home/francisco/robotis_ws/src/ros-bioloid-gp/bioloid_gp_description/bioloidgp_social_robot/meshes/right_arm_link_2.STL</uri>
            </mesh>
          </geometry>
        </visual>
        <self_collide>0</self_collide>
        <enable_wind>0</enable_wind>
        <kinematic>0</kinematic>
      </link>
      <joint name='joint_3' type='revolute'>
        <child>right_arm_link_2</child>
        <parent>right_arm_link_1</parent>
        <axis>
          <xyz>-1 0 0</xyz>
          <limit>
            <lower>-1e+16</lower>
            <upper>1e+16</upper>
          </limit>
          <dynamics>
            <spring_reference>0</spring_reference>
            <spring_stiffness>0</spring_stiffness>
          </dynamics>
          <use_parent_model_frame>1</use_parent_model_frame>
        </axis>
      </joint>
      <link name='right_arm_link_3'>
        <pose frame=''>0.02695 -0.0795 -0.07265 3.14159 -0 -1.5708</pose>
        <inertial>
          <pose frame=''>-0.006099 0.042395 0.016759 0 -0 0</pose>
          <mass>0.0525573</mass>
          <inertia>
            <ixx>1.07464e-05</ixx>
            <ixy>-2.3752e-08</ixy>
            <ixz>1.90926e-07</ixz>
            <iyy>1.44872e-05</iyy>
            <iyz>-2.49726e-07</iyz>
            <izz>1.4391e-05</izz>
          </inertia>
        </inertial>
        <collision name='right_arm_link_3_collision'>
          <pose frame=''>0 0 0 0 -0 3.14159</pose>
          <geometry>
            <mesh>
              <scale>1 1 1</scale>
              <uri>/home/francisco/robotis_ws/src/ros-bioloid-gp/bioloid_gp_description/bioloidgp_social_robot/meshes/right_arm_link_3.STL</uri>
            </mesh>
          </geometry>
          <max_contacts>10</max_contacts>
          <surface>
            <contact>
              <ode/>
            </contact>
            <bounce/>
            <friction>
              <torsional>
                <ode/>
              </torsional>
              <ode/>
            </friction>
          </surface>
        </collision>
        <visual name='right_arm_link_3_visual'>
          <pose frame=''>0 0 0 0 -0 3.14159</pose>
          <geometry>
            <mesh>
              <scale>1 1 1</scale>
              <uri>/home/francisco/robotis_ws/src/ros-bioloid-gp/bioloid_gp_description/bioloidgp_social_robot/meshes/right_arm_link_3.STL</uri>
            </mesh>
          </geometry>
        </visual>
        <self_collide>0</self_collide>
        <enable_wind>0</enable_wind>
        <kinematic>0</kinematic>
      </link>
      <joint name='joint_5' type='revolute'>
        <child>right_arm_link_3</child>
        <parent>right_arm_link_2</parent>
        <axis>
          <xyz>-0 -1 0</xyz>
          <limit>
            <lower>-1e+16</lower>
            <upper>1e+16</upper>
          </limit>
          <dynamics>
            <spring_reference>0</spring_reference>
            <spring_stiffness>0</spring_stiffness>
          </dynamics>
          <use_parent_model_frame>1</use_parent_model_frame>
        </axis>
      </joint>
      <link name='right_gripper'>
        <pose frame=''>0.06945 -0.102 -0.07265 -3e-06 -1.57079 3.14159</pose>
        <inertial>
          <pose frame=''>0.018 -0.00624 0.036135 3.14159 -0 0</pose>
          <mass>0.00882433</mass>
          <inertia>
            <ixx>7.46132e-06</ixx>
            <ixy>-2.1839e-11</ixy>
            <ixz>-7.86332e-12</ixz>
            <iyy>9.3608e-06</iyy>
            <iyz>-1.88054e-06</iyz>
            <izz>4.68291e-06</izz>
          </inertia>
        </inertial>
        <collision name='right_gripper_collision'>
          <pose frame=''>0 0 0 0 -0 3.14159</pose>
          <geometry>
            <mesh>
              <scale>1 1 1</scale>
              <uri>/home/francisco/robotis_ws/src/ros-bioloid-gp/bioloid_gp_description/bioloidgp_social_robot/meshes/right_gripper.STL</uri>
            </mesh>
          </geometry>
          <max_contacts>10</max_contacts>
          <surface>
            <contact>
              <ode/>
            </contact>
            <bounce/>
            <friction>
              <torsional>
                <ode/>
              </torsional>
              <ode/>
            </friction>
          </surface>
        </collision>
        <visual name='right_gripper_visual'>
          <pose frame=''>0 0 0 0 -0 3.14159</pose>
          <geometry>
            <mesh>
              <scale>1 1 1</scale>
              <uri>/home/francisco/robotis_ws/src/ros-bioloid-gp/bioloid_gp_description/bioloidgp_social_robot/meshes/right_gripper.STL</uri>
            </mesh>
          </geometry>
        </visual>
        <self_collide>0</self_collide>
        <enable_wind>0</enable_wind>
        <kinematic>0</kinematic>
      </link>
      <joint name='joint_7' type='revolute'>
        <child>right_gripper</child>
        <parent>right_arm_link_3</parent>
        <axis>
          <xyz>0 0 1</xyz>
          <limit>
            <lower>-1e+16</lower>
            <upper>1e+16</upper>
          </limit>
          <dynamics>
            <spring_reference>0</spring_reference>
            <spring_stiffness>0</spring_stiffness>
          </dynamics>
          <use_parent_model_frame>1</use_parent_model_frame>
        </axis>
      </joint>
      <link name='torso_Link'>
        <pose frame=''>0.00825 0 -0.05725 1.5708 -0 1.5708</pose>
        <inertial>
          <pose frame=''>0 -0.021091 -0.001319 0 -0 0</pose>
          <mass>0.0150307</mass>
          <inertia>
            <ixx>1.22996e-05</ixx>
            <ixy>-5.36004e-12</ixy>
            <ixz>4.57562e-15</ixz>
            <iyy>1.26744e-05</iyy>
            <iyz>-4.84169e-07</iyz>
            <izz>1.42781e-05</izz>
          </inertia>
        </inertial>
        <collision name='torso_Link_collision'>
          <pose frame=''>0 0 0 0 -0 0</pose>
          <geometry>
            <mesh>
              <scale>1 1 1</scale>
              <uri>/home/francisco/robotis_ws/src/ros-bioloid-gp/bioloid_gp_description/bioloidgp_social_robot/meshes/torso_Link.STL</uri>
            </mesh>
          </geometry>
          <max_contacts>10</max_contacts>
          <surface>
            <contact>
              <ode/>
            </contact>
            <bounce/>
            <friction>
              <torsional>
                <ode/>
              </torsional>
              <ode/>
            </friction>
          </surface>
        </collision>
        <visual name='torso_Link_visual'>
          <pose frame=''>0 0 0 0 -0 0</pose>
          <geometry>
            <mesh>
              <scale>1 1 1</scale>
              <uri>/home/francisco/robotis_ws/src/ros-bioloid-gp/bioloid_gp_description/bioloidgp_social_robot/meshes/torso_Link.STL</uri>
            </mesh>
          </geometry>
        </visual>
        <self_collide>0</self_collide>
        <enable_wind>0</enable_wind>
        <kinematic>0</kinematic>
      </link>
      <joint name='joint_19' type='revolute'>
        <child>torso_Link</child>
        <parent>dummy</parent>
        <axis>
          <xyz>0 -0 1</xyz>
          <limit>
            <lower>-1e+16</lower>
            <upper>1e+16</upper>
          </limit>
          <dynamics>
            <spring_reference>0</spring_reference>
            <spring_stiffness>0</spring_stiffness>
          </dynamics>
          <use_parent_model_frame>1</use_parent_model_frame>
        </axis>
      </joint>
      <link name='left_leg_link_1'>
        <pose frame=''>0.00825 0.016 -0.11075 1.5708 0 -1.5708</pose>
        <inertial>
          <pose frame=''>-0.013043 -0.002385 -0.000954 0 -0 0</pose>
          <mass>0.0465444</mass>
          <inertia>
            <ixx>7.24109e-06</ixx>
            <ixy>3.44088e-08</ixy>
            <ixz>-1.90927e-07</ixz>
            <iyy>1.32071e-05</iyy>
            <iyz>-1.46766e-09</iyz>
            <izz>1.18451e-05</izz>
          </inertia>
        </inertial>
        <collision name='left_leg_link_1_collision'>
          <pose frame=''>0 0 0 0 -0 0</pose>
          <geometry>
            <mesh>
              <scale>1 1 1</scale>
              <uri>/home/francisco/robotis_ws/src/ros-bioloid-gp/bioloid_gp_description/bioloidgp_social_robot/meshes/left_leg_link_1.STL</uri>
            </mesh>
          </geometry>
          <max_contacts>10</max_contacts>
          <surface>
            <contact>
              <ode/>
            </contact>
            <bounce/>
            <friction>
              <torsional>
                <ode/>
              </torsional>
              <ode/>
            </friction>
          </surface>
        </collision>
        <visual name='left_leg_link_1_visual'>
          <pose frame=''>0 0 0 0 -0 0</pose>
          <geometry>
            <mesh>
              <scale>1 1 1</scale>
              <uri>/home/francisco/robotis_ws/src/ros-bioloid-gp/bioloid_gp_description/bioloidgp_social_robot/meshes/left_leg_link_1.STL</uri>
            </mesh>
          </geometry>
        </visual>
        <self_collide>0</self_collide>
        <enable_wind>0</enable_wind>
        <kinematic>0</kinematic>
      </link>
      <joint name='joint_10' type='revolute'>
        <child>left_leg_link_1</child>
        <parent>torso_Link</parent>
        <axis>
          <xyz>-1 -0 0</xyz>
          <limit>
            <lower>-1e+16</lower>
            <upper>1e+16</upper>
          </limit>
          <dynamics>
            <spring_reference>0</spring_reference>
            <spring_stiffness>0</spring_stiffness>
          </dynamics>
          <use_parent_model_frame>1</use_parent_model_frame>
        </axis>
      </joint>
      <link name='left_leg_link_2'>
        <pose frame=''>0.00825 0.016 -0.15255 1.5708 -0 1.5708</pose>
        <inertial>
          <pose frame=''>0.012984 -0.043701 -0.000498 0 -0 0</pose>
          <mass>0.087396</mass>
          <inertia>
            <ixx>2.07331e-05</ixx>
            <ixy>-1.92394e-07</ixy>
            <ixz>1.89459e-07</ixz>
            <iyy>1.89035e-05</iyy>
            <iyz>-7.78205e-08</iyz>
            <izz>1.89379e-05</izz>
          </inertia>
        </inertial>
        <collision name='left_leg_link_2_collision'>
          <pose frame=''>0 0 0 0 -0 0</pose>
          <geometry>
            <mesh>
              <scale>1 1 1</scale>
              <uri>/home/francisco/robotis_ws/src/ros-bioloid-gp/bioloid_gp_description/bioloidgp_social_robot/meshes/left_leg_link_2.STL</uri>
            </mesh>
          </geometry>
          <max_contacts>10</max_contacts>
          <surface>
            <contact>
              <ode/>
            </contact>
            <bounce/>
            <friction>
              <torsional>
                <ode/>
              </torsional>
              <ode/>
            </friction>
          </surface>
        </collision>
        <visual name='left_leg_link_2_visual'>
          <pose frame=''>0 0 0 0 -0 0</pose>
          <geometry>
            <mesh>
              <scale>1 1 1</scale>
              <uri>/home/francisco/robotis_ws/src/ros-bioloid-gp/bioloid_gp_description/bioloidgp_social_robot/meshes/left_leg_link_2.STL</uri>
            </mesh>
          </geometry>
        </visual>
        <self_collide>0</self_collide>
        <enable_wind>0</enable_wind>
        <kinematic>0</kinematic>
      </link>
      <joint name='joint_12' type='revolute'>
        <child>left_leg_link_2</child>
        <parent>left_leg_link_1</parent>
        <axis>
          <xyz>-0 1 -0</xyz>
          <limit>
            <lower>-1e+16</lower>
            <upper>1e+16</upper>
          </limit>
          <dynamics>
            <spring_reference>0</spring_reference>
            <spring_stiffness>0</spring_stiffness>
          </dynamics>
          <use_parent_model_frame>1</use_parent_model_frame>
        </axis>
      </joint>
      <link name='left_leg_link_3'>
        <pose frame=''>-0.00625 0.016 -0.22695 -1.5708 -0 -1.5708</pose>
        <inertial>
          <pose frame=''>-0.014 0.033556 0.015194 0 -0 0</pose>
          <mass>0.00701487</mass>
          <inertia>
            <ixx>5.15588e-06</ixx>
            <ixy>3.01269e-19</ixy>
            <ixz>-2.1101e-18</ixz>
            <iyy>3.83308e-06</iyy>
            <iyz>-4.23988e-07</iyz>
            <izz>7.34905e-06</izz>
          </inertia>
        </inertial>
        <collision name='left_leg_link_3_collision'>
          <pose frame=''>0 0 0 0 -0 0</pose>
          <geometry>
            <mesh>
              <scale>1 1 1</scale>
              <uri>/home/francisco/robotis_ws/src/ros-bioloid-gp/bioloid_gp_description/bioloidgp_social_robot/meshes/left_leg_link_3.STL</uri>
            </mesh>
          </geometry>
          <max_contacts>10</max_contacts>
          <surface>
            <contact>
              <ode/>
            </contact>
            <bounce/>
            <friction>
              <torsional>
                <ode/>
              </torsional>
              <ode/>
            </friction>
          </surface>
        </collision>
        <visual name='left_leg_link_3_visual'>
          <pose frame=''>0 0 0 0 -0 0</pose>
          <geometry>
            <mesh>
              <scale>1 1 1</scale>
              <uri>/home/francisco/robotis_ws/src/ros-bioloid-gp/bioloid_gp_description/bioloidgp_social_robot/meshes/left_leg_link_3.STL</uri>
            </mesh>
          </geometry>
        </visual>
        <self_collide>0</self_collide>
        <enable_wind>0</enable_wind>
        <kinematic>0</kinematic>
      </link>
      <joint name='joint_14' type='revolute'>
        <child>left_leg_link_3</child>
        <parent>left_leg_link_2</parent>
        <axis>
          <xyz>0 -1 0</xyz>
          <limit>
            <lower>-1e+16</lower>
            <upper>1e+16</upper>
          </limit>
          <dynamics>
            <spring_reference>0</spring_reference>
            <spring_stiffness>0</spring_stiffness>
          </dynamics>
          <use_parent_model_frame>1</use_parent_model_frame>
        </axis>
      </joint>
      <link name='left_leg_link_4'>
        <pose frame=''>0.00825 0.016 -0.30195 0 -0 1.5708</pose>
        <inertial>
          <pose frame=''>0.0134 0.021096 0.013055 0 -0 0</pose>
          <mass>0.0856772</mass>
          <inertia>
            <ixx>2.17029e-05</ixx>
            <ixy>-2.48963e-19</ixy>
            <ixz>1.80511e-07</ixz>
            <iyy>2.20442e-05</iyy>
            <iyz>2.02917e-07</iyz>
            <izz>1.3056e-05</izz>
          </inertia>
        </inertial>
        <collision name='left_leg_link_4_collision'>
          <pose frame=''>0 0 0 0 -0 0</pose>
          <geometry>
            <mesh>
              <scale>1 1 1</scale>
              <uri>/home/francisco/robotis_ws/src/ros-bioloid-gp/bioloid_gp_description/bioloidgp_social_robot/meshes/left_leg_link_4.STL</uri>
            </mesh>
          </geometry>
          <max_contacts>10</max_contacts>
          <surface>
            <contact>
              <ode/>
            </contact>
            <bounce/>
            <friction>
              <torsional>
                <ode/>
              </torsional>
              <ode/>
            </friction>
          </surface>
        </collision>
        <visual name='left_leg_link_4_visual'>
          <pose frame=''>0 0 0 0 -0 0</pose>
          <geometry>
            <mesh>
              <scale>1 1 1</scale>
              <uri>/home/francisco/robotis_ws/src/ros-bioloid-gp/bioloid_gp_description/bioloidgp_social_robot/meshes/left_leg_link_4.STL</uri>
            </mesh>
          </geometry>
        </visual>
        <self_collide>0</self_collide>
        <enable_wind>0</enable_wind>
        <kinematic>0</kinematic>
      </link>
      <joint name='joint_16' type='revolute'>
        <child>left_leg_link_4</child>
        <parent>left_leg_link_3</parent>
        <axis>
          <xyz>-0 1 -0</xyz>
          <limit>
            <lower>-1e+16</lower>
            <upper>1e+16</upper>
          </limit>
          <dynamics>
            <spring_reference>0</spring_reference>
            <spring_stiffness>0</spring_stiffness>
          </dynamics>
          <use_parent_model_frame>1</use_parent_model_frame>
        </axis>
      </joint>
      <link name='left_leg_link_5'>
        <pose frame=''>0.00825 0.0298 -0.30205 1.5708 -0 0</pose>
        <inertial>
          <pose frame=''>-0.0002 0.027102 -0.005782 0 -0 0</pose>
          <mass>0.0145032</mass>
          <inertia>
            <ixx>5.46559e-06</ixx>
            <ixy>6.68355e-17</ixy>
            <ixz>-6.35562e-16</ixz>
            <iyy>1.36798e-05</iyy>
            <iyz>-6.23589e-15</iyz>
            <izz>9.53949e-06</izz>
          </inertia>
        </inertial>
        <collision name='left_leg_link_5_collision'>
          <pose frame=''>0 0 0 0 -0 3.14159</pose>
          <geometry>
            <mesh>
              <scale>1 1 1</scale>
              <uri>/home/francisco/robotis_ws/src/ros-bioloid-gp/bioloid_gp_description/bioloidgp_social_robot/meshes/left_leg_link_5.STL</uri>
            </mesh>
          </geometry>
          <surface>
            <contact>
              <ode/>
            </contact>
            <friction>
              <ode>
                <mu>0.9</mu>
                <mu2>0.9</mu2>
              </ode>
              <torsional>
                <ode/>
              </torsional>
            </friction>
            <bounce/>
          </surface>
          <max_contacts>10</max_contacts>
        </collision>
        <visual name='left_leg_link_5_visual'>
          <pose frame=''>0 0 0 0 -0 3.14159</pose>
          <geometry>
            <mesh>
              <scale>1 1 1</scale>
              <uri>/home/francisco/robotis_ws/src/ros-bioloid-gp/bioloid_gp_description/bioloidgp_social_robot/meshes/left_leg_link_5.STL</uri>
            </mesh>
          </geometry>
          <material>
            <script>
              <uri>__default__</uri>
              <name>__default__</name>
            </script>
          </material>
        </visual>
        <gravity>1</gravity>
        <velocity_decay/>
        <self_collide>0</self_collide>
        <enable_wind>0</enable_wind>
        <kinematic>0</kinematic>
      </link>
      <joint name='joint_18' type='revolute'>
        <child>left_leg_link_5</child>
        <parent>left_leg_link_4</parent>
        <axis>
          <xyz>1 0 0</xyz>
          <limit>
            <lower>-1e+16</lower>
            <upper>1e+16</upper>
          </limit>
          <dynamics>
            <spring_reference>0</spring_reference>
            <spring_stiffness>0</spring_stiffness>
          </dynamics>
          <use_parent_model_frame>1</use_parent_model_frame>
        </axis>
      </joint>
      <link name='right_leg_link_1'>
        <pose frame=''>0.00825 -0.016 -0.11075 1.5708 0 -1.5708</pose>
        <inertial>
          <pose frame=''>-0.013043 -0.002326 0.000954 0 -0 0</pose>
          <mass>0.0465444</mass>
          <inertia>
            <ixx>7.24109e-06</ixx>
            <ixy>5.52408e-08</ixy>
            <ixz>1.90927e-07</ixz>
            <iyy>1.32071e-05</iyy>
            <iyz>-1.46766e-09</iyz>
            <izz>1.18451e-05</izz>
          </inertia>
        </inertial>
        <collision name='right_leg_link_1_collision'>
          <pose frame=''>0 0 0 3.14159 -0 3.14159</pose>
          <geometry>
            <mesh>
              <scale>1 1 1</scale>
              <uri>/home/francisco/robotis_ws/src/ros-bioloid-gp/bioloid_gp_description/bioloidgp_social_robot/meshes/right_leg_link_1.STL</uri>
            </mesh>
          </geometry>
          <max_contacts>10</max_contacts>
          <surface>
            <contact>
              <ode/>
            </contact>
            <bounce/>
            <friction>
              <torsional>
                <ode/>
              </torsional>
              <ode/>
            </friction>
          </surface>
        </collision>
        <visual name='right_leg_link_1_visual'>
          <pose frame=''>0 0 0 3.14159 -0 3.14159</pose>
          <geometry>
            <mesh>
              <scale>1 1 1</scale>
              <uri>/home/francisco/robotis_ws/src/ros-bioloid-gp/bioloid_gp_description/bioloidgp_social_robot/meshes/right_leg_link_1.STL</uri>
            </mesh>
          </geometry>
        </visual>
        <self_collide>0</self_collide>
        <enable_wind>0</enable_wind>
        <kinematic>0</kinematic>
      </link>
      <joint name='joint_9' type='revolute'>
        <child>right_leg_link_1</child>
        <parent>torso_Link</parent>
        <axis>
          <xyz>-1 -0 0</xyz>
          <limit>
            <lower>-1e+16</lower>
            <upper>1e+16</upper>
          </limit>
          <dynamics>
            <spring_reference>0</spring_reference>
            <spring_stiffness>0</spring_stiffness>
          </dynamics>
          <use_parent_model_frame>1</use_parent_model_frame>
        </axis>
      </joint>
      <link name='right_leg_link_2'>
        <pose frame=''>0.00825 -0.016 -0.15255 1.5708 0 -1.5708</pose>
        <inertial>
          <pose frame=''>-0.012984 -0.043669 -0.000467 0 -0 0</pose>
          <mass>0.087396</mass>
          <inertia>
            <ixx>2.07331e-05</ixx>
            <ixy>1.89459e-07</ixy>
            <ixz>-1.92394e-07</ixz>
            <iyy>1.89035e-05</iyy>
            <iyz>-7.78205e-08</iyz>
            <izz>1.89379e-05</izz>
          </inertia>
        </inertial>
        <collision name='right_leg_link_2_collision'>
          <pose frame=''>0 0 0 3.14159 -0 3.14159</pose>
          <geometry>
            <mesh>
              <scale>1 1 1</scale>
              <uri>/home/francisco/robotis_ws/src/ros-bioloid-gp/bioloid_gp_description/bioloidgp_social_robot/meshes/right_leg_link_2.STL</uri>
            </mesh>
          </geometry>
          <max_contacts>10</max_contacts>
          <surface>
            <contact>
              <ode/>
            </contact>
            <bounce/>
            <friction>
              <torsional>
                <ode/>
              </torsional>
              <ode/>
            </friction>
          </surface>
        </collision>
        <visual name='right_leg_link_2_visual'>
          <pose frame=''>0 0 0 3.14159 -0 3.14159</pose>
          <geometry>
            <mesh>
              <scale>1 1 1</scale>
              <uri>/home/francisco/robotis_ws/src/ros-bioloid-gp/bioloid_gp_description/bioloidgp_social_robot/meshes/right_leg_link_2.STL</uri>
            </mesh>
          </geometry>
        </visual>
        <self_collide>0</self_collide>
        <enable_wind>0</enable_wind>
        <kinematic>0</kinematic>
      </link>
      <joint name='joint_11' type='revolute'>
        <child>right_leg_link_2</child>
        <parent>right_leg_link_1</parent>
        <axis>
          <xyz>0 -1 0</xyz>
          <limit>
            <lower>-1e+16</lower>
            <upper>1e+16</upper>
          </limit>
          <dynamics>
            <spring_reference>0</spring_reference>
            <spring_stiffness>0</spring_stiffness>
          </dynamics>
          <use_parent_model_frame>1</use_parent_model_frame>
        </axis>
      </joint>
      <link name='right_leg_link_3'>
        <pose frame=''>-0.00625 -0.016 -0.22695 -1.5708 0 1.5708</pose>
        <inertial>
          <pose frame=''>0.014 0.033556 0.015194 0 -0 0</pose>
          <mass>0.00701487</mass>
          <inertia>
            <ixx>5.15588e-06</ixx>
            <ixy>-9.82287e-20</ixy>
            <ixz>-3.00164e-20</ixz>
            <iyy>3.83308e-06</iyy>
            <iyz>-4.23988e-07</iyz>
            <izz>7.34905e-06</izz>
          </inertia>
        </inertial>
        <collision name='right_leg_link_3_collision'>
          <pose frame=''>0 0 0 3.14159 -0 3.14159</pose>
          <geometry>
            <mesh>
              <scale>1 1 1</scale>
              <uri>/home/francisco/robotis_ws/src/ros-bioloid-gp/bioloid_gp_description/bioloidgp_social_robot/meshes/right_leg_link_3.STL</uri>
            </mesh>
          </geometry>
          <max_contacts>10</max_contacts>
          <surface>
            <contact>
              <ode/>
            </contact>
            <bounce/>
            <friction>
              <torsional>
                <ode/>
              </torsional>
              <ode/>
            </friction>
          </surface>
        </collision>
        <visual name='right_leg_link_3_visual'>
          <pose frame=''>0 0 0 3.14159 -0 3.14159</pose>
          <geometry>
            <mesh>
              <scale>1 1 1</scale>
              <uri>/home/francisco/robotis_ws/src/ros-bioloid-gp/bioloid_gp_description/bioloidgp_social_robot/meshes/right_leg_link_3.STL</uri>
            </mesh>
          </geometry>
        </visual>
        <self_collide>0</self_collide>
        <enable_wind>0</enable_wind>
        <kinematic>0</kinematic>
      </link>
      <joint name='joint_13' type='revolute'>
        <child>right_leg_link_3</child>
        <parent>right_leg_link_2</parent>
        <axis>
          <xyz>-0 1 -0</xyz>
          <limit>
            <lower>-1e+16</lower>
            <upper>1e+16</upper>
          </limit>
          <dynamics>
            <spring_reference>0</spring_reference>
            <spring_stiffness>0</spring_stiffness>
          </dynamics>
          <use_parent_model_frame>1</use_parent_model_frame>
        </axis>
      </joint>
      <link name='right_leg_link_4'>
        <pose frame=''>0.00825 -0.016 -0.30195 0 0 -1.5708</pose>
        <inertial>
          <pose frame=''>-0.013368 0.021128 0.013055 0 -0 0</pose>
          <mass>0.0856772</mass>
          <inertia>
            <ixx>2.17029e-05</ixx>
            <ixy>7.45086e-20</ixy>
            <ixz>-2.01343e-07</ixz>
            <iyy>2.20442e-05</iyy>
            <iyz>1.82086e-07</iyz>
            <izz>1.3056e-05</izz>
          </inertia>
        </inertial>
        <collision name='right_leg_link_4_collision'>
          <pose frame=''>0 0 0 0 -0 3.14159</pose>
          <geometry>
            <mesh>
              <scale>1 1 1</scale>
              <uri>/home/francisco/robotis_ws/src/ros-bioloid-gp/bioloid_gp_description/bioloidgp_social_robot/meshes/right_leg_link_4.STL</uri>
            </mesh>
          </geometry>
          <max_contacts>10</max_contacts>
          <surface>
            <contact>
              <ode/>
            </contact>
            <bounce/>
            <friction>
              <torsional>
                <ode/>
              </torsional>
              <ode/>
            </friction>
          </surface>
        </collision>
        <visual name='right_leg_link_4_visual'>
          <pose frame=''>0 0 0 0 -0 3.14159</pose>
          <geometry>
            <mesh>
              <scale>1 1 1</scale>
              <uri>/home/francisco/robotis_ws/src/ros-bioloid-gp/bioloid_gp_description/bioloidgp_social_robot/meshes/right_leg_link_4.STL</uri>
            </mesh>
          </geometry>
        </visual>
        <self_collide>0</self_collide>
        <enable_wind>0</enable_wind>
        <kinematic>0</kinematic>
      </link>
      <joint name='joint_15' type='revolute'>
        <child>right_leg_link_4</child>
        <parent>right_leg_link_3</parent>
        <axis>
          <xyz>0 -1 -0</xyz>
          <limit>
            <lower>-1e+16</lower>
            <upper>1e+16</upper>
          </limit>
          <dynamics>
            <spring_reference>0</spring_reference>
            <spring_stiffness>0</spring_stiffness>
          </dynamics>
          <use_parent_model_frame>1</use_parent_model_frame>
        </axis>
      </joint>
      <link name='right_leg_link_5'>
        <pose frame=''>0.00825 -0.0298 -0.30205 1.5708 -0 0</pose>
        <inertial>
          <pose frame=''>0.0002 -0.027102 0.005782 0 -0 0</pose>
          <mass>0.0145032</mass>
          <inertia>
            <ixx>5.46559e-06</ixx>
            <ixy>6.68159e-17</ixy>
            <ixz>6.34572e-16</ixz>
            <iyy>1.36798e-05</iyy>
            <iyz>6.23592e-15</iyz>
            <izz>9.53949e-06</izz>
          </inertia>
        </inertial>
        <collision name='right_leg_link_5_collision'>
          <pose frame=''>0 0 0 0 -0 0</pose>
          <geometry>
            <mesh>
              <scale>1 1 1</scale>
              <uri>/home/francisco/robotis_ws/src/ros-bioloid-gp/bioloid_gp_description/bioloidgp_social_robot/meshes/right_leg_link_5.STL</uri>
            </mesh>
          </geometry>
          <surface>
            <contact>
              <ode/>
            </contact>
            <friction>
              <ode>
                <mu>0.9</mu>
                <mu2>0.9</mu2>
              </ode>
              <torsional>
                <ode/>
              </torsional>
            </friction>
            <bounce/>
          </surface>
          <max_contacts>10</max_contacts>
        </collision>
        <visual name='right_leg_link_5_visual'>
          <pose frame=''>0 0 0 0 -0 0</pose>
          <geometry>
            <mesh>
              <scale>1 1 1</scale>
              <uri>/home/francisco/robotis_ws/src/ros-bioloid-gp/bioloid_gp_description/bioloidgp_social_robot/meshes/right_leg_link_5.STL</uri>
            </mesh>
          </geometry>
          <material>
            <script>
              <uri>__default__</uri>
              <name>__default__</name>
            </script>
          </material>
        </visual>
        <gravity>1</gravity>
        <velocity_decay/>
        <self_collide>0</self_collide>
        <enable_wind>0</enable_wind>
        <kinematic>0</kinematic>
      </link>
      <joint name='joint_17' type='revolute'>
        <child>right_leg_link_5</child>
        <parent>right_leg_link_4</parent>
        <axis>
          <xyz>1 0 -0</xyz>
          <limit>
            <lower>-1e+16</lower>
            <upper>1e+16</upper>
          </limit>
          <dynamics>
            <spring_reference>0</spring_reference>
            <spring_stiffness>0</spring_stiffness>
          </dynamics>
          <use_parent_model_frame>1</use_parent_model_frame>
        </axis>
      </joint>
      <link name='left_arm_link_1'>
        <pose frame=''>0.00875 0.05649 0.00275 3.14159 -0 3.14159</pose>
        <inertial>
          <pose frame=''>-0 -0.009232 0.005179 0 -0 0</pose>
          <mass>0.00402029</mass>
          <inertia>
            <ixx>8.53462e-07</ixx>
            <ixy>1.70481e-12</ixy>
            <ixz>-1.05162e-12</ixz>
            <iyy>1.7713e-06</iyy>
            <iyz>2.51193e-07</iyz>
            <izz>1.69099e-06</izz>
          </inertia>
        </inertial>
        <collision name='left_arm_link_1_collision'>
          <pose frame=''>0 0 0 0 -0 3.14159</pose>
          <geometry>
            <mesh>
              <scale>1 1 1</scale>
              <uri>/home/francisco/robotis_ws/src/ros-bioloid-gp/bioloid_gp_description/bioloidgp_social_robot/meshes/left_arm_link_1.STL</uri>
            </mesh>
          </geometry>
          <max_contacts>10</max_contacts>
          <surface>
            <contact>
              <ode/>
            </contact>
            <bounce/>
            <friction>
              <torsional>
                <ode/>
              </torsional>
              <ode/>
            </friction>
          </surface>
        </collision>
        <visual name='left_arm_link_1_visual'>
          <pose frame=''>0 0 0 0 -0 3.14159</pose>
          <geometry>
            <mesh>
              <scale>1 1 1</scale>
              <uri>/home/francisco/robotis_ws/src/ros-bioloid-gp/bioloid_gp_description/bioloidgp_social_robot/meshes/left_arm_link_1.STL</uri>
            </mesh>
          </geometry>
        </visual>
        <self_collide>0</self_collide>
        <enable_wind>0</enable_wind>
        <kinematic>0</kinematic>
      </link>
      <joint name='joint_2' type='revolute'>
        <child>left_arm_link_1</child>
        <parent>dummy</parent>
        <axis>
          <xyz>0 1 0</xyz>
          <limit>
            <lower>-1e+16</lower>
            <upper>1e+16</upper>
          </limit>
          <dynamics>
            <spring_reference>0</spring_reference>
            <spring_stiffness>0</spring_stiffness>
          </dynamics>
          <use_parent_model_frame>1</use_parent_model_frame>
        </axis>
      </joint>
      <link name='left_arm_link_2'>
        <pose frame=''>0.00875 0.0795 -0.01525 1.5708 0 -1.5708</pose>
        <inertial>
          <pose frame=''>0.000496 -0.035284 0.003118 0 -0 0</pose>
          <mass>0.086643</mass>
          <inertia>
            <ixx>2.18653e-05</ixx>
            <ixy>-8.94831e-09</ixy>
            <ixz>1.92394e-07</ixz>
            <iyy>1.84666e-05</iyy>
            <iyz>1.80511e-07</iyz>
            <izz>1.66636e-05</izz>
          </inertia>
        </inertial>
        <collision name='left_arm_link_2_collision'>
          <pose frame=''>0 0 0 3.14159 -0 3.14159</pose>
          <geometry>
            <mesh>
              <scale>1 1 1</scale>
              <uri>/home/francisco/robotis_ws/src/ros-bioloid-gp/bioloid_gp_description/bioloidgp_social_robot/meshes/left_arm_link_2.STL</uri>
            </mesh>
          </geometry>
          <max_contacts>10</max_contacts>
          <surface>
            <contact>
              <ode/>
            </contact>
            <bounce/>
            <friction>
              <torsional>
                <ode/>
              </torsional>
              <ode/>
            </friction>
          </surface>
        </collision>
        <visual name='left_arm_link_2_visual'>
          <pose frame=''>0 0 0 3.14159 -0 3.14159</pose>
          <geometry>
            <mesh>
              <scale>1 1 1</scale>
              <uri>/home/francisco/robotis_ws/src/ros-bioloid-gp/bioloid_gp_description/bioloidgp_social_robot/meshes/left_arm_link_2.STL</uri>
            </mesh>
          </geometry>
        </visual>
        <self_collide>0</self_collide>
        <enable_wind>0</enable_wind>
        <kinematic>0</kinematic>
      </link>
      <joint name='joint_4' type='revolute'>
        <child>left_arm_link_2</child>
        <parent>left_arm_link_1</parent>
        <axis>
          <xyz>-1 -0 0</xyz>
          <limit>
            <lower>-1e+16</lower>
            <upper>1e+16</upper>
          </limit>
          <dynamics>
            <spring_reference>0</spring_reference>
            <spring_stiffness>0</spring_stiffness>
          </dynamics>
          <use_parent_model_frame>1</use_parent_model_frame>
        </axis>
      </joint>
      <link name='left_arm_link_3'>
        <pose frame=''>0.02695 0.0795 -0.07265 0 -0 1.5708</pose>
        <inertial>
          <pose frame=''>0.0061 0.042343 0.016759 0 -0 0</pose>
          <mass>0.0525573</mass>
          <inertia>
            <ixx>1.07464e-05</ixx>
            <ixy>2.91666e-09</ixy>
            <ixz>-1.90928e-07</ixz>
            <iyy>1.44872e-05</iyy>
            <iyz>-2.52661e-07</iyz>
            <izz>1.4391e-05</izz>
          </inertia>
        </inertial>
        <collision name='left_arm_link_3_collision'>
          <pose frame=''>0 0 0 3.14159 -0 0</pose>
          <geometry>
            <mesh>
              <scale>1 1 1</scale>
              <uri>/home/francisco/robotis_ws/src/ros-bioloid-gp/bioloid_gp_description/bioloidgp_social_robot/meshes/left_arm_link_3.STL</uri>
            </mesh>
          </geometry>
          <max_contacts>10</max_contacts>
          <surface>
            <contact>
              <ode/>
            </contact>
            <bounce/>
            <friction>
              <torsional>
                <ode/>
              </torsional>
              <ode/>
            </friction>
          </surface>
        </collision>
        <visual name='left_arm_link_3_visual'>
          <pose frame=''>0 0 0 3.14159 -0 0</pose>
          <geometry>
            <mesh>
              <scale>1 1 1</scale>
              <uri>/home/francisco/robotis_ws/src/ros-bioloid-gp/bioloid_gp_description/bioloidgp_social_robot/meshes/left_arm_link_3.STL</uri>
            </mesh>
          </geometry>
        </visual>
        <self_collide>0</self_collide>
        <enable_wind>0</enable_wind>
        <kinematic>0</kinematic>
      </link>
      <joint name='joint_6' type='revolute'>
        <child>left_arm_link_3</child>
        <parent>left_arm_link_2</parent>
        <axis>
          <xyz>-0 1 0</xyz>
          <limit>
            <lower>-1e+16</lower>
            <upper>1e+16</upper>
          </limit>
          <dynamics>
            <spring_reference>0</spring_reference>
            <spring_stiffness>0</spring_stiffness>
          </dynamics>
          <use_parent_model_frame>1</use_parent_model_frame>
        </axis>
      </joint>
      <link name='left_gripper'>
        <pose frame=''>0.06945 0.102 -0.07265 3.14159 -1.57079 3.14159</pose>
        <inertial>
          <pose frame=''>-0.018 -0.00624 0.036135 3.14159 -0 0</pose>
          <mass>0.00882433</mass>
          <inertia>
            <ixx>7.46132e-06</ixx>
            <ixy>-2.1839e-11</ixy>
            <ixz>-7.86332e-12</ixz>
            <iyy>9.3608e-06</iyy>
            <iyz>-1.88054e-06</iyz>
            <izz>4.68291e-06</izz>
          </inertia>
        </inertial>
        <collision name='left_gripper_collision'>
          <pose frame=''>0 0 0 3.14159 -0 0</pose>
          <geometry>
            <mesh>
              <scale>1 1 1</scale>
              <uri>/home/francisco/robotis_ws/src/ros-bioloid-gp/bioloid_gp_description/bioloidgp_social_robot/meshes/left_gripper.STL</uri>
            </mesh>
          </geometry>
          <max_contacts>10</max_contacts>
          <surface>
            <contact>
              <ode/>
            </contact>
            <bounce/>
            <friction>
              <torsional>
                <ode/>
              </torsional>
              <ode/>
            </friction>
          </surface>
        </collision>
        <visual name='left_gripper_visual'>
          <pose frame=''>0 0 0 3.14159 -0 0</pose>
          <geometry>
            <mesh>
              <scale>1 1 1</scale>
              <uri>/home/francisco/robotis_ws/src/ros-bioloid-gp/bioloid_gp_description/bioloidgp_social_robot/meshes/left_gripper.STL</uri>
            </mesh>
          </geometry>
        </visual>
        <self_collide>0</self_collide>
        <enable_wind>0</enable_wind>
        <kinematic>0</kinematic>
      </link>
      <joint name='joint_8' type='revolute'>
        <child>left_gripper</child>
        <parent>left_arm_link_3</parent>
        <axis>
          <xyz>0 -0 1</xyz>
          <limit>
            <lower>-1e+16</lower>
            <upper>1e+16</upper>
          </limit>
          <dynamics>
            <spring_reference>0</spring_reference>
            <spring_stiffness>0</spring_stiffness>
          </dynamics>
          <use_parent_model_frame>1</use_parent_model_frame>
        </axis>
      </joint>
      <link name='head_link'>
        <pose frame=''>0.00825 0 0.02205 0 0 -1.57079</pose>
        <inertial>
          <pose frame=''>0 0.00059 -0.022 0 -0 0</pose>
          <mass>0.0131553</mass>
          <inertia>
            <ixx>5.23339e-06</ixx>
            <ixy>3.48156e-12</ixy>
            <ixz>6.72257e-11</ixz>
            <iyy>9.22116e-06</iyy>
            <iyz>-7.97729e-08</iyz>
            <izz>6.0076e-06</izz>
          </inertia>
        </inertial>
        <collision name='head_link_collision'>
          <pose frame=''>0 0 0 3.14159 -0 0</pose>
          <geometry>
            <mesh>
              <scale>1 1 1</scale>
              <uri>/home/francisco/robotis_ws/src/ros-bioloid-gp/bioloid_gp_description/bioloidgp_social_robot/meshes/head_link.STL</uri>
            </mesh>
          </geometry>
          <max_contacts>10</max_contacts>
          <surface>
            <contact>
              <ode/>
            </contact>
            <bounce/>
            <friction>
              <torsional>
                <ode/>
              </torsional>
              <ode/>
            </friction>
          </surface>
        </collision>
        <visual name='head_link_visual'>
          <pose frame=''>0 0 0 3.14159 -0 0</pose>
          <geometry>
            <mesh>
              <scale>1 1 1</scale>
              <uri>/home/francisco/robotis_ws/src/ros-bioloid-gp/bioloid_gp_description/bioloidgp_social_robot/meshes/head_link.STL</uri>
            </mesh>
          </geometry>
        </visual>
        <self_collide>0</self_collide>
        <enable_wind>0</enable_wind>
        <kinematic>0</kinematic>
      </link>
      <joint name='joint_20' type='revolute'>
        <child>head_link</child>
        <parent>dummy</parent>
        <axis>
          <xyz>0 -0 1</xyz>
          <limit>
            <lower>-1e+16</lower>
            <upper>1e+16</upper>
          </limit>
          <dynamics>
            <spring_reference>0</spring_reference>
            <spring_stiffness>0</spring_stiffness>
          </dynamics>
          <use_parent_model_frame>1</use_parent_model_frame>
        </axis>
      </joint>
      <link name='camera'>
        <pose frame=''>0.00825 -0 0.07575 1.5708 -1.57079 3.14159</pose>
        <inertial>
          <pose frame=''>-4.4e-05 -0.036891 0.000351 0 -0 0</pose>
          <mass>0.0951615</mass>
          <inertia>
            <ixx>4.11638e-05</ixx>
            <ixy>-9.11391e-09</ixy>
            <ixz>4.26901e-09</ixz>
            <iyy>3.6166e-05</iyy>
            <iyz>4.35268e-07</iyz>
            <izz>1.42955e-05</izz>
          </inertia>
        </inertial>
        <collision name='camera_collision'>
          <pose frame=''>0 0 0 3.14159 -0 0</pose>
          <geometry>
            <mesh>
              <scale>1 1 1</scale>
              <uri>/home/francisco/robotis_ws/src/ros-bioloid-gp/bioloid_gp_description/bioloidgp_social_robot/meshes/camera.STL</uri>
            </mesh>
          </geometry>
          <max_contacts>10</max_contacts>
          <surface>
            <contact>
              <ode/>
            </contact>
            <bounce/>
            <friction>
              <torsional>
                <ode/>
              </torsional>
              <ode/>
            </friction>
          </surface>
        </collision>
        <visual name='camera_visual'>
          <pose frame=''>0 0 0 3.14159 -0 0</pose>
          <geometry>
            <mesh>
              <scale>1 1 1</scale>
              <uri>/home/francisco/robotis_ws/src/ros-bioloid-gp/bioloid_gp_description/bioloidgp_social_robot/meshes/camera.STL</uri>
            </mesh>
          </geometry>
        </visual>
        <self_collide>0</self_collide>
        <enable_wind>0</enable_wind>
        <kinematic>0</kinematic>
      </link>
      <joint name='joint_21' type='revolute'>
        <child>camera</child>
        <parent>head_link</parent>
        <axis>
          <xyz>-4e-06 1 -0</xyz>
          <limit>
            <lower>-1e+16</lower>
            <upper>1e+16</upper>
          </limit>
          <dynamics>
            <spring_reference>0</spring_reference>
            <spring_stiffness>0</spring_stiffness>
          </dynamics>
          <use_parent_model_frame>1</use_parent_model_frame>
        </axis>
      </joint>
      <static>0</static>
      <plugin name='gazebo_ros_control' filename='libgazebo_ros_control.so'>
        <robotNamespace>/bioloidgp_social_robot</robotNamespace>
      </plugin>
      <pose frame=''>0 0 0.33 0 -0 0</pose>
    </model>
    <state world_name='default'>
      <sim_time>9 115000000</sim_time>
      <real_time>19 565963150</real_time>
      <wall_time>1586957126 202855579</wall_time>
      <iterations>9115</iterations>
      <model name='bioloidgp_social_robot'>
        <pose frame=''>-0.407607 0.141306 0.034547 3.14129 -1.50025 3.03889</pose>
        <scale>1 1 1</scale>
        <link name='camera'>
          <pose frame=''>-0.483346 0.149128 0.03741 1.57073 0.070855 3.03869</pose>
          <velocity>0.000546 -0.006422 -0.000889 0.103733 -0.169915 0.038153</velocity>
          <acceleration>0.411564 -1.71101 0.442174 0.114711 -0.494513 2.49673</acceleration>
          <wrench>0.039165 -0.162822 0.042078 0 -0 0</wrench>
        </link>
        <link name='dummy'>
          <pose frame=''>-0.407607 0.141306 0.034547 3.14129 -1.50025 3.03889</pose>
          <velocity>0.001584 -0.002768 0.001055 0.100416 -0.02049 0.061122</velocity>
          <acceleration>1.45969 -5.25522 1.26214 -2.67565 0.068488 2.11657</acceleration>
          <wrench>0.348823 -1.25584 0.301614 0 -0 0</wrench>
        </link>
        <link name='head_link'>
          <pose frame=''>-0.430066 0.143627 0.041233 1.64132 8.4e-05 -1.67374</pose>
          <velocity>0.001167 -0.005138 0.001394 0.103881 -0.010325 0.060765</velocity>
          <acceleration>1.17435 -8.54424 1.41876 -1.29675 -0.679378 -2.06181</acceleration>
          <wrench>0.015449 -0.112402 0.018664 0 -0 0</wrench>
        </link>
        <link name='left_arm_link_1'>
          <pose frame=''>-0.405144 0.197842 0.043062 -0.020375 1.50243 -0.123118</pose>
          <velocity>-0.001587 -0.003046 0.005603 0.033464 0.508492 0.121938</velocity>
          <acceleration>-0.251615 -5.7271 9.00404 -0.837871 1.55577 1.65689</acceleration>
          <wrench>-0.001012 -0.023025 0.036199 0 -0 0</wrench>
        </link>
        <link name='left_arm_link_2'>
          <pose frame=''>-0.384917 0.218885 0.044317 -3.07276 -0.001347 -1.6736</pose>
          <velocity>-0.000295 -0.002303 0.000528 0.037562 0.475618 0.100427</velocity>
          <acceleration>1.48868 -1.55955 4.47082 -0.650338 -0.339443 -1.34375</acceleration>
          <wrench>0.128984 -0.135124 0.387366 0 -0 0</wrench>
        </link>
        <link name='left_arm_link_3'>
          <pose frame=''>-0.329198 0.213166 0.066421 -1.63959 0.001355 1.46799</pose>
          <velocity>0.010969 0.002431 -0.026344 0.03723 0.485592 0.101236</velocity>
          <acceleration>-4.19614 -1.17081 2.24432 -3.07176 -1.02121 3.11478</acceleration>
          <wrench>-0.220538 -0.061535 0.117955 0 -0 0</wrench>
        </link>
        <link name='left_gripper'>
          <pose frame=''>-0.329791 0.235904 0.10879 -3.14023 0.068802 3.03888</pose>
          <velocity>0.029222 0.000817 -0.025203 0.036157 0.485984 0.100546</velocity>
          <acceleration>7.44897 4.75772 -5.97262 -3.0321 -0.902294 0.962196</acceleration>
          <wrench>0.065732 0.041984 -0.052704 0 -0 0</wrench>
        </link>
        <link name='left_leg_link_1'>
          <pose frame=''>-0.296654 0.145939 0.050618 -3.0695 -5.9e-05 -1.67555</pose>
          <velocity>0.000526 0.001611 -5.5e-05 0.107496 0.133046 0.007977</velocity>
          <acceleration>-0.468786 -1.60793 2.56609 -0.133039 1.1144 -1.19604</acceleration>
          <wrench>-0.021819 -0.07484 0.119437 0 -0 0</wrench>
        </link>
        <link name='left_leg_link_2'>
          <pose frame=''>-0.255186 0.141584 0.0536 -0.072003 9e-05 1.46604</pose>
          <velocity>0.001224 0.002264 -0.003275 0.109377 0.138609 0.005485</velocity>
          <acceleration>0.772036 -0.058609 -6.6762 1.10573 0.186468 3.13509</acceleration>
          <wrench>0.067473 -0.005122 -0.583473 0 -0 0</wrench>
        </link>
        <link name='left_leg_link_3'>
          <pose frame=''>-0.180353 0.133713 0.044508 0.072271 -0.000238 -1.67555</pose>
          <velocity>0.001404 0.003528 -0.017895 0.120766 0.119914 -0.002841</velocity>
          <acceleration>1.80103 -0.95252 -14.9384 1.62895 -0.411536 -0.988027</acceleration>
          <wrench>0.012634 -0.006682 -0.104791 0 -0 0</wrench>
        </link>
        <link name='left_leg_link_4'>
          <pose frame=''>-0.106999 0.126003 0.064404 -1.64298 0.000378 1.46605</pose>
          <velocity>0.004153 0.001788 -0.033019 0.156052 0.116269 -0.005182</velocity>
          <acceleration>-0.18445 3.82943 -18.3911 -2.60604 -0.099356 -0.046306</acceleration>
          <wrench>-0.015803 0.328095 -1.5757 0 -0 0</wrench>
        </link>
        <link name='left_leg_link_5'>
          <pose frame=''>-0.105459 0.139716 0.064407 -1.568 -1.49848 3.03264</pose>
          <velocity>0.00484 0.002077 -0.031312 0.142631 0.15084 -0.00656</velocity>
          <acceleration>1.89223 -1.05276 -15.0311 0.32137 -0.816944 -0.026311</acceleration>
          <wrench>0.027443 -0.015268 -0.217999 0 -0 0</wrench>
        </link>
        <link name='right_arm_link_1'>
          <pose frame=''>-0.416752 0.085459 0.043063 -0.015868 -1.50134 3.05454</pose>
          <velocity>0.003866 -0.003385 -0.002764 0.000345 0.305662 0.149276</velocity>
          <acceleration>2.50776 -6.07192 -5.94753 -0.382781 -0.645994 2.32582</acceleration>
          <wrench>0.010082 -0.024411 -0.023911 0 -0 0</wrench>
        </link>
        <link name='right_arm_link_2'>
          <pose frame=''>-0.401254 0.060728 0.044339 -3.07163 0.001084 -1.67344</pose>
          <velocity>0.001954 -0.002999 -0.011629 0.007322 0.33634 0.122049</velocity>
          <acceleration>0.237487 -3.00209 -4.22172 -0.645444 0.441359 1.04554</acceleration>
          <wrench>0.020577 -0.26011 -0.365782 0 -0 0</wrench>
        </link>
        <link name='right_arm_link_3'>
          <pose frame=''>-0.345564 0.054967 0.066507 -1.50082 0.001099 -1.67344</pose>
          <velocity>0.009778 0.003766 -0.030341 0.003211 0.339393 0.120737</velocity>
          <acceleration>1.16532 0.241087 0.730033 0.913055 1.43749 -0.660521</acceleration>
          <wrench>0.061246 0.012671 0.038369 0 -0 0</wrench>
        </link>
        <link name='right_gripper'>
          <pose frame=''>-0.35083 0.032844 0.108878 -0.001119 0.069982 3.03887</pose>
          <velocity>0.026378 0.0029 -0.028678 0.003177 0.336937 0.121201</velocity>
          <acceleration>-11.6447 5.69113 -3.07693 -2.296 -0.791145 -3.0413</acceleration>
          <wrench>-0.102757 0.05022 -0.027152 0 -0 0</wrench>
        </link>
        <link name='right_leg_link_1'>
          <pose frame=''>-0.299937 0.114102 0.050604 -3.07022 -0.000508 -1.67003</pose>
          <velocity>0.001658 0.001342 -0.00079 0.111858 0.065867 0.118057</velocity>
          <acceleration>0.987698 -1.305 -2.31948 1.13852 -1.34166 0.768899</acceleration>
          <wrench>0.045972 -0.06074 -0.107959 0 -0 0</wrench>
        </link>
        <link name='right_leg_link_2'>
          <pose frame=''>-0.25845 0.109965 0.053556 -3.06971 -0.000565 -1.67002</pose>
          <velocity>0.001807 0.006039 -0.000717 0.123183 0.066287 0.112577</velocity>
          <acceleration>1.46948 1.07407 -6.29228 1.34968 -0.597728 0.271183</acceleration>
          <wrench>0.128426 0.09387 -0.54992 0 -0 0</wrench>
        </link>
        <link name='right_leg_link_3'>
          <pose frame=''>-0.183572 0.102511 0.044455 3.06786 0.001183 1.4716</pose>
          <velocity>0.001087 0.0153 -0.010773 0.224957 0.015409 0.109443</velocity>
          <acceleration>0.259271 13.1456 -10.4248 3.05857 -0.543928 2.39403</acceleration>
          <wrench>0.001819 0.092215 -0.073128 0 -0 0</wrench>
        </link>
        <link name='right_leg_link_4'>
          <pose frame=''>-0.110207 0.095221 0.064445 1.64376 -0.001012 -1.66999</pose>
          <velocity>0.004181 0.020263 -0.016361 0.185765 0.022166 0.108687</velocity>
          <acceleration>-0.44432 -6.15489 -13.3703 -0.393032 0.43241 0.012248</acceleration>
          <wrench>-0.038068 -0.527333 -1.14553 0 -0 0</wrench>
        </link>
        <link name='right_leg_link_5'>
          <pose frame=''>-0.111472 0.081477 0.064468 -1.55879 -1.49775 3.02745</pose>
          <velocity>0.005054 0.020681 -0.01942 0.207297 0.039635 0.109279</velocity>
          <acceleration>1.00357 2.38464 -26.9395 1.79304 1.09472 2.92981</acceleration>
          <wrench>0.014555 0.034585 -0.390709 0 -0 0</wrench>
        </link>
        <link name='torso_Link'>
          <pose frame=''>-0.351378 0.135497 0.046816 -0.071495 0.000166 1.46793</pose>
          <velocity>0.001006 -0.000594 0.001252 0.09969 0.074197 0.035796</velocity>
          <acceleration>0.554632 -2.97066 -2.39779 -2.4426 0.37737 -2.54988</acceleration>
          <wrench>0.008337 -0.044651 -0.03604 0 -0 0</wrench>
        </link>
      </model>
      <model name='ground_plane'>
        <pose frame=''>0 0 0 0 -0 0</pose>
        <scale>1 1 1</scale>
        <link name='link'>
          <pose frame=''>0 0 0 0 -0 0</pose>
          <velocity>0 0 0 0 -0 0</velocity>
          <acceleration>0 0 0 0 -0 0</acceleration>
          <wrench>0 0 0 0 -0 0</wrench>
        </link>
      </model>
      <light name='sun'>
        <pose frame=''>0 0 10 0 -0 0</pose>
      </light>
    </state>
    <gui fullscreen='0'>
      <camera name='user_camera'>
        <pose frame=''>5 -5 2 0 0.275643 2.35619</pose>
        <view_controller>orbit</view_controller>
        <projection_type>perspective</projection_type>
      </camera>
    </gui>
  </world>
</sdf>
