<?xml version="1.0" encoding="utf-8"?>
<!-- This URDF was automatically created by SolidWorks to URDF Exporter! Originally created by Stephen Brawner (brawner@gmail.com) 
     Commit Version: 1.6.0-1-g15f4949  Build Version: 1.6.7594.29634
     For more information, please see http://wiki.ros.org/sw_urdf_exporter -->
<robot
  name="bioloidgp_cfg2">
  <link
    name="base_link">
    <inertial>
      <origin
        xyz="-0.0037924 -8.2804E-06 0.00098887"
        rpy="0 0 0" />
      <mass
        value="0.15751" />
      <inertia
        ixx="5.7357E-05"
        ixy="-1.0313E-08"
        ixz="-3.9253E-07"
        iyy="4.7444E-05"
        iyz="1.503E-09"
        izz="7.2045E-05" />
    </inertial>
    <visual>
      <origin
        xyz="0 0 0"
        rpy="0 0 0" />
      <geometry>
        <mesh
          filename="package://bioloidgp_cfg2/meshes/base_link.STL" />
      </geometry>
      <material
        name="">
        <color
          rgba="0.79216 0.81961 0.93333 1" />
      </material>
    </visual>
    <collision>
      <origin
        xyz="0 0 0"
        rpy="0 0 0" />
      <geometry>
        <mesh
          filename="package://bioloidgp_cfg2/meshes/base_link.STL" />
      </geometry>
    </collision>
  </link>
  <link
    name="right_arm_link_1">
    <inertial>
      <origin
        xyz="-6.07043908196214E-08 -0.0092320672392516 0.00517864249847516"
        rpy="0 0 0" />
      <mass
        value="0.00402029367652144" />
      <inertia
        ixx="8.53462226825599E-07"
        ixy="1.70481193136309E-12"
        ixz="-1.05162132079151E-12"
        iyy="1.77130321667598E-06"
        iyz="2.51193243950454E-07"
        izz="1.69099459342748E-06" />
    </inertial>
    <visual>
      <origin
        xyz="0 0 0"
        rpy="0 0 0" />
      <geometry>
        <mesh
          filename="package://bioloidgp_cfg2/meshes/right_arm_link_1.STL" />
      </geometry>
      <material
        name="">
        <color
          rgba="0.792156862745098 0.819607843137255 0.933333333333333 1" />
      </material>
    </visual>
    <collision>
      <origin
        xyz="0 0 0"
        rpy="0 0 0" />
      <geometry>
        <mesh
          filename="package://bioloidgp_cfg2/meshes/right_arm_link_1.STL" />
      </geometry>
    </collision>
  </link>
  <joint
    name="joint_1"
    type="continuous">
    <origin
      xyz="0.00875 -0.05649 0.00275"
      rpy="3.1416 0 3.1416" />
    <parent
      link="base_link" />
    <child
      link="right_arm_link_1" />
    <axis
      xyz="0 1 0" />
    <safety_controller
      k_velocity="0" />
  </joint>
  <link
    name="right_arm_link_2">
    <inertial>
      <origin
        xyz="-0.000501890512671105 -0.035219108255101 0.003125589769726"
        rpy="0 0 0" />
      <mass
        value="0.0883642393517848" />
      <inertia
        ixx="2.19001716690432E-05"
        ixy="-8.80921683803909E-09"
        ixz="-1.89476813249764E-07"
        iyy="1.85292934705817E-05"
        iyz="2.01292818032304E-07"
        izz="1.67002940787384E-05" />
    </inertial>
    <visual>
      <origin
        xyz="0 0 0"
        rpy="0 0 0" />
      <geometry>
        <mesh
          filename="package://bioloidgp_cfg2/meshes/right_arm_link_2.STL" />
      </geometry>
      <material
        name="">
        <color
          rgba="0.792156862745098 0.819607843137255 0.933333333333333 1" />
      </material>
    </visual>
    <collision>
      <origin
        xyz="0 0 0"
        rpy="0 0 0" />
      <geometry>
        <mesh
          filename="package://bioloidgp_cfg2/meshes/right_arm_link_2.STL" />
      </geometry>
    </collision>
  </link>
  <joint
    name="joint_3"
    type="continuous">
    <origin
      xyz="0 -0.0230095805758359 0.0179999999999591"
      rpy="-1.5707963267949 0 1.5707963267949" />
    <parent
      link="right_arm_link_1" />
    <child
      link="right_arm_link_2" />
    <axis
      xyz="0 0 1" />
    <safety_controller
      k_velocity="0" />
  </joint>
  <link
    name="right_arm_link_3">
    <inertial>
      <origin
        xyz="0.00415752095634418 0.0477168328995845 -0.0163264630771301"
        rpy="0 0 0" />
      <mass
        value="0.0124405169193281" />
      <inertia
        ixx="1.01511820933173E-05"
        ixy="-7.57219531539235E-09"
        ixz="-1.05248184037674E-12"
        iyy="3.65282468945604E-06"
        iyz="2.51193224626464E-07"
        izz="9.92898397139806E-06" />
    </inertial>
    <visual>
      <origin
        xyz="0 0 0"
        rpy="0 0 0" />
      <geometry>
        <mesh
          filename="package://bioloidgp_cfg2/meshes/right_arm_link_3.STL" />
      </geometry>
      <material
        name="">
        <color
          rgba="0.792156862745098 0.819607843137255 0.933333333333333 1" />
      </material>
    </visual>
    <collision>
      <origin
        xyz="0 0 0"
        rpy="0 0 0" />
      <geometry>
        <mesh
          filename="package://bioloidgp_cfg2/meshes/right_arm_link_3.STL" />
      </geometry>
    </collision>
  </link>
  <joint
    name="joint_5"
    type="continuous">
    <origin
      xyz="0 -0.0574 0.0182000000000002"
      rpy="1.5707963267949 0 3.14159265358979" />
    <parent
      link="right_arm_link_2" />
    <child
      link="right_arm_link_3" />
    <axis
      xyz="1 0 0" />
    <safety_controller
      k_velocity="0" />
  </joint>
  <link
    name="left_arm_link_1">
    <inertial>
      <origin
        xyz="-6.07043890571424E-08 -0.0092320672392515 0.00517864249847648"
        rpy="0 0 0" />
      <mass
        value="0.00402029367652149" />
      <inertia
        ixx="8.53462226825609E-07"
        ixy="1.70481192819739E-12"
        ixz="-1.05162131865276E-12"
        iyy="1.77130321667599E-06"
        iyz="2.51193243950455E-07"
        izz="1.69099459342749E-06" />
    </inertial>
    <visual>
      <origin
        xyz="0 0 0"
        rpy="0 0 0" />
      <geometry>
        <mesh
          filename="package://bioloidgp_cfg2/meshes/left_arm_link_1.STL" />
      </geometry>
      <material
        name="">
        <color
          rgba="0.792156862745098 0.819607843137255 0.933333333333333 1" />
      </material>
    </visual>
    <collision>
      <origin
        xyz="0 0 0"
        rpy="0 0 0" />
      <geometry>
        <mesh
          filename="package://bioloidgp_cfg2/meshes/left_arm_link_1.STL" />
      </geometry>
    </collision>
  </link>
  <joint
    name="joint_2"
    type="continuous">
    <origin
      xyz="0.00875 0.05649 0.00275"
      rpy="3.1416 0 0" />
    <parent
      link="base_link" />
    <child
      link="left_arm_link_1" />
    <axis
      xyz="0 1 0" />
    <safety_controller
      k_velocity="0" />
  </joint>
  <link
    name="left_arm_link_2">
    <inertial>
      <origin
        xyz="0.000472372493798889 -0.0352486262739743 0.00312558976972636"
        rpy="0 0 0" />
      <mass
        value="0.0883642393517847" />
      <inertia
        ixx="2.19001716690431E-05"
        ixy="-8.80921683803528E-09"
        ixz="1.92483601194287E-07"
        iyy="1.85292934705817E-05"
        iyz="1.80667596411727E-07"
        izz="1.67002940787383E-05" />
    </inertial>
    <visual>
      <origin
        xyz="0 0 0"
        rpy="0 0 0" />
      <geometry>
        <mesh
          filename="package://bioloidgp_cfg2/meshes/left_arm_link_2.STL" />
      </geometry>
      <material
        name="">
        <color
          rgba="0.792156862745098 0.819607843137255 0.933333333333333 1" />
      </material>
    </visual>
    <collision>
      <origin
        xyz="0 0 0"
        rpy="0 0 0" />
      <geometry>
        <mesh
          filename="package://bioloidgp_cfg2/meshes/left_arm_link_2.STL" />
      </geometry>
    </collision>
  </link>
  <joint
    name="joint_4"
    type="continuous">
    <origin
      xyz="0 -0.0230095805758357 0.0179999999999604"
      rpy="-1.5707963267949 0 -1.5707963267949" />
    <parent
      link="left_arm_link_1" />
    <child
      link="left_arm_link_2" />
    <axis
      xyz="0 0 1" />
    <safety_controller
      k_velocity="0" />
  </joint>
  <link
    name="left_arm_link_3">
    <inertial>
      <origin
        xyz="-0.00415756019096623 0.0477168328995842 -0.01632646319197"
        rpy="0 0 0" />
      <mass
        value="0.0124405169193281" />
      <inertia
        ixx="1.01511820933173E-05"
        ixy="7.57560493926133E-09"
        ixz="-1.05248181858834E-12"
        iyy="3.65282468945609E-06"
        iyz="2.51193263274456E-07"
        izz="9.92898397139807E-06" />
    </inertial>
    <visual>
      <origin
        xyz="0 0 0"
        rpy="0 0 0" />
      <geometry>
        <mesh
          filename="package://bioloidgp_cfg2/meshes/left_arm_link_3.STL" />
      </geometry>
      <material
        name="">
        <color
          rgba="0.792156862745098 0.819607843137255 0.933333333333333 1" />
      </material>
    </visual>
    <collision>
      <origin
        xyz="0 0 0"
        rpy="0 0 0" />
      <geometry>
        <mesh
          filename="package://bioloidgp_cfg2/meshes/left_arm_link_3.STL" />
      </geometry>
    </collision>
  </link>
  <joint
    name="joint_6"
    type="continuous">
    <origin
      xyz="0 -0.0573999999999997 0.0182000000000009"
      rpy="1.5707963267949 0 3.14159265358979" />
    <parent
      link="left_arm_link_2" />
    <child
      link="left_arm_link_3" />
    <axis
      xyz="1 0 0" />
    <safety_controller
      k_velocity="0" />
  </joint>
  <link
    name="torso_link">
    <inertial>
      <origin
        xyz="0 0 0"
        rpy="0 0 0" />
      <mass
        value="0" />
      <inertia
        ixx="0"
        ixy="0"
        ixz="0"
        iyy="0"
        iyz="0"
        izz="0" />
    </inertial>
    <visual>
      <origin
        xyz="0 0 0"
        rpy="0 0 0" />
      <geometry>
        <mesh
          filename="package://bioloidgp_cfg2/meshes/torso_link.STL" />
      </geometry>
      <material
        name="">
        <color
          rgba="1 1 1 1" />
      </material>
    </visual>
    <collision>
      <origin
        xyz="0 0 0"
        rpy="0 0 0" />
      <geometry>
        <mesh
          filename="package://bioloidgp_cfg2/meshes/torso_link.STL" />
      </geometry>
    </collision>
  </link>
  <joint
    name="joint_19"
    type="continuous">
    <origin
      xyz="0.00824999999999999 0 -0.02375"
      rpy="1.5707963267949 0 1.5707963267949" />
    <parent
      link="base_link" />
    <child
      link="torso_link" />
    <axis
      xyz="0 1 0" />
    <safety_controller
      k_velocity="0" />
  </joint>
  <link
    name="right_leg_link_1">
    <inertial>
      <origin
        xyz="-0.0129819085295125 -0.00228500435172156 0.000908026149630231"
        rpy="0 0 0" />
      <mass
        value="0.047405027669223" />
      <inertia
        ixx="7.27334637836052E-06"
        ixy="5.51374282894465E-08"
        ixz="1.90980207222024E-07"
        iyy="1.32375639686867E-05"
        iyz="-1.50339397226115E-09"
        izz="1.18495804679192E-05" />
    </inertial>
    <visual>
      <origin
        xyz="0 0 0"
        rpy="0 0 0" />
      <geometry>
        <mesh
          filename="package://bioloidgp_cfg2/meshes/right_leg_link_1.STL" />
      </geometry>
      <material
        name="">
        <color
          rgba="0.792156862745098 0.819607843137255 0.933333333333333 1" />
      </material>
    </visual>
    <collision>
      <origin
        xyz="0 0 0"
        rpy="0 0 0" />
      <geometry>
        <mesh
          filename="package://bioloidgp_cfg2/meshes/right_leg_link_1.STL" />
      </geometry>
    </collision>
  </link>
  <joint
    name="joint_9"
    type="continuous">
    <origin
      xyz="-0.016 -0.053500000000001 0"
      rpy="0 0 0" />
    <parent
      link="torso_link" />
    <child
      link="right_leg_link_1" />
    <axis
      xyz="0 0 1" />
    <safety_controller
      k_velocity="0" />
  </joint>
  <link
    name="right_leg_link_2">
    <inertial>
      <origin
        xyz="-0.0130339683821673 -0.0436380731762434 -0.000505151739104481"
        rpy="0 0 0" />
      <mass
        value="0.0891171757796175" />
      <inertia
        ixx="2.07420488419902E-05"
        ixy="1.89476813249684E-07"
        ixz="-1.92483601194145E-07"
        iyy="1.89661820142661E-05"
        iyz="-7.78205227092188E-08"
        izz="1.90005912983823E-05" />
    </inertial>
    <visual>
      <origin
        xyz="0 0 0"
        rpy="0 0 0" />
      <geometry>
        <mesh
          filename="package://bioloidgp_cfg2/meshes/right_leg_link_2.STL" />
      </geometry>
      <material
        name="">
        <color
          rgba="0.792156862745098 0.819607843137255 0.933333333333333 1" />
      </material>
    </visual>
    <collision>
      <origin
        xyz="0 0 0"
        rpy="0 0 0" />
      <geometry>
        <mesh
          filename="package://bioloidgp_cfg2/meshes/right_leg_link_2.STL" />
      </geometry>
    </collision>
  </link>
  <joint
    name="joint_11"
    type="continuous">
    <origin
      xyz="0 -0.0417999999999986 0"
      rpy="0 0 0" />
    <parent
      link="right_leg_link_1" />
    <child
      link="right_leg_link_2" />
    <axis
      xyz="1 0 0" />
    <safety_controller
      k_velocity="0" />
  </joint>
  <link
    name="right_leg_link_3">
    <inertial>
      <origin
        xyz="0.0139999999999992 0.033556383206639 0.0151934897642461"
        rpy="0 0 0" />
      <mass
        value="0.00701486534628872" />
      <inertia
        ixx="5.15587753735927E-06"
        ixy="-9.03548140591605E-20"
        ixz="-3.2651259631231E-20"
        iyy="3.83307916350282E-06"
        iyz="-4.23987865116599E-07"
        izz="7.34905050588703E-06" />
    </inertial>
    <visual>
      <origin
        xyz="0 0 0"
        rpy="0 0 0" />
      <geometry>
        <mesh
          filename="package://bioloidgp_cfg2/meshes/right_leg_link_3.STL" />
      </geometry>
      <material
        name="">
        <color
          rgba="0.792156862745098 0.819607843137255 0.933333333333333 1" />
      </material>
    </visual>
    <collision>
      <origin
        xyz="0 0 0"
        rpy="0 0 0" />
      <geometry>
        <mesh
          filename="package://bioloidgp_cfg2/meshes/right_leg_link_3.STL" />
      </geometry>
    </collision>
  </link>
  <joint
    name="joint_13"
    type="continuous">
    <origin
      xyz="0 -0.0744000000000003 -0.0145000000000005"
      rpy="0 0 3.14159265358979" />
    <parent
      link="right_leg_link_2" />
    <child
      link="right_leg_link_3" />
    <axis
      xyz="1 0 0" />
    <safety_controller
      k_velocity="0" />
  </joint>
  <link
    name="right_leg_link_4">
    <inertial>
      <origin
        xyz="-0.0133946384168481 0.0211528090768009 0.0129875072823341"
        rpy="0 0 0" />
      <mass
        value="0.0873984262026252" />
      <inertia
        ixx="2.17378173151335E-05"
        ixy="7.44599515805113E-20"
        ixz="-2.01292818032276E-07"
        iyy="2.20790808773904E-05"
        iyz="1.82242487051719E-07"
        izz="1.31204837284324E-05" />
    </inertial>
    <visual>
      <origin
        xyz="0 0 0"
        rpy="0 0 0" />
      <geometry>
        <mesh
          filename="package://bioloidgp_cfg2/meshes/right_leg_link_4.STL" />
      </geometry>
      <material
        name="">
        <color
          rgba="0.792156862745098 0.819607843137255 0.933333333333333 1" />
      </material>
    </visual>
    <collision>
      <origin
        xyz="0 0 0"
        rpy="0 0 0" />
      <geometry>
        <mesh
          filename="package://bioloidgp_cfg2/meshes/right_leg_link_4.STL" />
      </geometry>
    </collision>
  </link>
  <joint
    name="joint_15"
    type="continuous">
    <origin
      xyz="0 0.075 0.0145000000000001"
      rpy="-1.5707963267949 0 3.14159265358979" />
    <parent
      link="right_leg_link_3" />
    <child
      link="right_leg_link_4" />
    <axis
      xyz="1 0 0" />
    <safety_controller
      k_velocity="0" />
  </joint>
  <link
    name="right_leg_link_5">
    <inertial>
      <origin
        xyz="0.000199999992457636 -0.0271016298640742 0.00578156165290536"
        rpy="0 0 0" />
      <mass
        value="0.0145032303847989" />
      <inertia
        ixx="5.46558889534126E-06"
        ixy="6.68158300289132E-17"
        ixz="6.34574768034608E-16"
        iyy="1.36797822725631E-05"
        iyz="6.23592035713619E-15"
        izz="9.53948774258591E-06" />
    </inertial>
    <visual>
      <origin
        xyz="0 0 0"
        rpy="0 0 0" />
      <geometry>
        <mesh
          filename="package://bioloidgp_cfg2/meshes/right_leg_link_5.STL" />
      </geometry>
      <material
        name="">
        <color
          rgba="0.792156862745098 0.819607843137255 0.933333333333333 1" />
      </material>
    </visual>
    <collision>
      <origin
        xyz="0 0 0"
        rpy="0 0 0" />
      <geometry>
        <mesh
          filename="package://bioloidgp_cfg2/meshes/right_leg_link_5.STL" />
      </geometry>
    </collision>
  </link>
  <joint
    name="joint_17"
    type="continuous">
    <origin
      xyz="-0.0138000000000001 0 -9.99999999997669E-05"
      rpy="1.5707963267949 0 -1.5707963267949" />
    <parent
      link="right_leg_link_4" />
    <child
      link="right_leg_link_5" />
    <axis
      xyz="1 0 0" />
    <safety_controller
      k_velocity="0" />
  </joint>
  <link
    name="left_leg_link_1">
    <inertial>
      <origin
        xyz="-0.0129819085295124 -0.00234002672831649 -0.000908026149630328"
        rpy="0 0 0" />
      <mass
        value="0.047405027669223" />
      <inertia
        ixx="7.27334637836052E-06"
        ixy="3.45122066688674E-08"
        ixz="-1.90980207222008E-07"
        iyy="1.32375639686867E-05"
        iyz="-1.50339397226348E-09"
        izz="1.18495804679192E-05" />
    </inertial>
    <visual>
      <origin
        xyz="0 0 0"
        rpy="0 0 0" />
      <geometry>
        <mesh
          filename="package://bioloidgp_cfg2/meshes/left_leg_link_1.STL" />
      </geometry>
      <material
        name="">
        <color
          rgba="0.792156862745098 0.819607843137255 0.933333333333333 1" />
      </material>
    </visual>
    <collision>
      <origin
        xyz="0 0 0"
        rpy="0 0 0" />
      <geometry>
        <mesh
          filename="package://bioloidgp_cfg2/meshes/left_leg_link_1.STL" />
      </geometry>
    </collision>
  </link>
  <joint
    name="joint_10"
    type="continuous">
    <origin
      xyz="0.016 -0.0535000000000007 0"
      rpy="3.14159265358979 0 -3.14159265358979" />
    <parent
      link="torso_link" />
    <child
      link="left_leg_link_1" />
    <axis
      xyz="0 0 1" />
    <safety_controller
      k_velocity="0" />
  </joint>
  <link
    name="left_leg_link_2">
    <inertial>
      <origin
        xyz="0.0130339683821149 -0.043667341802208 -0.000534420365074492"
        rpy="0 0 0" />
      <mass
        value="0.0891171757796175" />
      <inertia
        ixx="2.07420488419902E-05"
        ixy="-1.92483601194347E-07"
        ixz="1.89476813249889E-07"
        iyy="1.89661820142661E-05"
        iyz="-7.78205227092396E-08"
        izz="1.90005912983823E-05" />
    </inertial>
    <visual>
      <origin
        xyz="0 0 0"
        rpy="0 0 0" />
      <geometry>
        <mesh
          filename="package://bioloidgp_cfg2/meshes/left_leg_link_2.STL" />
      </geometry>
      <material
        name="">
        <color
          rgba="0.792156862745098 0.819607843137255 0.933333333333333 1" />
      </material>
    </visual>
    <collision>
      <origin
        xyz="0 0 0"
        rpy="0 0 0" />
      <geometry>
        <mesh
          filename="package://bioloidgp_cfg2/meshes/left_leg_link_2.STL" />
      </geometry>
    </collision>
  </link>
  <joint
    name="joint_12"
    type="continuous">
    <origin
      xyz="0 -0.0418000000000006 0"
      rpy="3.14159265358979 0 -3.14159265358979" />
    <parent
      link="left_leg_link_1" />
    <child
      link="left_leg_link_2" />
    <axis
      xyz="1 0 0" />
    <safety_controller
      k_velocity="0" />
  </joint>
  <link
    name="left_leg_link_3">
    <inertial>
      <origin
        xyz="-0.0140000000000142 0.033556383206639 0.0151934897642235"
        rpy="0 0 0" />
      <mass
        value="0.00701486534628872" />
      <inertia
        ixx="5.15587753735929E-06"
        ixy="2.99639326388526E-19"
        ixz="-2.11097430098724E-18"
        iyy="3.83307916350282E-06"
        iyz="-4.23987865116591E-07"
        izz="7.34905050588705E-06" />
    </inertial>
    <visual>
      <origin
        xyz="0 0 0"
        rpy="0 0 0" />
      <geometry>
        <mesh
          filename="package://bioloidgp_cfg2/meshes/left_leg_link_3.STL" />
      </geometry>
      <material
        name="">
        <color
          rgba="0.792156862745098 0.819607843137255 0.933333333333333 1" />
      </material>
    </visual>
    <collision>
      <origin
        xyz="0 0 0"
        rpy="0 0 0" />
      <geometry>
        <mesh
          filename="package://bioloidgp_cfg2/meshes/left_leg_link_3.STL" />
      </geometry>
    </collision>
  </link>
  <joint
    name="joint_14"
    type="continuous">
    <origin
      xyz="0 -0.0744 -0.0145000000000106"
      rpy="0 0 3.14159265358979" />
    <parent
      link="left_leg_link_2" />
    <child
      link="left_leg_link_3" />
    <axis
      xyz="1 0 0" />
    <safety_controller
      k_velocity="0" />
  </joint>
  <link
    name="left_leg_link_4">
    <inertial>
      <origin
        xyz="0.0134244826302436 0.021122964863385 0.0129875072823342"
        rpy="0 0 0" />
      <mass
        value="0.0873984262026251" />
      <inertia
        ixx="2.17378173151335E-05"
        ixy="-2.48903729482866E-19"
        ixz="1.80667596411541E-07"
        iyy="2.20790808773904E-05"
        iyz="2.02867708672486E-07"
        izz="1.31204837284324E-05" />
    </inertial>
    <visual>
      <origin
        xyz="0 0 0"
        rpy="0 0 0" />
      <geometry>
        <mesh
          filename="package://bioloidgp_cfg2/meshes/left_leg_link_4.STL" />
      </geometry>
      <material
        name="">
        <color
          rgba="0.792156862745098 0.819607843137255 0.933333333333333 1" />
      </material>
    </visual>
    <collision>
      <origin
        xyz="0 0 0"
        rpy="0 0 0" />
      <geometry>
        <mesh
          filename="package://bioloidgp_cfg2/meshes/left_leg_link_4.STL" />
      </geometry>
    </collision>
  </link>
  <joint
    name="joint_16"
    type="continuous">
    <origin
      xyz="0 0.075 0.0144999999999907"
      rpy="-1.5707963267949 0 -3.14159265358979" />
    <parent
      link="left_leg_link_3" />
    <child
      link="left_leg_link_4" />
    <axis
      xyz="1 0 0" />
    <safety_controller
      k_velocity="0" />
  </joint>
  <link
    name="left_leg_link_5">
    <inertial>
      <origin
        xyz="-0.00019999999247397 0.0271016298640752 -0.00578156174805474"
        rpy="0 0 0" />
      <mass
        value="0.014503230384799" />
      <inertia
        ixx="5.46558889534131E-06"
        ixy="6.683597674306E-17"
        ixz="-6.35559152327675E-16"
        iyy="1.36797822725632E-05"
        iyz="-6.23589198528723E-15"
        izz="9.53948774258595E-06" />
    </inertial>
    <visual>
      <origin
        xyz="0 0 0"
        rpy="0 0 0" />
      <geometry>
        <mesh
          filename="package://bioloidgp_cfg2/meshes/left_leg_link_5.STL" />
      </geometry>
      <material
        name="">
        <color
          rgba="0.792156862745098 0.819607843137255 0.933333333333333 1" />
      </material>
    </visual>
    <collision>
      <origin
        xyz="0 0 0"
        rpy="0 0 0" />
      <geometry>
        <mesh
          filename="package://bioloidgp_cfg2/meshes/left_leg_link_5.STL" />
      </geometry>
    </collision>
  </link>
  <joint
    name="joint_18"
    type="continuous">
    <origin
      xyz="0.0137999999999867 0 -9.9999999999989E-05"
      rpy="-1.5707963267949 0 1.5707963267949" />
    <parent
      link="left_leg_link_4" />
    <child
      link="left_leg_link_5" />
    <axis
      xyz="1 0 0" />
    <safety_controller
      k_velocity="0" />
  </joint>
</robot>